Workbook

Sheet INSTRUÇÕES
A1: CONTROLE FINANCEIRO — ENTRADA, SAÍDA E CARTÃO
A2: Moeda: Guaraní (Gs.) · Ano-base: 2026
B4: AS 3 REGRAS QUE FAZEM A PLANILHA FECHAR
B5: 1) Dinheiro que entra ou sai da sua mão / conta → lança na aba LANÇAMENTOS.
B6: 2) Compra no cartão de crédito → lança SÓ na aba CARTÕES. Não repita em LANÇAMENTOS.
B7: A planilha divide a compra nas parcelas e joga cada parcela no mês certo, sozinha.
B8: 3) Quando você paga a fatura do cartão, NÃO lance nada. A parcela já foi contada no mês dela.
B9: Seguindo essas 3 regras é impossível contar o mesmo gasto duas vezes.
B11: COMO USAR, PASSO A PASSO
B12: 1º Abra a aba LISTAS e escreva o nome dos seus cartões e, se quiser, ajuste as categorias.
B13: 2º Abra a aba LANÇAMENTOS e comece a digitar. Data, Tipo, Status, Categoria, Descrição, Meio, Valor.
B14: 3º Compras parceladas no cartão vão na aba CARTÕES: data, cartão, valor total e nº de parcelas.
B15: 4º Veja o mês na aba RESUMO MENSAL (escolha ano e mês no alto) e o ano na aba RESUMO ANUAL.
B17: REALIZADO x PROJETADO
... B39: O saldo acumulado no RESUMO ANUAL soma o resultado de cada mês, de janeiro em diante.

Sheet LANÇAMENTOS
A1: LANÇAMENTOS
A2: Dinheiro que entra e sai da sua conta ou do seu bolso. Compra no cartão NÃO vem aqui — vai na aba CARTÕES.
A3: Total ENTRADAS | B3: Total SAÍDAS | C3: Saldo (sem cartão) | D3: Lançamentos digitados | E3: Espaço livre para digitar
A4: =SUMIF($B$6:$B$1005,"ENTRADA",$G$6:$G$1005) | B4: =SUMIF($B$6:$B$1005,"SAÍDA",$G$6:$G$1005) | C4: =A4-B4 | D4: =COUNTA($A$6:$A$1005) | E4: =1000-D4
A5: Data | B5: Tipo | C5: Status | D5: Categoria | E5: Descrição | F5: Meio de pagamento | G5: Valor (Gs.) | H5: Mês (auto) | I5: Índice (auto)
H6: =IF($A6="","",MONTH($A6)&"/"&YEAR($A6)) | I6: =IF($A6="",0,YEAR($A6)*12+MONTH($A6))
H7: =IF($A7="","",MONTH($A7)&"/"&YEAR($A7)) | I7: =IF($A7="",0,YEAR($A7)*12+MONTH($A7))
H8: =IF($A8="","",MONTH($A8)&"/"&YEAR($A8)) | I8: =IF($A8="",0,YEAR($A8)*12+MONTH($A8))
H9: =IF($A9="","",MONTH($A9)&"/"&YEAR($A9)) | I9: =IF($A9="",0,YEAR($A9)*12+MONTH($A9))
H10: =IF($A10="","",MONTH($A10)&"/"&YEAR($A10)) | I10: =IF($A10="",0,YEAR($A10)*12+MONTH($A10))
H11: =IF($A11="","",MONTH($A11)&"/"&YEAR($A11)) | I11: =IF($A11="",0,YEAR($A11)*12+MONTH($A11))
H12: =IF($A12="","",MONTH($A12)&"/"&YEAR($A12)) | I12: =IF($A12="",0,YEAR($A12)*12+MONTH($A12))
H13: =IF($A13="","",MONTH($A13)&"/"&YEAR($A13)) | I13: =IF($A13="",0,YEAR($A13)*12+MONTH($A13))
H14: =IF($A14="","",MONTH($A14)&"/"&YEAR($A14)) | I14: =IF($A14="",0,YEAR($A14)*12+MONTH($A14))
H15: =IF($A15="","",MONTH($A15)&"/"&YEAR($A15)) | I15: =IF($A15="",0,YEAR($A15)*12+MONTH($A15))
H16: =IF($A16="","",MONTH($A16)&"/"&YEAR($A16)) | I16: =IF($A16="",0,YEAR($A16)*12+MONTH($A16))
H17: =IF($A17="","",MONTH($A17)&"/"&YEAR($A17)) | I17: =IF($A17="",0,YEAR($A17)*12+MONTH($A17))
... H1005: =IF($A1005="","",MONTH($A1005)&"/"&YEAR($A1005)) | I1005: =IF($A1005="",0,YEAR($A1005)*12+MONTH($A1005))

Sheet CARTÕES
A1: CARTÕES DE CRÉDITO — COMPRAS E PARCELAS
A2: Digite a compra uma vez. A planilha divide nas parcelas e joga cada uma no mês certo. Não lance a fatura em LANÇAMENTOS.
A3: Total comprado | B3: Já pago (até hoje) | C3: Falta pagar (saldo devedor) | D3: Mês de referência de hoje
A4: =SUM($E$6:$E$65) | B4: =SUM($L$6:$L$65) | C4: =SUM($M$6:$M$65) | D4: =MONTH(TODAY())&"/"&YEAR(TODAY())
A5: Data da compra | B5: Cartão | C5: Descrição | D5: Categoria | E5: Valor total (Gs.) | F5: Nº de parcelas | G5: 1ª parcela (opcional) | H5: Início (auto) | I5: Valor da parcela (auto) | J5: Última parcela (auto) | K5: Índice (auto) | L5: Já pago (auto) | M5: Falta pagar (auto)
H6: =IF($A6="","",IF($G6<>"",$G6,DATE(YEAR($A6)+IF(MONTH($A6)=12,1,0),IF(MONTH($A6)=12,1,MONTH($A6)+1),1))) | I6: =IF(OR($E6="",$F6=""),"",ROUND($E6/$F6,0)) | J6: =IF($K6=0,"",($K6+$F6-1-INT(($K6+$F6-2)/12)*12)&"/"&INT(($K6+$F6-2)/12)) | K6: =IF($H6="",0,YEAR($H6)*12+MONTH($H6)) | L6: =IF($K6=0,"",SUMPRODUCT((PARCELAS!$C6:$AL6>0)*(PARCELAS!$C6:$AL6<=YEAR(TODAY())*12+MONTH(TODAY()))*PARCELAS!$AM6:$BV6)) | M6: =IF($K6=0,"",$E6-$L6)
H7: =IF($A7="","",IF($G7<>"",$G7,DATE(YEAR($A7)+IF(MONTH($A7)=12,1,0),IF(MONTH($A7)=12,1,MONTH($A7)+1),1))) | I7: =IF(OR($E7="",$F7=""),"",ROUND($E7/$F7,0)) | J7: =IF($K7=0,"",($K7+$F7-1-INT(($K7+$F7-2)/12)*12)&"/"&INT(($K7+$F7-2)/12)) | K7: =IF($H7="",0,YEAR($H7)*12+MONTH($H7)) | L7: =IF($K7=0,"",SUMPRODUCT((PARCELAS!$C7:$AL7>0)*(PARCELAS!$C7:$AL7<=YEAR(TODAY())*12+MONTH(TODAY()))*PARCELAS!$AM7:$BV7)) | M7: =IF($K7=0,"",$E7-$L7)
H8: =IF($A8="","",IF($G8<>"",$G8,DATE(YEAR($A8)+IF(MONTH($A8)=12,1,0),IF(MONTH($A8)=12,1,MONTH($A8)+1),1))) | I8: =IF(OR($E8="",$F8=""),"",ROUND($E8/$F8,0)) | J8: =IF($K8=0,"",($K8+$F8-1-INT(($K8+$F8-2)/12)*12)&"/"&INT(($K8+$F8-2)/12)) | K8: =IF($H8="",0,YEAR($H8)*12+MONTH($H8)) | L8: =IF($K8=0,"",SUMPRODUCT((PARCELAS!$C8:$AL8>0)*(PARCELAS!$C8:$AL8<=YEAR(TODAY())*12+MONTH(TODAY()))*PARCELAS!$AM8:$BV8)) | M8: =IF($K8=0,"",$E8-$L8)
H9: =IF($A9="","",IF($G9<>"",$G9,DATE(YEAR($A9)+IF(MONTH($A9)=12,1,0),IF(MONTH($A9)=12,1,MONTH($A9)+1),1))) | I9: =IF(OR($E9="",$F9=""),"",ROUND($E9/$F9,0)) | J9: =IF($K9=0,"",($K9+$F9-1-INT(($K9+$F9-2)/12)*12)&"/"&INT(($K9+$F9-2)/12)) | K9: =IF($H9="",0,YEAR($H9)*12+MONTH($H9)) | L9: =IF($K9=0,"",SUMPRODUCT((PARCELAS!$C9:$AL9>0)*(PARCELAS!$C9:$AL9<=YEAR(TODAY())*12+MONTH(TODAY()))*PARCELAS!$AM9:$BV9)) | M9: =IF($K9=0,"",$E9-$L9)
H10: =IF($A10="","",IF($G10<>"",$G10,DATE(YEAR($A10)+IF(MONTH($A10)=12,1,0),IF(MONTH($A10)=12,1,MONTH($A10)+1),1))) | I10: =IF(OR($E10="",$F10=""),"",ROUND($E10/$F10,0)) | J10: =IF($K10=0,"",($K10+$F10-1-INT(($K10+$F10-2)/12)*12)&"/"&INT(($K10+$F10-2)/12)) | K10: =IF($H10="",0,YEAR($H10)*12+MONTH($H10)) | L10: =IF($K10=0,"",SUMPRODUCT((PARCELAS!$C10:$AL10>0)*(PARCELAS!$C10:$AL10<=YEAR(TODAY())*12+MONTH(TODAY()))*PARCELAS!$AM10:$BV10)) | M10: =IF($K10=0,"",$E10-$L10)
H11: =IF($A11="","",IF($G11<>"",$G11,DATE(YEAR($A11)+IF(MONTH($A11)=12,1,0),IF(MONTH($A11)=12,1,MONTH($A11)+1),1))) | I11: =IF(OR($E11="",$F11=""),"",ROUND($E11/$F11,0)) | J11: =IF($K11=0,"",($K11+$F11-1-INT(($K11+$F11-2)/12)*12)&"/"&INT(($K11+$F11-2)/12)) | K11: =IF($H11="",0,YEAR($H11)*12+MONTH($H11)) | L11: =IF($K11=0,"",SUMPRODUCT((PARCELAS!$C11:$AL11>0)*(PARCELAS!$C11:$AL11<=YEAR(TODAY())*12+MONTH(TODAY()))*PARCELAS!$AM11:$BV11)) | M11: =IF($K11=0,"",$E11-$L11)
H12: =IF($A12="","",IF($G12<>"",$G12,DATE(YEAR($A12)+IF(MONTH($A12)=12,1,0),IF(MONTH($A12)=12,1,MONTH($A12)+1),1))) | I12: =IF(OR($E12="",$F12=""),"",ROUND($E12/$F12,0)) | J12: =IF($K12=0,"",($K12+$F12-1-INT(($K12+$F12-2)/12)*12)&"/"&INT(($K12+$F12-2)/12)) | K12: =IF($H12="",0,YEAR($H12)*12+MONTH($H12)) | L12: =IF($K12=0,"",SUMPRODUCT((PARCELAS!$C12:$AL12>0)*(PARCELAS!$C12:$AL12<=YEAR(TODAY())*12+MONTH(TODAY()))*PARCELAS!$AM12:$BV12)) | M12: =IF($K12=0,"",$E12-$L12)
H13: =IF($A13="","",IF($G13<>"",$G13,DATE(YEAR($A13)+IF(MONTH($A13)=12,1,0),IF(MONTH($A13)=12,1,MONTH($A13)+1),1))) | I13: =IF(OR($E13="",$F13=""),"",ROUND($E13/$F13,0)) | J13: =IF($K13=0,"",($K13+$F13-1-INT(($K13+$F13-2)/12)*12)&"/"&INT(($K13+$F13-2)/12)) | K13: =IF($H13="",0,YEAR($H13)*12+MONTH($H13)) | L13: =IF($K13=0,"",SUMPRODUCT((PARCELAS!$C13:$AL13>0)*(PARCELAS!$C13:$AL13<=YEAR(TODAY())*12+MONTH(TODAY()))*PARCELAS!$AM13:$BV13)) | M13: =IF($K13=0,"",$E13-$L13)
H14: =IF($A14="","",IF($G14<>"",$G14,DATE(YEAR($A14)+IF(MONTH($A14)=12,1,0),IF(MONTH($A14)=12,1,MONTH($A14)+1),1))) | I14: =IF(OR($E14="",$F14=""),"",ROUND($E14/$F14,0)) | J14: =IF($K14=0,"",($K14+$F14-1-INT(($K14+$F14-2)/12)*12)&"/"&INT(($K14+$F14-2)/12)) | K14: =IF($H14="",0,YEAR($H14)*12+MONTH($H14)) | L14: =IF($K14=0,"",SUMPRODUCT((PARCELAS!$C14:$AL14>0)*(PARCELAS!$C14:$AL14<=YEAR(TODAY())*12+MONTH(TODAY()))*PARCELAS!$AM14:$BV14)) | M14: =IF($K14=0,"",$E14-$L14)
H15: =IF($A15="","",IF($G15<>"",$G15,DATE(YEAR($A15)+IF(MONTH($A15)=12,1,0),IF(MONTH($A15)=12,1,MONTH($A15)+1),1))) | I15: =IF(OR($E15="",$F15=""),"",ROUND($E15/$F15,0)) | J15: =IF($K15=0,"",($K15+$F15-1-INT(($K15+$F15-2)/12)*12)&"/"&INT(($K15+$F15-2)/12)) | K15: =IF($H15="",0,YEAR($H15)*12+MONTH($H15)) | L15: =IF($K15=0,"",SUMPRODUCT((PARCELAS!$C15:$AL15>0)*(PARCELAS!$C15:$AL15<=YEAR(TODAY())*12+MONTH(TODAY()))*PARCELAS!$AM15:$BV15)) | M15: =IF($K15=0,"",$E15-$L15)
H16: =IF($A16="","",IF($G16<>"",$G16,DATE(YEAR($A16)+IF(MONTH($A16)=12,1,0),IF(MONTH($A16)=12,1,MONTH($A16)+1),1))) | I16: =IF(OR($E16="",$F16=""),"",ROUND($E16/$F16,0)) | J16: =IF($K16=0,"",($K16+$F16-1-INT(($K16+$F16-2)/12)*12)&"/"&INT(($K16+$F16-2)/12)) | K16: =IF($H16="",0,YEAR($H16)*12+MONTH($H16)) | L16: =IF($K16=0,"",SUMPRODUCT((PARCELAS!$C16:$AL16>0)*(PARCELAS!$C16:$AL16<=YEAR(TODAY())*12+MONTH(TODAY()))*PARCELAS!$AM16:$BV16)) | M16: =IF($K16=0,"",$E16-$L16)
H17: =IF($A17="","",IF($G17<>"",$G17,DATE(YEAR($A17)+IF(MONTH($A17)=12,1,0),IF(MONTH($A17)=12,1,MONTH($A17)+1),1))) | I17: =IF(OR($E17="",$F17=""),"",ROUND($E17/$F17,0)) | J17: =IF($K17=0,"",($K17+$F17-1-INT(($K17+$F17-2)/12)*12)&"/"&INT(($K17+$F17-2)/12)) | K17: =IF($H17="",0,YEAR($H17)*12+MONTH($H17)) | L17: =IF($K17=0,"",SUMPRODUCT((PARCELAS!$C17:$AL17>0)*(PARCELAS!$C17:$AL17<=YEAR(TODAY())*12+MONTH(TODAY()))*PARCELAS!$AM17:$BV17)) | M17: =IF($K17=0,"",$E17-$L17)
... H65: =IF($A65="","",IF($G65<>"",$G65,DATE(YEAR($A65)+IF(MONTH($A65)=12,1,0),IF(MONTH($A65)=12,1,MONTH($A65)+1),1))) | I65: =IF(OR($E65="",$F65=""),"",ROUND($E65/$F65,0)) | J65: =IF($K65=0,"",($K65+$F65-1-INT(($K65+$F65-2)/12)*12)&"/"&INT(($K65+$F65-2)/12)) | K65: =IF($H65="",0,YEAR($H65)*12+MONTH($H65)) | L65: =IF($K65=0,"",SUMPRODUCT((PARCELAS!$C65:$AL65>0)*(PARCELAS!$C65:$AL65<=YEAR(TODAY())*12+MONTH(TODAY()))*PARCELAS!$AM65:$BV65)) | M65: =IF($K65=0,"",$E65-$L65)
A68: SALDO POR CARTÃO
A69: Cartão | B69: Total comprado | C69: Já pago | D69: Falta pagar | E69: Parcelas em aberto
A70: =IF(LISTAS!$F6="","",LISTAS!$F6) | B70: =IF($A70="","",SUMIF($B$6:$B$65,$A70,$E$6:$E$65)) | C70: =IF($A70="","",SUMIF($B$6:$B$65,$A70,$L$6:$L$65)) | D70: =IF($A70="","",SUMIF($B$6:$B$65,$A70,$M$6:$M$65)) | E70: =IF($A70="","",SUMPRODUCT((PARCELAS!$C$6:$AL$65>YEAR(TODAY())*12+MONTH(TODAY()))*(PARCELAS!$AM$6:$BV$65>0)*1*(CARTÕES!$B$6:$B$65=$A70)))
A71: =IF(LISTAS!$F7="","",LISTAS!$F7) | B71: =IF($A71="","",SUMIF($B$6:$B$65,$A71,$E$6:$E$65)) | C71: =IF($A71="","",SUMIF($B$6:$B$65,$A71,$L$6:$L$65)) | D71: =IF($A71="","",SUMIF($B$6:$B$65,$A71,$M$6:$M$65)) | E71: =IF($A71="","",SUMPRODUCT((PARCELAS!$C$6:$AL$65>YEAR(TODAY())*12+MONTH(TODAY()))*(PARCELAS!$AM$6:$BV$65>0)*1*(CARTÕES!$B$6:$B$65=$A71)))
A72: =IF(LISTAS!$F8="","",LISTAS!$F8) | B72: =IF($A72="","",SUMIF($B$6:$B$65,$A72,$E$6:$E$65)) | C72: =IF($A72="","",SUMIF($B$6:$B$65,$A72,$L$6:$L$65)) | D72: =IF($A72="","",SUMIF($B$6:$B$65,$A72,$M$6:$M$65)) | E72: =IF($A72="","",SUMPRODUCT((PARCELAS!$C$6:$AL$65>YEAR(TODAY())*12+MONTH(TODAY()))*(PARCELAS!$AM$6:$BV$65>0)*1*(CARTÕES!$B$6:$B$65=$A72)))
A73: =IF(LISTAS!$F9="","",LISTAS!$F9) | B73: =IF($A73="","",SUMIF($B$6:$B$65,$A73,$E$6:$E$65)) | C73: =IF($A73="","",SUMIF($B$6:$B$65,$A73,$L$6:$L$65)) | D73: =IF($A73="","",SUMIF($B$6:$B$65,$A73,$M$6:$M$65)) | E73: =IF($A73="","",SUMPRODUCT((PARCELAS!$C$6:$AL$65>YEAR(TODAY())*12+MONTH(TODAY()))*(PARCELAS!$AM$6:$BV$65>0)*1*(CARTÕES!$B$6:$B$65=$A73)))
A74: =IF(LISTAS!$F10="","",LISTAS!$F10) | B74: =IF($A74="","",SUMIF($B$6:$B$65,$A74,$E$6:$E$65)) | C74: =IF($A74="","",SUMIF($B$6:$B$65,$A74,$L$6:$L$65)) | D74: =IF($A74="","",SUMIF($B$6:$B$65,$A74,$M$6:$M$65)) | E74: =IF($A74="","",SUMPRODUCT((PARCELAS!$C$6:$AL$65>YEAR(TODAY())*12+MONTH(TODAY()))*(PARCELAS!$AM$6:$BV$65>0)*1*(CARTÕES!$B$6:$B$65=$A74)))
A75: =IF(LISTAS!$F11="","",LISTAS!$F11) | B75: =IF($A75="","",SUMIF($B$6:$B$65,$A75,$E$6:$E$65)) | C75: =IF($A75="","",SUMIF($B$6:$B$65,$A75,$L$6:$L$65)) | D75: =IF($A75="","",SUMIF($B$6:$B$65,$A75,$M$6:$M$65)) | E75: =IF($A75="","",SUMPRODUCT((PARCELAS!$C$6:$AL$65>YEAR(TODAY())*12+MONTH(TODAY()))*(PARCELAS!$AM$6:$BV$65>0)*1*(CARTÕES!$B$6:$B$65=$A75)))
A76: =IF(LISTAS!$F12="","",LISTAS!$F12) | B76: =IF($A76="","",SUMIF($B$6:$B$65,$A76,$E$6:$E$65)) | C76: =IF($A76="","",SUMIF($B$6:$B$65,$A76,$L$6:$L$65)) | D76: =IF($A76="","",SUMIF($B$6:$B$65,$A76,$M$6:$M$65)) | E76: =IF($A76="","",SUMPRODUCT((PARCELAS!$C$6:$AL$65>YEAR(TODAY())*12+MONTH(TODAY()))*(PARCELAS!$AM$6:$BV$65>0)*1*(CARTÕES!$B$6:$B$65=$A76)))
A77: =IF(LISTAS!$F13="","",LISTAS!$F13) | B77: =IF($A77="","",SUMIF($B$6:$B$65,$A77,$E$6:$E$65)) | C77: =IF($A77="","",SUMIF($B$6:$B$65,$A77,$L$6:$L$65)) | D77: =IF($A77="","",SUMIF($B$6:$B$65,$A77,$M$6:$M$65)) | E77: =IF($A77="","",SUMPRODUCT((PARCELAS!$C$6:$AL$65>YEAR(TODAY())*12+MONTH(TODAY()))*(PARCELAS!$AM$6:$BV$65>0)*1*(CARTÕES!$B$6:$B$65=$A77)))
A78: TOTAL | B78: =SUM(B70:B77) | C78: =SUM(C70:C77) | D78: =SUM(D70:D77) | E78: =SUM(E70:E77)

Sheet RESUMO MENSAL
A1: RESUMO MENSAL
A2: Escolha o ano e o mês nas células amarelas. Tudo abaixo se recalcula sozinho.
A3: Ano | B3: Mês | C3: Índice (auto)
A4: 2026 | B4: 1 | C4: =$A$4*12+$B$4 | D4: =INDEX(LISTAS!$K$6:$K$17,$B$4)&" de "&$A$4
A6: Entradas REALIZADAS | C6: Entradas PROJETADAS | E6: Saídas REALIZADAS | G6: Saídas PROJETADAS
A7: =SUMIFS('LANÇAMENTOS'!$G$6:$G$1005,'LANÇAMENTOS'!$I$6:$I$1005,$C$4,'LANÇAMENTOS'!$B$6:$B$1005,"ENTRADA",'LANÇAMENTOS'!$C$6:$C$1005,"REALIZADO") | C7: =SUMIFS('LANÇAMENTOS'!$G$6:$G$1005,'LANÇAMENTOS'!$I$6:$I$1005,$C$4,'LANÇAMENTOS'!$B$6:$B$1005,"ENTRADA",'LANÇAMENTOS'!$C$6:$C$1005,"PROJETADO") | E7: =SUMIFS('LANÇAMENTOS'!$G$6:$G$1005,'LANÇAMENTOS'!$I$6:$I$1005,$C$4,'LANÇAMENTOS'!$B$6:$B$1005,"SAÍDA",'LANÇAMENTOS'!$C$6:$C$1005,"REALIZADO") | G7: =SUMIFS('LANÇAMENTOS'!$G$6:$G$1005,'LANÇAMENTOS'!$I$6:$I$1005,$C$4,'LANÇAMENTOS'!$B$6:$B$1005,"SAÍDA",'LANÇAMENTOS'!$C$6:$C$1005,"PROJETADO")
A9: Entradas do mês (realizado + projetado) | B9: =SUMIFS('LANÇAMENTOS'!$G$6:$G$1005,'LANÇAMENTOS'!$I$6:$I$1005,$C$4,'LANÇAMENTOS'!$B$6:$B$1005,"ENTRADA")
A10: Saídas do mês (realizado + projetado) | B10: =SUMIFS('LANÇAMENTOS'!$G$6:$G$1005,'LANÇAMENTOS'!$I$6:$I$1005,$C$4,'LANÇAMENTOS'!$B$6:$B$1005,"SAÍDA")
A11: Parcelas de cartão que vencem no mês | B11: =SUMPRODUCT((PARCELAS!$C$6:$AL$65=$C$4)*PARCELAS!$AM$6:$BV$65)
A12: RESULTADO DO MÊS | B12: =$B$9-$B$10-$B$11
A14: ENTRADAS POR CATEGORIA | F14: SAÍDAS POR CATEGORIA
A15: Categoria | B15: Realizado | C15: Projetado | D15: Total | F15: Categoria | G15: Realizado | H15: Projetado | I15: Total
A16: =IF(LISTAS!$B6="ENTRADA",LISTAS!$A6,"") | B16: =IF($A16="","",SUMIFS('LANÇAMENTOS'!$G$6:$G$1005,'LANÇAMENTOS'!$I$6:$I$1005,$C$4,'LANÇAMENTOS'!$B$6:$B$1005,"ENTRADA",'LANÇAMENTOS'!$C$6:$C$1005,"REALIZADO",'LANÇAMENTOS'!$D$6:$D$1005,$A16)) | C16: =IF($A16="","",SUMIFS('LANÇAMENTOS'!$G$6:$G$1005,'LANÇAMENTOS'!$I$6:$I$1005,$C$4,'LANÇAMENTOS'!$B$6:$B$1005,"ENTRADA",'LANÇAMENTOS'!$C$6:$C$1005,"PROJETADO",'LANÇAMENTOS'!$D$6:$D$1005,$A16)) | D16: =IF($A16="","",SUMIFS('LANÇAMENTOS'!$G$6:$G$1005,'LANÇAMENTOS'!$I$6:$I$1005,$C$4,'LANÇAMENTOS'!$B$6:$B$1005,"ENTRADA",'LANÇAMENTOS'!$D$6:$D$1005,$A16)) | F16: =IF(LISTAS!$B6="SAÍDA",LISTAS!$A6,"") | G16: =IF($F16="","",SUMIFS('LANÇAMENTOS'!$G$6:$G$1005,'LANÇAMENTOS'!$I$6:$I$1005,$C$4,'LANÇAMENTOS'!$B$6:$B$1005,"SAÍDA",'LANÇAMENTOS'!$C$6:$C$1005,"REALIZADO",'LANÇAMENTOS'!$D$6:$D$1005,$F16)) | H16: =IF($F16="","",SUMIFS('LANÇAMENTOS'!$G$6:$G$1005,'LANÇAMENTOS'!$I$6:$I$1005,$C$4,'LANÇAMENTOS'!$B$6:$B$1005,"SAÍDA",'LANÇAMENTOS'!$C$6:$C$1005,"PROJETADO",'LANÇAMENTOS'!$D$6:$D$1005,$F16)) | I16: =IF($F16="","",SUMIFS('LANÇAMENTOS'!$G$6:$G$1005,'LANÇAMENTOS'!$I$6:$I$1005,$C$4,'LANÇAMENTOS'!$B$6:$B$1005,"SAÍDA",'LANÇAMENTOS'!$D$6:$D$1005,$F16))
A17: =IF(LISTAS!$B7="ENTRADA",LISTAS!$A7,"") | B17: =IF($A17="","",SUMIFS('LANÇAMENTOS'!$G$6:$G$1005,'LANÇAMENTOS'!$I$6:$I$1005,$C$4,'LANÇAMENTOS'!$B$6:$B$1005,"ENTRADA",'LANÇAMENTOS'!$C$6:$C$1005,"REALIZADO",'LANÇAMENTOS'!$D$6:$D$1005,$A17)) | C17: =IF($A17="","",SUMIFS('LANÇAMENTOS'!$G$6:$G$1005,'LANÇAMENTOS'!$I$6:$I$1005,$C$4,'LANÇAMENTOS'!$B$6:$B$1005,"ENTRADA",'LANÇAMENTOS'!$C$6:$C$1005,"PROJETADO",'LANÇAMENTOS'!$D$6:$D$1005,$A17)) | D17: =IF($A17="","",SUMIFS('LANÇAMENTOS'!$G$6:$G$1005,'LANÇAMENTOS'!$I$6:$I$1005,$C$4,'LANÇAMENTOS'!$B$6:$B$1005,"ENTRADA",'LANÇAMENTOS'!$D$6:$D$1005,$A17)) | F17: =IF(LISTAS!$B7="SAÍDA",LISTAS!$A7,"") | G17: =IF($F17="","",SUMIFS('LANÇAMENTOS'!$G$6:$G$1005,'LANÇAMENTOS'!$I$6:$I$1005,$C$4,'LANÇAMENTOS'!$B$6:$B$1005,"SAÍDA",'LANÇAMENTOS'!$C$6:$C$1005,"REALIZADO",'LANÇAMENTOS'!$D$6:$D$1005,$F17)) | H17: =IF($F17="","",SUMIFS('LANÇAMENTOS'!$G$6:$G$1005,'LANÇAMENTOS'!$I$6:$I$1005,$C$4,'LANÇAMENTOS'!$B$6:$B$1005,"SAÍDA",'LANÇAMENTOS'!$C$6:$C$1005,"PROJETADO",'LANÇAMENTOS'!$D$6:$D$1005,$F17)) | I17: =IF($F17="","",SUMIFS('LANÇAMENTOS'!$G$6:$G$1005,'LANÇAMENTOS'!$I$6:$I$1005,$C$4,'LANÇAMENTOS'!$B$6:$B$1005,"SAÍDA",'LANÇAMENTOS'!$D$6:$D$1005,$F17))
A18: =IF(LISTAS!$B8="ENTRADA",LISTAS!$A8,"") | B18: =IF($A18="","",SUMIFS('LANÇAMENTOS'!$G$6:$G$1005,'LANÇAMENTOS'!$I$6:$I$1005,$C$4,'LANÇAMENTOS'!$B$6:$B$1005,"ENTRADA",'LANÇAMENTOS'!$C$6:$C$1005,"REALIZADO",'LANÇAMENTOS'!$D$6:$D$1005,$A18)) | C18: =IF($A18="","",SUMIFS('LANÇAMENTOS'!$G$6:$G$1005,'LANÇAMENTOS'!$I$6:$I$1005,$C$4,'LANÇAMENTOS'!$B$6:$B$1005,"ENTRADA",'LANÇAMENTOS'!$C$6:$C$1005,"PROJETADO",'LANÇAMENTOS'!$D$6:$D$1005,$A18)) | D18: =IF($A18="","",SUMIFS('LANÇAMENTOS'!$G$6:$G$1005,'LANÇAMENTOS'!$I$6:$I$1005,$C$4,'LANÇAMENTOS'!$B$6:$B$1005,"ENTRADA",'LANÇAMENTOS'!$D$6:$D$1005,$A18)) | F18: =IF(LISTAS!$B8="SAÍDA",LISTAS!$A8,"") | G18: =IF($F18="","",SUMIFS('LANÇAMENTOS'!$G$6:$G$1005,'LANÇAMENTOS'!$I$6:$I$1005,$C$4,'LANÇAMENTOS'!$B$6:$B$1005,"SAÍDA",'LANÇAMENTOS'!$C$6:$C$1005,"REALIZADO",'LANÇAMENTOS'!$D$6:$D$1005,$F18)) | H18: =IF($F18="","",SUMIFS('LANÇAMENTOS'!$G$6:$G$1005,'LANÇAMENTOS'!$I$6:$I$1005,$C$4,'LANÇAMENTOS'!$B$6:$B$1005,"SAÍDA",'LANÇAMENTOS'!$C$6:$C$1005,"PROJETADO",'LANÇAMENTOS'!$D$6:$D$1005,$F18)) | I18: =IF($F18="","",SUMIFS('LANÇAMENTOS'!$G$6:$G$1005,'LANÇAMENTOS'!$I$6:$I$1005,$C$4,'LANÇAMENTOS'!$B$6:$B$1005,"SAÍDA",'LANÇAMENTOS'!$D$6:$D$1005,$F18))
A19: =IF(LISTAS!$B9="ENTRADA",LISTAS!$A9,"") | B19: =IF($A19="","",SUMIFS('LANÇAMENTOS'!$G$6:$G$1005,'LANÇAMENTOS'!$I$6:$I$1005,$C$4,'LANÇAMENTOS'!$B$6:$B$1005,"ENTRADA",'LANÇAMENTOS'!$C$6:$C$1005,"REALIZADO",'LANÇAMENTOS'!$D$6:$D$1005,$A19)) | C19: =IF($A19="","",SUMIFS('LANÇAMENTOS'!$G$6:$G$1005,'LANÇAMENTOS'!$I$6:$I$1005,$C$4,'LANÇAMENTOS'!$B$6:$B$1005,"ENTRADA",'LANÇAMENTOS'!$C$6:$C$1005,"PROJETADO",'LANÇAMENTOS'!$D$6:$D$1005,$A19)) | D19: =IF($A19="","",SUMIFS('LANÇAMENTOS'!$G$6:$G$1005,'LANÇAMENTOS'!$I$6:$I$1005,$C$4,'LANÇAMENTOS'!$B$6:$B$1005,"ENTRADA",'LANÇAMENTOS'!$D$6:$D$1005,$A19)) | F19: =IF(LISTAS!$B9="SAÍDA",LISTAS!$A9,"") | G19: =IF($F19="","",SUMIFS('LANÇAMENTOS'!$G$6:$G$1005,'LANÇAMENTOS'!$I$6:$I$1005,$C$4,'LANÇAMENTOS'!$B$6:$B$1005,"SAÍDA",'LANÇAMENTOS'!$C$6:$C$1005,"REALIZADO",'LANÇAMENTOS'!$D$6:$D$1005,$F19)) | H19: =IF($F19="","",SUMIFS('LANÇAMENTOS'!$G$6:$G$1005,'LANÇAMENTOS'!$I$6:$I$1005,$C$4,'LANÇAMENTOS'!$B$6:$B$1005,"SAÍDA",'LANÇAMENTOS'!$C$6:$C$1005,"PROJETADO",'LANÇAMENTOS'!$D$6:$D$1005,$F19)) | I19: =IF($F19="","",SUMIFS('LANÇAMENTOS'!$G$6:$G$1005,'LANÇAMENTOS'!$I$6:$I$1005,$C$4,'LANÇAMENTOS'!$B$6:$B$1005,"SAÍDA",'LANÇAMENTOS'!$D$6:$D$1005,$F19))
A20: =IF(LISTAS!$B10="ENTRADA",LISTAS!$A10,"") | B20: =IF($A20="","",SUMIFS('LANÇAMENTOS'!$G$6:$G$1005,'LANÇAMENTOS'!$I$6:$I$1005,$C$4,'LANÇAMENTOS'!$B$6:$B$1005,"ENTRADA",'LANÇAMENTOS'!$C$6:$C$1005,"REALIZADO",'LANÇAMENTOS'!$D$6:$D$1005,$A20)) | C20: =IF($A20="","",SUMIFS('LANÇAMENTOS'!$G$6:$G$1005,'LANÇAMENTOS'!$I$6:$I$1005,$C$4,'LANÇAMENTOS'!$B$6:$B$1005,"ENTRADA",'LANÇAMENTOS'!$C$6:$C$1005,"PROJETADO",'LANÇAMENTOS'!$D$6:$D$1005,$A20)) | D20: =IF($A20="","",SUMIFS('LANÇAMENTOS'!$G$6:$G$1005,'LANÇAMENTOS'!$I$6:$I$1005,$C$4,'LANÇAMENTOS'!$B$6:$B$1005,"ENTRADA",'LANÇAMENTOS'!$D$6:$D$1005,$A20)) | F20: =IF(LISTAS!$B10="SAÍDA",LISTAS!$A10,"") | G20: =IF($F20="","",SUMIFS('LANÇAMENTOS'!$G$6:$G$1005,'LANÇAMENTOS'!$I$6:$I$1005,$C$4,'LANÇAMENTOS'!$B$6:$B$1005,"SAÍDA",'LANÇAMENTOS'!$C$6:$C$1005,"REALIZADO",'LANÇAMENTOS'!$D$6:$D$1005,$F20)) | H20: =IF($F20="","",SUMIFS('LANÇAMENTOS'!$G$6:$G$1005,'LANÇAMENTOS'!$I$6:$I$1005,$C$4,'LANÇAMENTOS'!$B$6:$B$1005,"SAÍDA",'LANÇAMENTOS'!$C$6:$C$1005,"PROJETADO",'LANÇAMENTOS'!$D$6:$D$1005,$F20)) | I20: =IF($F20="","",SUMIFS('LANÇAMENTOS'!$G$6:$G$1005,'LANÇAMENTOS'!$I$6:$I$1005,$C$4,'LANÇAMENTOS'!$B$6:$B$1005,"SAÍDA",'LANÇAMENTOS'!$D$6:$D$1005,$F20))
A21: =IF(LISTAS!$B11="ENTRADA",LISTAS!$A11,"") | B21: =IF($A21="","",SUMIFS('LANÇAMENTOS'!$G$6:$G$1005,'LANÇAMENTOS'!$I$6:$I$1005,$C$4,'LANÇAMENTOS'!$B$6:$B$1005,"ENTRADA",'LANÇAMENTOS'!$C$6:$C$1005,"REALIZADO",'LANÇAMENTOS'!$D$6:$D$1005,$A21)) | C21: =IF($A21="","",SUMIFS('LANÇAMENTOS'!$G$6:$G$1005,'LANÇAMENTOS'!$I$6:$I$1005,$C$4,'LANÇAMENTOS'!$B$6:$B$1005,"ENTRADA",'LANÇAMENTOS'!$C$6:$C$1005,"PROJETADO",'LANÇAMENTOS'!$D$6:$D$1005,$A21)) | D21: =IF($A21="","",SUMIFS('LANÇAMENTOS'!$G$6:$G$1005,'LANÇAMENTOS'!$I$6:$I$1005,$C$4,'LANÇAMENTOS'!$B$6:$B$1005,"ENTRADA",'LANÇAMENTOS'!$D$6:$D$1005,$A21)) | F21: =IF(LISTAS!$B11="SAÍDA",LISTAS!$A11,"") | G21: =IF($F21="","",SUMIFS('LANÇAMENTOS'!$G$6:$G$1005,'LANÇAMENTOS'!$I$6:$I$1005,$C$4,'LANÇAMENTOS'!$B$6:$B$1005,"SAÍDA",'LANÇAMENTOS'!$C$6:$C$1005,"REALIZADO",'LANÇAMENTOS'!$D$6:$D$1005,$F21)) | H21: =IF($F21="","",SUMIFS('LANÇAMENTOS'!$G$6:$G$1005,'LANÇAMENTOS'!$I$6:$I$1005,$C$4,'LANÇAMENTOS'!$B$6:$B$1005,"SAÍDA",'LANÇAMENTOS'!$C$6:$C$1005,"PROJETADO",'LANÇAMENTOS'!$D$6:$D$1005,$F21)) | I21: =IF($F21="","",SUMIFS('LANÇAMENTOS'!$G$6:$G$1005,'LANÇAMENTOS'!$I$6:$I$1005,$C$4,'LANÇAMENTOS'!$B$6:$B$1005,"SAÍDA",'LANÇAMENTOS'!$D$6:$D$1005,$F21))
A22: =IF(LISTAS!$B12="ENTRADA",LISTAS!$A12,"") | B22: =IF($A22="","",SUMIFS('LANÇAMENTOS'!$G$6:$G$1005,'LANÇAMENTOS'!$I$6:$I$1005,$C$4,'LANÇAMENTOS'!$B$6:$B$1005,"ENTRADA",'LANÇAMENTOS'!$C$6:$C$1005,"REALIZADO",'LANÇAMENTOS'!$D$6:$D$1005,$A22)) | C22: =IF($A22="","",SUMIFS('LANÇAMENTOS'!$G$6:$G$1005,'LANÇAMENTOS'!$I$6:$I$1005,$C$4,'LANÇAMENTOS'!$B$6:$B$1005,"ENTRADA",'LANÇAMENTOS'!$C$6:$C$1005,"PROJETADO",'LANÇAMENTOS'!$D$6:$D$1005,$A22)) | D22: =IF($A22="","",SUMIFS('LANÇAMENTOS'!$G$6:$G$1005,'LANÇAMENTOS'!$I$6:$I$1005,$C$4,'LANÇAMENTOS'!$B$6:$B$1005,"ENTRADA",'LANÇAMENTOS'!$D$6:$D$1005,$A22)) | F22: =IF(LISTAS!$B12="SAÍDA",LISTAS!$A12,"") | G22: =IF($F22="","",SUMIFS('LANÇAMENTOS'!$G$6:$G$1005,'LANÇAMENTOS'!$I$6:$I$1005,$C$4,'LANÇAMENTOS'!$B$6:$B$1005,"SAÍDA",'LANÇAMENTOS'!$C$6:$C$1005,"REALIZADO",'LANÇAMENTOS'!$D$6:$D$1005,$F22)) | H22: =IF($F22="","",SUMIFS('LANÇAMENTOS'!$G$6:$G$1005,'LANÇAMENTOS'!$I$6:$I$1005,$C$4,'LANÇAMENTOS'!$B$6:$B$1005,"SAÍDA",'LANÇAMENTOS'!$C$6:$C$1005,"PROJETADO",'LANÇAMENTOS'!$D$6:$D$1005,$F22)) | I22: =IF($F22="","",SUMIFS('LANÇAMENTOS'!$G$6:$G$1005,'LANÇAMENTOS'!$I$6:$I$1005,$C$4,'LANÇAMENTOS'!$B$6:$B$1005,"SAÍDA",'LANÇAMENTOS'!$D$6:$D$1005,$F22))
A23: =IF(LISTAS!$B13="ENTRADA",LISTAS!$A13,"") | B23: =IF($A23="","",SUMIFS('LANÇAMENTOS'!$G$6:$G$1005,'LANÇAMENTOS'!$I$6:$I$1005,$C$4,'LANÇAMENTOS'!$B$6:$B$1005,"ENTRADA",'LANÇAMENTOS'!$C$6:$C$1005,"REALIZADO",'LANÇAMENTOS'!$D$6:$D$1005,$A23)) | C23: =IF($A23="","",SUMIFS('LANÇAMENTOS'!$G$6:$G$1005,'LANÇAMENTOS'!$I$6:$I$1005,$C$4,'LANÇAMENTOS'!$B$6:$B$1005,"ENTRADA",'LANÇAMENTOS'!$C$6:$C$1005,"PROJETADO",'LANÇAMENTOS'!$D$6:$D$1005,$A23)) | D23: =IF($A23="","",SUMIFS('LANÇAMENTOS'!$G$6:$G$1005,'LANÇAMENTOS'!$I$6:$I$1005,$C$4,'LANÇAMENTOS'!$B$6:$B$1005,"ENTRADA",'LANÇAMENTOS'!$D$6:$D$1005,$A23)) | F23: =IF(LISTAS!$B13="SAÍDA",LISTAS!$A13,"") | G23: =IF($F23="","",SUMIFS('LANÇAMENTOS'!$G$6:$G$1005,'LANÇAMENTOS'!$I$6:$I$1005,$C$4,'LANÇAMENTOS'!$B$6:$B$1005,"SAÍDA",'LANÇAMENTOS'!$C$6:$C$1005,"REALIZADO",'LANÇAMENTOS'!$D$6:$D$1005,$F23)) | H23: =IF($F23="","",SUMIFS('LANÇAMENTOS'!$G$6:$G$1005,'LANÇAMENTOS'!$I$6:$I$1005,$C$4,'LANÇAMENTOS'!$B$6:$B$1005,"SAÍDA",'LANÇAMENTOS'!$C$6:$C$1005,"PROJETADO",'LANÇAMENTOS'!$D$6:$D$1005,$F23)) | I23: =IF($F23="","",SUMIFS('LANÇAMENTOS'!$G$6:$G$1005,'LANÇAMENTOS'!$I$6:$I$1005,$C$4,'LANÇAMENTOS'!$B$6:$B$1005,"SAÍDA",'LANÇAMENTOS'!$D$6:$D$1005,$F23))
A24: =IF(LISTAS!$B14="ENTRADA",LISTAS!$A14,"") | B24: =IF($A24="","",SUMIFS('LANÇAMENTOS'!$G$6:$G$1005,'LANÇAMENTOS'!$I$6:$I$1005,$C$4,'LANÇAMENTOS'!$B$6:$B$1005,"ENTRADA",'LANÇAMENTOS'!$C$6:$C$1005,"REALIZADO",'LANÇAMENTOS'!$D$6:$D$1005,$A24)) | C24: =IF($A24="","",SUMIFS('LANÇAMENTOS'!$G$6:$G$1005,'LANÇAMENTOS'!$I$6:$I$1005,$C$4,'LANÇAMENTOS'!$B$6:$B$1005,"ENTRADA",'LANÇAMENTOS'!$C$6:$C$1005,"PROJETADO",'LANÇAMENTOS'!$D$6:$D$1005,$A24)) | D24: =IF($A24="","",SUMIFS('LANÇAMENTOS'!$G$6:$G$1005,'LANÇAMENTOS'!$I$6:$I$1005,$C$4,'LANÇAMENTOS'!$B$6:$B$1005,"ENTRADA",'LANÇAMENTOS'!$D$6:$D$1005,$A24)) | F24: =IF(LISTAS!$B14="SAÍDA",LISTAS!$A14,"") | G24: =IF($F24="","",SUMIFS('LANÇAMENTOS'!$G$6:$G$1005,'LANÇAMENTOS'!$I$6:$I$1005,$C$4,'LANÇAMENTOS'!$B$6:$B$1005,"SAÍDA",'LANÇAMENTOS'!$C$6:$C$1005,"REALIZADO",'LANÇAMENTOS'!$D$6:$D$1005,$F24)) | H24: =IF($F24="","",SUMIFS('LANÇAMENTOS'!$G$6:$G$1005,'LANÇAMENTOS'!$I$6:$I$1005,$C$4,'LANÇAMENTOS'!$B$6:$B$1005,"SAÍDA",'LANÇAMENTOS'!$C$6:$C$1005,"PROJETADO",'LANÇAMENTOS'!$D$6:$D$1005,$F24)) | I24: =IF($F24="","",SUMIFS('LANÇAMENTOS'!$G$6:$G$1005,'LANÇAMENTOS'!$I$6:$I$1005,$C$4,'LANÇAMENTOS'!$B$6:$B$1005,"SAÍDA",'LANÇAMENTOS'!$D$6:$D$1005,$F24))
A25: =IF(LISTAS!$B15="ENTRADA",LISTAS!$A15,"") | B25: =IF($A25="","",SUMIFS('LANÇAMENTOS'!$G$6:$G$1005,'LANÇAMENTOS'!$I$6:$I$1005,$C$4,'LANÇAMENTOS'!$B$6:$B$1005,"ENTRADA",'LANÇAMENTOS'!$C$6:$C$1005,"REALIZADO",'LANÇAMENTOS'!$D$6:$D$1005,$A25)) | C25: =IF($A25="","",SUMIFS('LANÇAMENTOS'!$G$6:$G$1005,'LANÇAMENTOS'!$I$6:$I$1005,$C$4,'LANÇAMENTOS'!$B$6:$B$1005,"ENTRADA",'LANÇAMENTOS'!$C$6:$C$1005,"PROJETADO",'LANÇAMENTOS'!$D$6:$D$1005,$A25)) | D25: =IF($A25="","",SUMIFS('LANÇAMENTOS'!$G$6:$G$1005,'LANÇAMENTOS'!$I$6:$I$1005,$C$4,'LANÇAMENTOS'!$B$6:$B$1005,"ENTRADA",'LANÇAMENTOS'!$D$6:$D$1005,$A25)) | F25: =IF(LISTAS!$B15="SAÍDA",LISTAS!$A15,"") | G25: =IF($F25="","",SUMIFS('LANÇAMENTOS'!$G$6:$G$1005,'LANÇAMENTOS'!$I$6:$I$1005,$C$4,'LANÇAMENTOS'!$B$6:$B$1005,"SAÍDA",'LANÇAMENTOS'!$C$6:$C$1005,"REALIZADO",'LANÇAMENTOS'!$D$6:$D$1005,$F25)) | H25: =IF($F25="","",SUMIFS('LANÇAMENTOS'!$G$6:$G$1005,'LANÇAMENTOS'!$I$6:$I$1005,$C$4,'LANÇAMENTOS'!$B$6:$B$1005,"SAÍDA",'LANÇAMENTOS'!$C$6:$C$1005,"PROJETADO",'LANÇAMENTOS'!$D$6:$D$1005,$F25)) | I25: =IF($F25="","",SUMIFS('LANÇAMENTOS'!$G$6:$G$1005,'LANÇAMENTOS'!$I$6:$I$1005,$C$4,'LANÇAMENTOS'!$B$6:$B$1005,"SAÍDA",'LANÇAMENTOS'!$D$6:$D$1005,$F25))
A26: =IF(LISTAS!$B16="ENTRADA",LISTAS!$A16,"") | B26: =IF($A26="","",SUMIFS('LANÇAMENTOS'!$G$6:$G$1005,'LANÇAMENTOS'!$I$6:$I$1005,$C$4,'LANÇAMENTOS'!$B$6:$B$1005,"ENTRADA",'LANÇAMENTOS'!$C$6:$C$1005,"REALIZADO",'LANÇAMENTOS'!$D$6:$D$1005,$A26)) | C26: =IF($A26="","",SUMIFS('LANÇAMENTOS'!$G$6:$G$1005,'LANÇAMENTOS'!$I$6:$I$1005,$C$4,'LANÇAMENTOS'!$B$6:$B$1005,"ENTRADA",'LANÇAMENTOS'!$C$6:$C$1005,"PROJETADO",'LANÇAMENTOS'!$D$6:$D$1005,$A26)) | D26: =IF($A26="","",SUMIFS('LANÇAMENTOS'!$G$6:$G$1005,'LANÇAMENTOS'!$I$6:$I$1005,$C$4,'LANÇAMENTOS'!$B$6:$B$1005,"ENTRADA",'LANÇAMENTOS'!$D$6:$D$1005,$A26)) | F26: =IF(LISTAS!$B16="SAÍDA",LISTAS!$A16,"") | G26: =IF($F26="","",SUMIFS('LANÇAMENTOS'!$G$6:$G$1005,'LANÇAMENTOS'!$I$6:$I$1005,$C$4,'LANÇAMENTOS'!$B$6:$B$1005,"SAÍDA",'LANÇAMENTOS'!$C$6:$C$1005,"REALIZADO",'LANÇAMENTOS'!$D$6:$D$1005,$F26)) | H26: =IF($F26="","",SUMIFS('LANÇAMENTOS'!$G$6:$G$1005,'LANÇAMENTOS'!$I$6:$I$1005,$C$4,'LANÇAMENTOS'!$B$6:$B$1005,"SAÍDA",'LANÇAMENTOS'!$C$6:$C$1005,"PROJETADO",'LANÇAMENTOS'!$D$6:$D$1005,$F26)) | I26: =IF($F26="","",SUMIFS('LANÇAMENTOS'!$G$6:$G$1005,'LANÇAMENTOS'!$I$6:$I$1005,$C$4,'LANÇAMENTOS'!$B$6:$B$1005,"SAÍDA",'LANÇAMENTOS'!$D$6:$D$1005,$F26))
A27: =IF(LISTAS!$B17="ENTRADA",LISTAS!$A17,"") | B27: =IF($A27="","",SUMIFS('LANÇAMENTOS'!$G$6:$G$1005,'LANÇAMENTOS'!$I$6:$I$1005,$C$4,'LANÇAMENTOS'!$B$6:$B$1005,"ENTRADA",'LANÇAMENTOS'!$C$6:$C$1005,"REALIZADO",'LANÇAMENTOS'!$D$6:$D$1005,$A27)) | C27: =IF($A27="","",SUMIFS('LANÇAMENTOS'!$G$6:$G$1005,'LANÇAMENTOS'!$I$6:$I$1005,$C$4,'LANÇAMENTOS'!$B$6:$B$1005,"ENTRADA",'LANÇAMENTOS'!$C$6:$C$1005,"PROJETADO",'LANÇAMENTOS'!$D$6:$D$1005,$A27)) | D27: =IF($A27="","",SUMIFS('LANÇAMENTOS'!$G$6:$G$1005,'LANÇAMENTOS'!$I$6:$I$1005,$C$4,'LANÇAMENTOS'!$B$6:$B$1005,"ENTRADA",'LANÇAMENTOS'!$D$6:$D$1005,$A27)) | F27: =IF(LISTAS!$B17="SAÍDA",LISTAS!$A17,"") | G27: =IF($F27="","",SUMIFS('LANÇAMENTOS'!$G$6:$G$1005,'LANÇAMENTOS'!$I$6:$I$1005,$C$4,'LANÇAMENTOS'!$B$6:$B$1005,"SAÍDA",'LANÇAMENTOS'!$C$6:$C$1005,"REALIZADO",'LANÇAMENTOS'!$D$6:$D$1005,$F27)) | H27: =IF($F27="","",SUMIFS('LANÇAMENTOS'!$G$6:$G$1005,'LANÇAMENTOS'!$I$6:$I$1005,$C$4,'LANÇAMENTOS'!$B$6:$B$1005,"SAÍDA",'LANÇAMENTOS'!$C$6:$C$1005,"PROJETADO",'LANÇAMENTOS'!$D$6:$D$1005,$F27)) | I27: =IF($F27="","",SUMIFS('LANÇAMENTOS'!$G$6:$G$1005,'LANÇAMENTOS'!$I$6:$I$1005,$C$4,'LANÇAMENTOS'!$B$6:$B$1005,"SAÍDA",'LANÇAMENTOS'!$D$6:$D$1005,$F27))
... A55: =IF(LISTAS!$B45="ENTRADA",LISTAS!$A45,"") | B55: =IF($A55="","",SUMIFS('LANÇAMENTOS'!$G$6:$G$1005,'LANÇAMENTOS'!$I$6:$I$1005,$C$4,'LANÇAMENTOS'!$B$6:$B$1005,"ENTRADA",'LANÇAMENTOS'!$C$6:$C$1005,"REALIZADO",'LANÇAMENTOS'!$D$6:$D$1005,$A55)) | C55: =IF($A55="","",SUMIFS('LANÇAMENTOS'!$G$6:$G$1005,'LANÇAMENTOS'!$I$6:$I$1005,$C$4,'LANÇAMENTOS'!$B$6:$B$1005,"ENTRADA",'LANÇAMENTOS'!$C$6:$C$1005,"PROJETADO",'LANÇAMENTOS'!$D$6:$D$1005,$A55)) | D55: =IF($A55="","",SUMIFS('LANÇAMENTOS'!$G$6:$G$1005,'LANÇAMENTOS'!$I$6:$I$1005,$C$4,'LANÇAMENTOS'!$B$6:$B$1005,"ENTRADA",'LANÇAMENTOS'!$D$6:$D$1005,$A55)) | F55: =IF(LISTAS!$B45="SAÍDA",LISTAS!$A45,"") | G55: =IF($F55="","",SUMIFS('LANÇAMENTOS'!$G$6:$G$1005,'LANÇAMENTOS'!$I$6:$I$1005,$C$4,'LANÇAMENTOS'!$B$6:$B$1005,"SAÍDA",'LANÇAMENTOS'!$C$6:$C$1005,"REALIZADO",'LANÇAMENTOS'!$D$6:$D$1005,$F55)) | H55: =IF($F55="","",SUMIFS('LANÇAMENTOS'!$G$6:$G$1005,'LANÇAMENTOS'!$I$6:$I$1005,$C$4,'LANÇAMENTOS'!$B$6:$B$1005,"SAÍDA",'LANÇAMENTOS'!$C$6:$C$1005,"PROJETADO",'LANÇAMENTOS'!$D$6:$D$1005,$F55)) | I55: =IF($F55="","",SUMIFS('LANÇAMENTOS'!$G$6:$G$1005,'LANÇAMENTOS'!$I$6:$I$1005,$C$4,'LANÇAMENTOS'!$B$6:$B$1005,"SAÍDA",'LANÇAMENTOS'!$D$6:$D$1005,$F55))
A56: TOTAL | B56: =SUM(B16:B55) | C56: =SUM(C16:C55) | D56: =SUM(D16:D55) | F56: TOTAL | G56: =SUM(G16:G55) | H56: =SUM(H16:H55) | I56: =SUM(I16:I55)
A58: CONFERÊNCIA
A59: Entradas: KPI menos soma das categorias | D59: =$B$9-$D$56
A60: Saídas: KPI menos soma das categorias | D60: =$B$10-$I$56
A61: Lançamentos sem tipo ou sem status | D61: =SUMPRODUCT(('LANÇAMENTOS'!$A$6:$A$1005<>"")*(('LANÇAMENTOS'!$B$6:$B$1005="")+('LANÇAMENTOS'!$C$6:$C$1005="")>0))
A62: Compras de cartão sem nº de parcelas | D62: =SUMPRODUCT((CARTÕES!$A$6:$A$65<>"")*(CARTÕES!$F$6:$F$65=""))
A63: Parcelas: soma das parcelas menos total comprado | D63: =SUMPRODUCT((PARCELAS!$C$6:$AL$65>0)*PARCELAS!$AM$6:$BV$65)-SUM(CARTÕES!$E$6:$E$65)
A64: Tudo em zero = a planilha está fechando. Qualquer número diferente de zero fica vermelho.

Sheet RESUMO ANUAL
A1: RESUMO ANUAL
A2: Os 12 meses do ano lado a lado. Troque o ano na célula amarela.
A3: Ano
A4: 2026
A5: Mês | B5: Entradas realizadas | C5: Entradas projetadas | D5: Entradas total | E5: Saídas realizadas | F5: Saídas projetadas | G5: Saídas total | H5: Cartão (parcelas) | I5: Resultado do mês | J5: Saldo acumulado
A6: =INDEX(LISTAS!$K$6:$K$17,1) | B6: =SUMIFS('LANÇAMENTOS'!$G$6:$G$1005,'LANÇAMENTOS'!$I$6:$I$1005,($A$4*12+1),'LANÇAMENTOS'!$B$6:$B$1005,"ENTRADA",'LANÇAMENTOS'!$C$6:$C$1005,"REALIZADO") | C6: =SUMIFS('LANÇAMENTOS'!$G$6:$G$1005,'LANÇAMENTOS'!$I$6:$I$1005,($A$4*12+1),'LANÇAMENTOS'!$B$6:$B$1005,"ENTRADA",'LANÇAMENTOS'!$C$6:$C$1005,"PROJETADO") | D6: =B6+C6 | E6: =SUMIFS('LANÇAMENTOS'!$G$6:$G$1005,'LANÇAMENTOS'!$I$6:$I$1005,($A$4*12+1),'LANÇAMENTOS'!$B$6:$B$1005,"SAÍDA",'LANÇAMENTOS'!$C$6:$C$1005,"REALIZADO") | F6: =SUMIFS('LANÇAMENTOS'!$G$6:$G$1005,'LANÇAMENTOS'!$I$6:$I$1005,($A$4*12+1),'LANÇAMENTOS'!$B$6:$B$1005,"SAÍDA",'LANÇAMENTOS'!$C$6:$C$1005,"PROJETADO") | G6: =E6+F6 | H6: =SUMPRODUCT((PARCELAS!$C$6:$AL$65=($A$4*12+1))*PARCELAS!$AM$6:$BV$65) | I6: =D6-G6-H6 | J6: =I6
A7: =INDEX(LISTAS!$K$6:$K$17,2) | B7: =SUMIFS('LANÇAMENTOS'!$G$6:$G$1005,'LANÇAMENTOS'!$I$6:$I$1005,($A$4*12+2),'LANÇAMENTOS'!$B$6:$B$1005,"ENTRADA",'LANÇAMENTOS'!$C$6:$C$1005,"REALIZADO") | C7: =SUMIFS('LANÇAMENTOS'!$G$6:$G$1005,'LANÇAMENTOS'!$I$6:$I$1005,($A$4*12+2),'LANÇAMENTOS'!$B$6:$B$1005,"ENTRADA",'LANÇAMENTOS'!$C$6:$C$1005,"PROJETADO") | D7: =B7+C7 | E7: =SUMIFS('LANÇAMENTOS'!$G$6:$G$1005,'LANÇAMENTOS'!$I$6:$I$1005,($A$4*12+2),'LANÇAMENTOS'!$B$6:$B$1005,"SAÍDA",'LANÇAMENTOS'!$C$6:$C$1005,"REALIZADO") | F7: =SUMIFS('LANÇAMENTOS'!$G$6:$G$1005,'LANÇAMENTOS'!$I$6:$I$1005,($A$4*12+2),'LANÇAMENTOS'!$B$6:$B$1005,"SAÍDA",'LANÇAMENTOS'!$C$6:$C$1005,"PROJETADO") | G7: =E7+F7 | H7: =SUMPRODUCT((PARCELAS!$C$6:$AL$65=($A$4*12+2))*PARCELAS!$AM$6:$BV$65) | I7: =D7-G7-H7 | J7: =J6+I7
A8: =INDEX(LISTAS!$K$6:$K$17,3) | B8: =SUMIFS('LANÇAMENTOS'!$G$6:$G$1005,'LANÇAMENTOS'!$I$6:$I$1005,($A$4*12+3),'LANÇAMENTOS'!$B$6:$B$1005,"ENTRADA",'LANÇAMENTOS'!$C$6:$C$1005,"REALIZADO") | C8: =SUMIFS('LANÇAMENTOS'!$G$6:$G$1005,'LANÇAMENTOS'!$I$6:$I$1005,($A$4*12+3),'LANÇAMENTOS'!$B$6:$B$1005,"ENTRADA",'LANÇAMENTOS'!$C$6:$C$1005,"PROJETADO") | D8: =B8+C8 | E8: =SUMIFS('LANÇAMENTOS'!$G$6:$G$1005,'LANÇAMENTOS'!$I$6:$I$1005,($A$4*12+3),'LANÇAMENTOS'!$B$6:$B$1005,"SAÍDA",'LANÇAMENTOS'!$C$6:$C$1005,"REALIZADO") | F8: =SUMIFS('LANÇAMENTOS'!$G$6:$G$1005,'LANÇAMENTOS'!$I$6:$I$1005,($A$4*12+3),'LANÇAMENTOS'!$B$6:$B$1005,"SAÍDA",'LANÇAMENTOS'!$C$6:$C$1005,"PROJETADO") | G8: =E8+F8 | H8: =SUMPRODUCT((PARCELAS!$C$6:$AL$65=($A$4*12+3))*PARCELAS!$AM$6:$BV$65) | I8: =D8-G8-H8 | J8: =J7+I8
A9: =INDEX(LISTAS!$K$6:$K$17,4) | B9: =SUMIFS('LANÇAMENTOS'!$G$6:$G$1005,'LANÇAMENTOS'!$I$6:$I$1005,($A$4*12+4),'LANÇAMENTOS'!$B$6:$B$1005,"ENTRADA",'LANÇAMENTOS'!$C$6:$C$1005,"REALIZADO") | C9: =SUMIFS('LANÇAMENTOS'!$G$6:$G$1005,'LANÇAMENTOS'!$I$6:$I$1005,($A$4*12+4),'LANÇAMENTOS'!$B$6:$B$1005,"ENTRADA",'LANÇAMENTOS'!$C$6:$C$1005,"PROJETADO") | D9: =B9+C9 | E9: =SUMIFS('LANÇAMENTOS'!$G$6:$G$1005,'LANÇAMENTOS'!$I$6:$I$1005,($A$4*12+4),'LANÇAMENTOS'!$B$6:$B$1005,"SAÍDA",'LANÇAMENTOS'!$C$6:$C$1005,"REALIZADO") | F9: =SUMIFS('LANÇAMENTOS'!$G$6:$G$1005,'LANÇAMENTOS'!$I$6:$I$1005,($A$4*12+4),'LANÇAMENTOS'!$B$6:$B$1005,"SAÍDA",'LANÇAMENTOS'!$C$6:$C$1005,"PROJETADO") | G9: =E9+F9 | H9: =SUMPRODUCT((PARCELAS!$C$6:$AL$65=($A$4*12+4))*PARCELAS!$AM$6:$BV$65) | I9: =D9-G9-H9 | J9: =J8+I9
A10: =INDEX(LISTAS!$K$6:$K$17,5) | B10: =SUMIFS('LANÇAMENTOS'!$G$6:$G$1005,'LANÇAMENTOS'!$I$6:$I$1005,($A$4*12+5),'LANÇAMENTOS'!$B$6:$B$1005,"ENTRADA",'LANÇAMENTOS'!$C$6:$C$1005,"REALIZADO") | C10: =SUMIFS('LANÇAMENTOS'!$G$6:$G$1005,'LANÇAMENTOS'!$I$6:$I$1005,($A$4*12+5),'LANÇAMENTOS'!$B$6:$B$1005,"ENTRADA",'LANÇAMENTOS'!$C$6:$C$1005,"PROJETADO") | D10: =B10+C10 | E10: =SUMIFS('LANÇAMENTOS'!$G$6:$G$1005,'LANÇAMENTOS'!$I$6:$I$1005,($A$4*12+5),'LANÇAMENTOS'!$B$6:$B$1005,"SAÍDA",'LANÇAMENTOS'!$C$6:$C$1005,"REALIZADO") | F10: =SUMIFS('LANÇAMENTOS'!$G$6:$G$1005,'LANÇAMENTOS'!$I$6:$I$1005,($A$4*12+5),'LANÇAMENTOS'!$B$6:$B$1005,"SAÍDA",'LANÇAMENTOS'!$C$6:$C$1005,"PROJETADO") | G10: =E10+F10 | H10: =SUMPRODUCT((PARCELAS!$C$6:$AL$65=($A$4*12+5))*PARCELAS!$AM$6:$BV$65) | I10: =D10-G10-H10 | J10: =J9+I10
A11: =INDEX(LISTAS!$K$6:$K$17,6) | B11: =SUMIFS('LANÇAMENTOS'!$G$6:$G$1005,'LANÇAMENTOS'!$I$6:$I$1005,($A$4*12+6),'LANÇAMENTOS'!$B$6:$B$1005,"ENTRADA",'LANÇAMENTOS'!$C$6:$C$1005,"REALIZADO") | C11: =SUMIFS('LANÇAMENTOS'!$G$6:$G$1005,'LANÇAMENTOS'!$I$6:$I$1005,($A$4*12+6),'LANÇAMENTOS'!$B$6:$B$1005,"ENTRADA",'LANÇAMENTOS'!$C$6:$C$1005,"PROJETADO") | D11: =B11+C11 | E11: =SUMIFS('LANÇAMENTOS'!$G$6:$G$1005,'LANÇAMENTOS'!$I$6:$I$1005,($A$4*12+6),'LANÇAMENTOS'!$B$6:$B$1005,"SAÍDA",'LANÇAMENTOS'!$C$6:$C$1005,"REALIZADO") | F11: =SUMIFS('LANÇAMENTOS'!$G$6:$G$1005,'LANÇAMENTOS'!$I$6:$I$1005,($A$4*12+6),'LANÇAMENTOS'!$B$6:$B$1005,"SAÍDA",'LANÇAMENTOS'!$C$6:$C$1005,"PROJETADO") | G11: =E11+F11 | H11: =SUMPRODUCT((PARCELAS!$C$6:$AL$65=($A$4*12+6))*PARCELAS!$AM$6:$BV$65) | I11: =D11-G11-H11 | J11: =J10+I11
A12: =INDEX(LISTAS!$K$6:$K$17,7) | B12: =SUMIFS('LANÇAMENTOS'!$G$6:$G$1005,'LANÇAMENTOS'!$I$6:$I$1005,($A$4*12+7),'LANÇAMENTOS'!$B$6:$B$1005,"ENTRADA",'LANÇAMENTOS'!$C$6:$C$1005,"REALIZADO") | C12: =SUMIFS('LANÇAMENTOS'!$G$6:$G$1005,'LANÇAMENTOS'!$I$6:$I$1005,($A$4*12+7),'LANÇAMENTOS'!$B$6:$B$1005,"ENTRADA",'LANÇAMENTOS'!$C$6:$C$1005,"PROJETADO") | D12: =B12+C12 | E12: =SUMIFS('LANÇAMENTOS'!$G$6:$G$1005,'LANÇAMENTOS'!$I$6:$I$1005,($A$4*12+7),'LANÇAMENTOS'!$B$6:$B$1005,"SAÍDA",'LANÇAMENTOS'!$C$6:$C$1005,"REALIZADO") | F12: =SUMIFS('LANÇAMENTOS'!$G$6:$G$1005,'LANÇAMENTOS'!$I$6:$I$1005,($A$4*12+7),'LANÇAMENTOS'!$B$6:$B$1005,"SAÍDA",'LANÇAMENTOS'!$C$6:$C$1005,"PROJETADO") | G12: =E12+F12 | H12: =SUMPRODUCT((PARCELAS!$C$6:$AL$65=($A$4*12+7))*PARCELAS!$AM$6:$BV$65) | I12: =D12-G12-H12 | J12: =J11+I12
A13: =INDEX(LISTAS!$K$6:$K$17,8) | B13: =SUMIFS('LANÇAMENTOS'!$G$6:$G$1005,'LANÇAMENTOS'!$I$6:$I$1005,($A$4*12+8),'LANÇAMENTOS'!$B$6:$B$1005,"ENTRADA",'LANÇAMENTOS'!$C$6:$C$1005,"REALIZADO") | C13: =SUMIFS('LANÇAMENTOS'!$G$6:$G$1005,'LANÇAMENTOS'!$I$6:$I$1005,($A$4*12+8),'LANÇAMENTOS'!$B$6:$B$1005,"ENTRADA",'LANÇAMENTOS'!$C$6:$C$1005,"PROJETADO") | D13: =B13+C13 | E13: =SUMIFS('LANÇAMENTOS'!$G$6:$G$1005,'LANÇAMENTOS'!$I$6:$I$1005,($A$4*12+8),'LANÇAMENTOS'!$B$6:$B$1005,"SAÍDA",'LANÇAMENTOS'!$C$6:$C$1005,"REALIZADO") | F13: =SUMIFS('LANÇAMENTOS'!$G$6:$G$1005,'LANÇAMENTOS'!$I$6:$I$1005,($A$4*12+8),'LANÇAMENTOS'!$B$6:$B$1005,"SAÍDA",'LANÇAMENTOS'!$C$6:$C$1005,"PROJETADO") | G13: =E13+F13 | H13: =SUMPRODUCT((PARCELAS!$C$6:$AL$65=($A$4*12+8))*PARCELAS!$AM$6:$BV$65) | I13: =D13-G13-H13 | J13: =J12+I13
A14: =INDEX(LISTAS!$K$6:$K$17,9) | B14: =SUMIFS('LANÇAMENTOS'!$G$6:$G$1005,'LANÇAMENTOS'!$I$6:$I$1005,($A$4*12+9),'LANÇAMENTOS'!$B$6:$B$1005,"ENTRADA",'LANÇAMENTOS'!$C$6:$C$1005,"REALIZADO") | C14: =SUMIFS('LANÇAMENTOS'!$G$6:$G$1005,'LANÇAMENTOS'!$I$6:$I$1005,($A$4*12+9),'LANÇAMENTOS'!$B$6:$B$1005,"ENTRADA",'LANÇAMENTOS'!$C$6:$C$1005,"PROJETADO") | D14: =B14+C14 | E14: =SUMIFS('LANÇAMENTOS'!$G$6:$G$1005,'LANÇAMENTOS'!$I$6:$I$1005,($A$4*12+9),'LANÇAMENTOS'!$B$6:$B$1005,"SAÍDA",'LANÇAMENTOS'!$C$6:$C$1005,"REALIZADO") | F14: =SUMIFS('LANÇAMENTOS'!$G$6:$G$1005,'LANÇAMENTOS'!$I$6:$I$1005,($A$4*12+9),'LANÇAMENTOS'!$B$6:$B$1005,"SAÍDA",'LANÇAMENTOS'!$C$6:$C$1005,"PROJETADO") | G14: =E14+F14 | H14: =SUMPRODUCT((PARCELAS!$C$6:$AL$65=($A$4*12+9))*PARCELAS!$AM$6:$BV$65) | I14: =D14-G14-H14 | J14: =J13+I14
A15: =INDEX(LISTAS!$K$6:$K$17,10) | B15: =SUMIFS('LANÇAMENTOS'!$G$6:$G$1005,'LANÇAMENTOS'!$I$6:$I$1005,($A$4*12+10),'LANÇAMENTOS'!$B$6:$B$1005,"ENTRADA",'LANÇAMENTOS'!$C$6:$C$1005,"REALIZADO") | C15: =SUMIFS('LANÇAMENTOS'!$G$6:$G$1005,'LANÇAMENTOS'!$I$6:$I$1005,($A$4*12+10),'LANÇAMENTOS'!$B$6:$B$1005,"ENTRADA",'LANÇAMENTOS'!$C$6:$C$1005,"PROJETADO") | D15: =B15+C15 | E15: =SUMIFS('LANÇAMENTOS'!$G$6:$G$1005,'LANÇAMENTOS'!$I$6:$I$1005,($A$4*12+10),'LANÇAMENTOS'!$B$6:$B$1005,"SAÍDA",'LANÇAMENTOS'!$C$6:$C$1005,"REALIZADO") | F15: =SUMIFS('LANÇAMENTOS'!$G$6:$G$1005,'LANÇAMENTOS'!$I$6:$I$1005,($A$4*12+10),'LANÇAMENTOS'!$B$6:$B$1005,"SAÍDA",'LANÇAMENTOS'!$C$6:$C$1005,"PROJETADO") | G15: =E15+F15 | H15: =SUMPRODUCT((PARCELAS!$C$6:$AL$65=($A$4*12+10))*PARCELAS!$AM$6:$BV$65) | I15: =D15-G15-H15 | J15: =J14+I15
A16: =INDEX(LISTAS!$K$6:$K$17,11) | B16: =SUMIFS('LANÇAMENTOS'!$G$6:$G$1005,'LANÇAMENTOS'!$I$6:$I$1005,($A$4*12+11),'LANÇAMENTOS'!$B$6:$B$1005,"ENTRADA",'LANÇAMENTOS'!$C$6:$C$1005,"REALIZADO") | C16: =SUMIFS('LANÇAMENTOS'!$G$6:$G$1005,'LANÇAMENTOS'!$I$6:$I$1005,($A$4*12+11),'LANÇAMENTOS'!$B$6:$B$1005,"ENTRADA",'LANÇAMENTOS'!$C$6:$C$1005,"PROJETADO") | D16: =B16+C16 | E16: =SUMIFS('LANÇAMENTOS'!$G$6:$G$1005,'LANÇAMENTOS'!$I$6:$I$1005,($A$4*12+11),'LANÇAMENTOS'!$B$6:$B$1005,"SAÍDA",'LANÇAMENTOS'!$C$6:$C$1005,"REALIZADO") | F16: =SUMIFS('LANÇAMENTOS'!$G$6:$G$1005,'LANÇAMENTOS'!$I$6:$I$1005,($A$4*12+11),'LANÇAMENTOS'!$B$6:$B$1005,"SAÍDA",'LANÇAMENTOS'!$C$6:$C$1005,"PROJETADO") | G16: =E16+F16 | H16: =SUMPRODUCT((PARCELAS!$C$6:$AL$65=($A$4*12+11))*PARCELAS!$AM$6:$BV$65) | I16: =D16-G16-H16 | J16: =J15+I16
A17: =INDEX(LISTAS!$K$6:$K$17,12) | B17: =SUMIFS('LANÇAMENTOS'!$G$6:$G$1005,'LANÇAMENTOS'!$I$6:$I$1005,($A$4*12+12),'LANÇAMENTOS'!$B$6:$B$1005,"ENTRADA",'LANÇAMENTOS'!$C$6:$C$1005,"REALIZADO") | C17: =SUMIFS('LANÇAMENTOS'!$G$6:$G$1005,'LANÇAMENTOS'!$I$6:$I$1005,($A$4*12+12),'LANÇAMENTOS'!$B$6:$B$1005,"ENTRADA",'LANÇAMENTOS'!$C$6:$C$1005,"PROJETADO") | D17: =B17+C17 | E17: =SUMIFS('LANÇAMENTOS'!$G$6:$G$1005,'LANÇAMENTOS'!$I$6:$I$1005,($A$4*12+12),'LANÇAMENTOS'!$B$6:$B$1005,"SAÍDA",'LANÇAMENTOS'!$C$6:$C$1005,"REALIZADO") | F17: =SUMIFS('LANÇAMENTOS'!$G$6:$G$1005,'LANÇAMENTOS'!$I$6:$I$1005,($A$4*12+12),'LANÇAMENTOS'!$B$6:$B$1005,"SAÍDA",'LANÇAMENTOS'!$C$6:$C$1005,"PROJETADO") | G17: =E17+F17 | H17: =SUMPRODUCT((PARCELAS!$C$6:$AL$65=($A$4*12+12))*PARCELAS!$AM$6:$BV$65) | I17: =D17-G17-H17 | J17: =J16+I17
A18: TOTAL DO ANO | B18: =SUM(B6:B17) | C18: =SUM(C6:C17) | D18: =SUM(D6:D17) | E18: =SUM(E6:E17) | F18: =SUM(F6:F17) | G18: =SUM(G6:G17) | H18: =SUM(H6:H17) | I18: =SUM(I6:I17) | J18: =J17
A21: SAÍDAS POR CATEGORIA, MÊS A MÊS
A22: Categoria | B22: Jan | C22: Fev | D22: Mar | E22: Abr | F22: Mai | G22: Jun | H22: Jul | I22: Ago | J22: Set | K22: Out | L22: Nov | M22: Dez | N22: Total do ano
A23: =IF(LISTAS!$B6="SAÍDA",LISTAS!$A6,"") | B23: =IF($A23="","",SUMIFS('LANÇAMENTOS'!$G$6:$G$1005,'LANÇAMENTOS'!$I$6:$I$1005,($A$4*12+1),'LANÇAMENTOS'!$B$6:$B$1005,"SAÍDA",'LANÇAMENTOS'!$D$6:$D$1005,$A23)) | C23: =IF($A23="","",SUMIFS('LANÇAMENTOS'!$G$6:$G$1005,'LANÇAMENTOS'!$I$6:$I$1005,($A$4*12+2),'LANÇAMENTOS'!$B$6:$B$1005,"SAÍDA",'LANÇAMENTOS'!$D$6:$D$1005,$A23)) | D23: =IF($A23="","",SUMIFS('LANÇAMENTOS'!$G$6:$G$1005,'LANÇAMENTOS'!$I$6:$I$1005,($A$4*12+3),'LANÇAMENTOS'!$B$6:$B$1005,"SAÍDA",'LANÇAMENTOS'!$D$6:$D$1005,$A23)) | E23: =IF($A23="","",SUMIFS('LANÇAMENTOS'!$G$6:$G$1005,'LANÇAMENTOS'!$I$6:$I$1005,($A$4*12+4),'LANÇAMENTOS'!$B$6:$B$1005,"SAÍDA",'LANÇAMENTOS'!$D$6:$D$1005,$A23)) | F23: =IF($A23="","",SUMIFS('LANÇAMENTOS'!$G$6:$G$1005,'LANÇAMENTOS'!$I$6:$I$1005,($A$4*12+5),'LANÇAMENTOS'!$B$6:$B$1005,"SAÍDA",'LANÇAMENTOS'!$D$6:$D$1005,$A23)) | G23: =IF($A23="","",SUMIFS('LANÇAMENTOS'!$G$6:$G$1005,'LANÇAMENTOS'!$I$6:$I$1005,($A$4*12+6),'LANÇAMENTOS'!$B$6:$B$1005,"SAÍDA",'LANÇAMENTOS'!$D$6:$D$1005,$A23)) | H23: =IF($A23="","",SUMIFS('LANÇAMENTOS'!$G$6:$G$1005,'LANÇAMENTOS'!$I$6:$I$1005,($A$4*12+7),'LANÇAMENTOS'!$B$6:$B$1005,"SAÍDA",'LANÇAMENTOS'!$D$6:$D$1005,$A23)) | I23: =IF($A23="","",SUMIFS('LANÇAMENTOS'!$G$6:$G$1005,'LANÇAMENTOS'!$I$6:$I$1005,($A$4*12+8),'LANÇAMENTOS'!$B$6:$B$1005,"SAÍDA",'LANÇAMENTOS'!$D$6:$D$1005,$A23)) | J23: =IF($A23="","",SUMIFS('LANÇAMENTOS'!$G$6:$G$1005,'LANÇAMENTOS'!$I$6:$I$1005,($A$4*12+9),'LANÇAMENTOS'!$B$6:$B$1005,"SAÍDA",'LANÇAMENTOS'!$D$6:$D$1005,$A23)) | K23: =IF($A23="","",SUMIFS('LANÇAMENTOS'!$G$6:$G$1005,'LANÇAMENTOS'!$I$6:$I$1005,($A$4*12+10),'LANÇAMENTOS'!$B$6:$B$1005,"SAÍDA",'LANÇAMENTOS'!$D$6:$D$1005,$A23)) | L23: =IF($A23="","",SUMIFS('LANÇAMENTOS'!$G$6:$G$1005,'LANÇAMENTOS'!$I$6:$I$1005,($A$4*12+11),'LANÇAMENTOS'!$B$6:$B$1005,"SAÍDA",'LANÇAMENTOS'!$D$6:$D$1005,$A23)) | M23: =IF($A23="","",SUMIFS('LANÇAMENTOS'!$G$6:$G$1005,'LANÇAMENTOS'!$I$6:$I$1005,($A$4*12+12),'LANÇAMENTOS'!$B$6:$B$1005,"SAÍDA",'LANÇAMENTOS'!$D$6:$D$1005,$A23)) | N23: =IF($A23="","",SUM(B23:M23))
A24: =IF(LISTAS!$B7="SAÍDA",LISTAS!$A7,"") | B24: =IF($A24="","",SUMIFS('LANÇAMENTOS'!$G$6:$G$1005,'LANÇAMENTOS'!$I$6:$I$1005,($A$4*12+1),'LANÇAMENTOS'!$B$6:$B$1005,"SAÍDA",'LANÇAMENTOS'!$D$6:$D$1005,$A24)) | C24: =IF($A24="","",SUMIFS('LANÇAMENTOS'!$G$6:$G$1005,'LANÇAMENTOS'!$I$6:$I$1005,($A$4*12+2),'LANÇAMENTOS'!$B$6:$B$1005,"SAÍDA",'LANÇAMENTOS'!$D$6:$D$1005,$A24)) | D24: =IF($A24="","",SUMIFS('LANÇAMENTOS'!$G$6:$G$1005,'LANÇAMENTOS'!$I$6:$I$1005,($A$4*12+3),'LANÇAMENTOS'!$B$6:$B$1005,"SAÍDA",'LANÇAMENTOS'!$D$6:$D$1005,$A24)) | E24: =IF($A24="","",SUMIFS('LANÇAMENTOS'!$G$6:$G$1005,'LANÇAMENTOS'!$I$6:$I$1005,($A$4*12+4),'LANÇAMENTOS'!$B$6:$B$1005,"SAÍDA",'LANÇAMENTOS'!$D$6:$D$1005,$A24)) | F24: =IF($A24="","",SUMIFS('LANÇAMENTOS'!$G$6:$G$1005,'LANÇAMENTOS'!$I$6:$I$1005,($A$4*12+5),'LANÇAMENTOS'!$B$6:$B$1005,"SAÍDA",'LANÇAMENTOS'!$D$6:$D$1005,$A24)) | G24: =IF($A24="","",SUMIFS('LANÇAMENTOS'!$G$6:$G$1005,'LANÇAMENTOS'!$I$6:$I$1005,($A$4*12+6),'LANÇAMENTOS'!$B$6:$B$1005,"SAÍDA",'LANÇAMENTOS'!$D$6:$D$1005,$A24)) | H24: =IF($A24="","",SUMIFS('LANÇAMENTOS'!$G$6:$G$1005,'LANÇAMENTOS'!$I$6:$I$1005,($A$4*12+7),'LANÇAMENTOS'!$B$6:$B$1005,"SAÍDA",'LANÇAMENTOS'!$D$6:$D$1005,$A24)) | I24: =IF($A24="","",SUMIFS('LANÇAMENTOS'!$G$6:$G$1005,'LANÇAMENTOS'!$I$6:$I$1005,($A$4*12+8),'LANÇAMENTOS'!$B$6:$B$1005,"SAÍDA",'LANÇAMENTOS'!$D$6:$D$1005,$A24)) | J24: =IF($A24="","",SUMIFS('LANÇAMENTOS'!$G$6:$G$1005,'LANÇAMENTOS'!$I$6:$I$1005,($A$4*12+9),'LANÇAMENTOS'!$B$6:$B$1005,"SAÍDA",'LANÇAMENTOS'!$D$6:$D$1005,$A24)) | K24: =IF($A24="","",SUMIFS('LANÇAMENTOS'!$G$6:$G$1005,'LANÇAMENTOS'!$I$6:$I$1005,($A$4*12+10),'LANÇAMENTOS'!$B$6:$B$1005,"SAÍDA",'LANÇAMENTOS'!$D$6:$D$1005,$A24)) | L24: =IF($A24="","",SUMIFS('LANÇAMENTOS'!$G$6:$G$1005,'LANÇAMENTOS'!$I$6:$I$1005,($A$4*12+11),'LANÇAMENTOS'!$B$6:$B$1005,"SAÍDA",'LANÇAMENTOS'!$D$6:$D$1005,$A24)) | M24: =IF($A24="","",SUMIFS('LANÇAMENTOS'!$G$6:$G$1005,'LANÇAMENTOS'!$I$6:$I$1005,($A$4*12+12),'LANÇAMENTOS'!$B$6:$B$1005,"SAÍDA",'LANÇAMENTOS'!$D$6:$D$1005,$A24)) | N24: =IF($A24="","",SUM(B24:M24))
A25: =IF(LISTAS!$B8="SAÍDA",LISTAS!$A8,"") | B25: =IF($A25="","",SUMIFS('LANÇAMENTOS'!$G$6:$G$1005,'LANÇAMENTOS'!$I$6:$I$1005,($A$4*12+1),'LANÇAMENTOS'!$B$6:$B$1005,"SAÍDA",'LANÇAMENTOS'!$D$6:$D$1005,$A25)) | C25: =IF($A25="","",SUMIFS('LANÇAMENTOS'!$G$6:$G$1005,'LANÇAMENTOS'!$I$6:$I$1005,($A$4*12+2),'LANÇAMENTOS'!$B$6:$B$1005,"SAÍDA",'LANÇAMENTOS'!$D$6:$D$1005,$A25)) | D25: =IF($A25="","",SUMIFS('LANÇAMENTOS'!$G$6:$G$1005,'LANÇAMENTOS'!$I$6:$I$1005,($A$4*12+3),'LANÇAMENTOS'!$B$6:$B$1005,"SAÍDA",'LANÇAMENTOS'!$D$6:$D$1005,$A25)) | E25: =IF($A25="","",SUMIFS('LANÇAMENTOS'!$G$6:$G$1005,'LANÇAMENTOS'!$I$6:$I$1005,($A$4*12+4),'LANÇAMENTOS'!$B$6:$B$1005,"SAÍDA",'LANÇAMENTOS'!$D$6:$D$1005,$A25)) | F25: =IF($A25="","",SUMIFS('LANÇAMENTOS'!$G$6:$G$1005,'LANÇAMENTOS'!$I$6:$I$1005,($A$4*12+5),'LANÇAMENTOS'!$B$6:$B$1005,"SAÍDA",'LANÇAMENTOS'!$D$6:$D$1005,$A25)) | G25: =IF($A25="","",SUMIFS('LANÇAMENTOS'!$G$6:$G$1005,'LANÇAMENTOS'!$I$6:$I$1005,($A$4*12+6),'LANÇAMENTOS'!$B$6:$B$1005,"SAÍDA",'LANÇAMENTOS'!$D$6:$D$1005,$A25)) | H25: =IF($A25="","",SUMIFS('LANÇAMENTOS'!$G$6:$G$1005,'LANÇAMENTOS'!$I$6:$I$1005,($A$4*12+7),'LANÇAMENTOS'!$B$6:$B$1005,"SAÍDA",'LANÇAMENTOS'!$D$6:$D$1005,$A25)) | I25: =IF($A25="","",SUMIFS('LANÇAMENTOS'!$G$6:$G$1005,'LANÇAMENTOS'!$I$6:$I$1005,($A$4*12+8),'LANÇAMENTOS'!$B$6:$B$1005,"SAÍDA",'LANÇAMENTOS'!$D$6:$D$1005,$A25)) | J25: =IF($A25="","",SUMIFS('LANÇAMENTOS'!$G$6:$G$1005,'LANÇAMENTOS'!$I$6:$I$1005,($A$4*12+9),'LANÇAMENTOS'!$B$6:$B$1005,"SAÍDA",'LANÇAMENTOS'!$D$6:$D$1005,$A25)) | K25: =IF($A25="","",SUMIFS('LANÇAMENTOS'!$G$6:$G$1005,'LANÇAMENTOS'!$I$6:$I$1005,($A$4*12+10),'LANÇAMENTOS'!$B$6:$B$1005,"SAÍDA",'LANÇAMENTOS'!$D$6:$D$1005,$A25)) | L25: =IF($A25="","",SUMIFS('LANÇAMENTOS'!$G$6:$G$1005,'LANÇAMENTOS'!$I$6:$I$1005,($A$4*12+11),'LANÇAMENTOS'!$B$6:$B$1005,"SAÍDA",'LANÇAMENTOS'!$D$6:$D$1005,$A25)) | M25: =IF($A25="","",SUMIFS('LANÇAMENTOS'!$G$6:$G$1005,'LANÇAMENTOS'!$I$6:$I$1005,($A$4*12+12),'LANÇAMENTOS'!$B$6:$B$1005,"SAÍDA",'LANÇAMENTOS'!$D$6:$D$1005,$A25)) | N25: =IF($A25="","",SUM(B25:M25))
A26: =IF(LISTAS!$B9="SAÍDA",LISTAS!$A9,"") | B26: =IF($A26="","",SUMIFS('LANÇAMENTOS'!$G$6:$G$1005,'LANÇAMENTOS'!$I$6:$I$1005,($A$4*12+1),'LANÇAMENTOS'!$B$6:$B$1005,"SAÍDA",'LANÇAMENTOS'!$D$6:$D$1005,$A26)) | C26: =IF($A26="","",SUMIFS('LANÇAMENTOS'!$G$6:$G$1005,'LANÇAMENTOS'!$I$6:$I$1005,($A$4*12+2),'LANÇAMENTOS'!$B$6:$B$1005,"SAÍDA",'LANÇAMENTOS'!$D$6:$D$1005,$A26)) | D26: =IF($A26="","",SUMIFS('LANÇAMENTOS'!$G$6:$G$1005,'LANÇAMENTOS'!$I$6:$I$1005,($A$4*12+3),'LANÇAMENTOS'!$B$6:$B$1005,"SAÍDA",'LANÇAMENTOS'!$D$6:$D$1005,$A26)) | E26: =IF($A26="","",SUMIFS('LANÇAMENTOS'!$G$6:$G$1005,'LANÇAMENTOS'!$I$6:$I$1005,($A$4*12+4),'LANÇAMENTOS'!$B$6:$B$1005,"SAÍDA",'LANÇAMENTOS'!$D$6:$D$1005,$A26)) | F26: =IF($A26="","",SUMIFS('LANÇAMENTOS'!$G$6:$G$1005,'LANÇAMENTOS'!$I$6:$I$1005,($A$4*12+5),'LANÇAMENTOS'!$B$6:$B$1005,"SAÍDA",'LANÇAMENTOS'!$D$6:$D$1005,$A26)) | G26: =IF($A26="","",SUMIFS('LANÇAMENTOS'!$G$6:$G$1005,'LANÇAMENTOS'!$I$6:$I$1005,($A$4*12+6),'LANÇAMENTOS'!$B$6:$B$1005,"SAÍDA",'LANÇAMENTOS'!$D$6:$D$1005,$A26)) | H26: =IF($A26="","",SUMIFS('LANÇAMENTOS'!$G$6:$G$1005,'LANÇAMENTOS'!$I$6:$I$1005,($A$4*12+7),'LANÇAMENTOS'!$B$6:$B$1005,"SAÍDA",'LANÇAMENTOS'!$D$6:$D$1005,$A26)) | I26: =IF($A26="","",SUMIFS('LANÇAMENTOS'!$G$6:$G$1005,'LANÇAMENTOS'!$I$6:$I$1005,($A$4*12+8),'LANÇAMENTOS'!$B$6:$B$1005,"SAÍDA",'LANÇAMENTOS'!$D$6:$D$1005,$A26)) | J26: =IF($A26="","",SUMIFS('LANÇAMENTOS'!$G$6:$G$1005,'LANÇAMENTOS'!$I$6:$I$1005,($A$4*12+9),'LANÇAMENTOS'!$B$6:$B$1005,"SAÍDA",'LANÇAMENTOS'!$D$6:$D$1005,$A26)) | K26: =IF($A26="","",SUMIFS('LANÇAMENTOS'!$G$6:$G$1005,'LANÇAMENTOS'!$I$6:$I$1005,($A$4*12+10),'LANÇAMENTOS'!$B$6:$B$1005,"SAÍDA",'LANÇAMENTOS'!$D$6:$D$1005,$A26)) | L26: =IF($A26="","",SUMIFS('LANÇAMENTOS'!$G$6:$G$1005,'LANÇAMENTOS'!$I$6:$I$1005,($A$4*12+11),'LANÇAMENTOS'!$B$6:$B$1005,"SAÍDA",'LANÇAMENTOS'!$D$6:$D$1005,$A26)) | M26: =IF($A26="","",SUMIFS('LANÇAMENTOS'!$G$6:$G$1005,'LANÇAMENTOS'!$I$6:$I$1005,($A$4*12+12),'LANÇAMENTOS'!$B$6:$B$1005,"SAÍDA",'LANÇAMENTOS'!$D$6:$D$1005,$A26)) | N26: =IF($A26="","",SUM(B26:M26))
A27: =IF(LISTAS!$B10="SAÍDA",LISTAS!$A10,"") | B27: =IF($A27="","",SUMIFS('LANÇAMENTOS'!$G$6:$G$1005,'LANÇAMENTOS'!$I$6:$I$1005,($A$4*12+1),'LANÇAMENTOS'!$B$6:$B$1005,"SAÍDA",'LANÇAMENTOS'!$D$6:$D$1005,$A27)) | C27: =IF($A27="","",SUMIFS('LANÇAMENTOS'!$G$6:$G$1005,'LANÇAMENTOS'!$I$6:$I$1005,($A$4*12+2),'LANÇAMENTOS'!$B$6:$B$1005,"SAÍDA",'LANÇAMENTOS'!$D$6:$D$1005,$A27)) | D27: =IF($A27="","",SUMIFS('LANÇAMENTOS'!$G$6:$G$1005,'LANÇAMENTOS'!$I$6:$I$1005,($A$4*12+3),'LANÇAMENTOS'!$B$6:$B$1005,"SAÍDA",'LANÇAMENTOS'!$D$6:$D$1005,$A27)) | E27: =IF($A27="","",SUMIFS('LANÇAMENTOS'!$G$6:$G$1005,'LANÇAMENTOS'!$I$6:$I$1005,($A$4*12+4),'LANÇAMENTOS'!$B$6:$B$1005,"SAÍDA",'LANÇAMENTOS'!$D$6:$D$1005,$A27)) | F27: =IF($A27="","",SUMIFS('LANÇAMENTOS'!$G$6:$G$1005,'LANÇAMENTOS'!$I$6:$I$1005,($A$4*12+5),'LANÇAMENTOS'!$B$6:$B$1005,"SAÍDA",'LANÇAMENTOS'!$D$6:$D$1005,$A27)) | G27: =IF($A27="","",SUMIFS('LANÇAMENTOS'!$G$6:$G$1005,'LANÇAMENTOS'!$I$6:$I$1005,($A$4*12+6),'LANÇAMENTOS'!$B$6:$B$1005,"SAÍDA",'LANÇAMENTOS'!$D$6:$D$1005,$A27)) | H27: =IF($A27="","",SUMIFS('LANÇAMENTOS'!$G$6:$G$1005,'LANÇAMENTOS'!$I$6:$I$1005,($A$4*12+7),'LANÇAMENTOS'!$B$6:$B$1005,"SAÍDA",'LANÇAMENTOS'!$D$6:$D$1005,$A27)) | I27: =IF($A27="","",SUMIFS('LANÇAMENTOS'!$G$6:$G$1005,'LANÇAMENTOS'!$I$6:$I$1005,($A$4*12+8),'LANÇAMENTOS'!$B$6:$B$1005,"SAÍDA",'LANÇAMENTOS'!$D$6:$D$1005,$A27)) | J27: =IF($A27="","",SUMIFS('LANÇAMENTOS'!$G$6:$G$1005,'LANÇAMENTOS'!$I$6:$I$1005,($A$4*12+9),'LANÇAMENTOS'!$B$6:$B$1005,"SAÍDA",'LANÇAMENTOS'!$D$6:$D$1005,$A27)) | K27: =IF($A27="","",SUMIFS('LANÇAMENTOS'!$G$6:$G$1005,'LANÇAMENTOS'!$I$6:$I$1005,($A$4*12+10),'LANÇAMENTOS'!$B$6:$B$1005,"SAÍDA",'LANÇAMENTOS'!$D$6:$D$1005,$A27)) | L27: =IF($A27="","",SUMIFS('LANÇAMENTOS'!$G$6:$G$1005,'LANÇAMENTOS'!$I$6:$I$1005,($A$4*12+11),'LANÇAMENTOS'!$B$6:$B$1005,"SAÍDA",'LANÇAMENTOS'!$D$6:$D$1005,$A27)) | M27: =IF($A27="","",SUMIFS('LANÇAMENTOS'!$G$6:$G$1005,'LANÇAMENTOS'!$I$6:$I$1005,($A$4*12+12),'LANÇAMENTOS'!$B$6:$B$1005,"SAÍDA",'LANÇAMENTOS'!$D$6:$D$1005,$A27)) | N27: =IF($A27="","",SUM(B27:M27))
A28: =IF(LISTAS!$B11="SAÍDA",LISTAS!$A11,"") | B28: =IF($A28="","",SUMIFS('LANÇAMENTOS'!$G$6:$G$1005,'LANÇAMENTOS'!$I$6:$I$1005,($A$4*12+1),'LANÇAMENTOS'!$B$6:$B$1005,"SAÍDA",'LANÇAMENTOS'!$D$6:$D$1005,$A28)) | C28: =IF($A28="","",SUMIFS('LANÇAMENTOS'!$G$6:$G$1005,'LANÇAMENTOS'!$I$6:$I$1005,($A$4*12+2),'LANÇAMENTOS'!$B$6:$B$1005,"SAÍDA",'LANÇAMENTOS'!$D$6:$D$1005,$A28)) | D28: =IF($A28="","",SUMIFS('LANÇAMENTOS'!$G$6:$G$1005,'LANÇAMENTOS'!$I$6:$I$1005,($A$4*12+3),'LANÇAMENTOS'!$B$6:$B$1005,"SAÍDA",'LANÇAMENTOS'!$D$6:$D$1005,$A28)) | E28: =IF($A28="","",SUMIFS('LANÇAMENTOS'!$G$6:$G$1005,'LANÇAMENTOS'!$I$6:$I$1005,($A$4*12+4),'LANÇAMENTOS'!$B$6:$B$1005,"SAÍDA",'LANÇAMENTOS'!$D$6:$D$1005,$A28)) | F28: =IF($A28="","",SUMIFS('LANÇAMENTOS'!$G$6:$G$1005,'LANÇAMENTOS'!$I$6:$I$1005,($A$4*12+5),'LANÇAMENTOS'!$B$6:$B$1005,"SAÍDA",'LANÇAMENTOS'!$D$6:$D$1005,$A28)) | G28: =IF($A28="","",SUMIFS('LANÇAMENTOS'!$G$6:$G$1005,'LANÇAMENTOS'!$I$6:$I$1005,($A$4*12+6),'LANÇAMENTOS'!$B$6:$B$1005,"SAÍDA",'LANÇAMENTOS'!$D$6:$D$1005,$A28)) | H28: =IF($A28="","",SUMIFS('LANÇAMENTOS'!$G$6:$G$1005,'LANÇAMENTOS'!$I$6:$I$1005,($A$4*12+7),'LANÇAMENTOS'!$B$6:$B$1005,"SAÍDA",'LANÇAMENTOS'!$D$6:$D$1005,$A28)) | I28: =IF($A28="","",SUMIFS('LANÇAMENTOS'!$G$6:$G$1005,'LANÇAMENTOS'!$I$6:$I$1005,($A$4*12+8),'LANÇAMENTOS'!$B$6:$B$1005,"SAÍDA",'LANÇAMENTOS'!$D$6:$D$1005,$A28)) | J28: =IF($A28="","",SUMIFS('LANÇAMENTOS'!$G$6:$G$1005,'LANÇAMENTOS'!$I$6:$I$1005,($A$4*12+9),'LANÇAMENTOS'!$B$6:$B$1005,"SAÍDA",'LANÇAMENTOS'!$D$6:$D$1005,$A28)) | K28: =IF($A28="","",SUMIFS('LANÇAMENTOS'!$G$6:$G$1005,'LANÇAMENTOS'!$I$6:$I$1005,($A$4*12+10),'LANÇAMENTOS'!$B$6:$B$1005,"SAÍDA",'LANÇAMENTOS'!$D$6:$D$1005,$A28)) | L28: =IF($A28="","",SUMIFS('LANÇAMENTOS'!$G$6:$G$1005,'LANÇAMENTOS'!$I$6:$I$1005,($A$4*12+11),'LANÇAMENTOS'!$B$6:$B$1005,"SAÍDA",'LANÇAMENTOS'!$D$6:$D$1005,$A28)) | M28: =IF($A28="","",SUMIFS('LANÇAMENTOS'!$G$6:$G$1005,'LANÇAMENTOS'!$I$6:$I$1005,($A$4*12+12),'LANÇAMENTOS'!$B$6:$B$1005,"SAÍDA",'LANÇAMENTOS'!$D$6:$D$1005,$A28)) | N28: =IF($A28="","",SUM(B28:M28))
A29: =IF(LISTAS!$B12="SAÍDA",LISTAS!$A12,"") | B29: =IF($A29="","",SUMIFS('LANÇAMENTOS'!$G$6:$G$1005,'LANÇAMENTOS'!$I$6:$I$1005,($A$4*12+1),'LANÇAMENTOS'!$B$6:$B$1005,"SAÍDA",'LANÇAMENTOS'!$D$6:$D$1005,$A29)) | C29: =IF($A29="","",SUMIFS('LANÇAMENTOS'!$G$6:$G$1005,'LANÇAMENTOS'!$I$6:$I$1005,($A$4*12+2),'LANÇAMENTOS'!$B$6:$B$1005,"SAÍDA",'LANÇAMENTOS'!$D$6:$D$1005,$A29)) | D29: =IF($A29="","",SUMIFS('LANÇAMENTOS'!$G$6:$G$1005,'LANÇAMENTOS'!$I$6:$I$1005,($A$4*12+3),'LANÇAMENTOS'!$B$6:$B$1005,"SAÍDA",'LANÇAMENTOS'!$D$6:$D$1005,$A29)) | E29: =IF($A29="","",SUMIFS('LANÇAMENTOS'!$G$6:$G$1005,'LANÇAMENTOS'!$I$6:$I$1005,($A$4*12+4),'LANÇAMENTOS'!$B$6:$B$1005,"SAÍDA",'LANÇAMENTOS'!$D$6:$D$1005,$A29)) | F29: =IF($A29="","",SUMIFS('LANÇAMENTOS'!$G$6:$G$1005,'LANÇAMENTOS'!$I$6:$I$1005,($A$4*12+5),'LANÇAMENTOS'!$B$6:$B$1005,"SAÍDA",'LANÇAMENTOS'!$D$6:$D$1005,$A29)) | G29: =IF($A29="","",SUMIFS('LANÇAMENTOS'!$G$6:$G$1005,'LANÇAMENTOS'!$I$6:$I$1005,($A$4*12+6),'LANÇAMENTOS'!$B$6:$B$1005,"SAÍDA",'LANÇAMENTOS'!$D$6:$D$1005,$A29)) | H29: =IF($A29="","",SUMIFS('LANÇAMENTOS'!$G$6:$G$1005,'LANÇAMENTOS'!$I$6:$I$1005,($A$4*12+7),'LANÇAMENTOS'!$B$6:$B$1005,"SAÍDA",'LANÇAMENTOS'!$D$6:$D$1005,$A29)) | I29: =IF($A29="","",SUMIFS('LANÇAMENTOS'!$G$6:$G$1005,'LANÇAMENTOS'!$I$6:$I$1005,($A$4*12+8),'LANÇAMENTOS'!$B$6:$B$1005,"SAÍDA",'LANÇAMENTOS'!$D$6:$D$1005,$A29)) | J29: =IF($A29="","",SUMIFS('LANÇAMENTOS'!$G$6:$G$1005,'LANÇAMENTOS'!$I$6:$I$1005,($A$4*12+9),'LANÇAMENTOS'!$B$6:$B$1005,"SAÍDA",'LANÇAMENTOS'!$D$6:$D$1005,$A29)) | K29: =IF($A29="","",SUMIFS('LANÇAMENTOS'!$G$6:$G$1005,'LANÇAMENTOS'!$I$6:$I$1005,($A$4*12+10),'LANÇAMENTOS'!$B$6:$B$1005,"SAÍDA",'LANÇAMENTOS'!$D$6:$D$1005,$A29)) | L29: =IF($A29="","",SUMIFS('LANÇAMENTOS'!$G$6:$G$1005,'LANÇAMENTOS'!$I$6:$I$1005,($A$4*12+11),'LANÇAMENTOS'!$B$6:$B$1005,"SAÍDA",'LANÇAMENTOS'!$D$6:$D$1005,$A29)) | M29: =IF($A29="","",SUMIFS('LANÇAMENTOS'!$G$6:$G$1005,'LANÇAMENTOS'!$I$6:$I$1005,($A$4*12+12),'LANÇAMENTOS'!$B$6:$B$1005,"SAÍDA",'LANÇAMENTOS'!$D$6:$D$1005,$A29)) | N29: =IF($A29="","",SUM(B29:M29))
A30: =IF(LISTAS!$B13="SAÍDA",LISTAS!$A13,"") | B30: =IF($A30="","",SUMIFS('LANÇAMENTOS'!$G$6:$G$1005,'LANÇAMENTOS'!$I$6:$I$1005,($A$4*12+1),'LANÇAMENTOS'!$B$6:$B$1005,"SAÍDA",'LANÇAMENTOS'!$D$6:$D$1005,$A30)) | C30: =IF($A30="","",SUMIFS('LANÇAMENTOS'!$G$6:$G$1005,'LANÇAMENTOS'!$I$6:$I$1005,($A$4*12+2),'LANÇAMENTOS'!$B$6:$B$1005,"SAÍDA",'LANÇAMENTOS'!$D$6:$D$1005,$A30)) | D30: =IF($A30="","",SUMIFS('LANÇAMENTOS'!$G$6:$G$1005,'LANÇAMENTOS'!$I$6:$I$1005,($A$4*12+3),'LANÇAMENTOS'!$B$6:$B$1005,"SAÍDA",'LANÇAMENTOS'!$D$6:$D$1005,$A30)) | E30: =IF($A30="","",SUMIFS('LANÇAMENTOS'!$G$6:$G$1005,'LANÇAMENTOS'!$I$6:$I$1005,($A$4*12+4),'LANÇAMENTOS'!$B$6:$B$1005,"SAÍDA",'LANÇAMENTOS'!$D$6:$D$1005,$A30)) | F30: =IF($A30="","",SUMIFS('LANÇAMENTOS'!$G$6:$G$1005,'LANÇAMENTOS'!$I$6:$I$1005,($A$4*12+5),'LANÇAMENTOS'!$B$6:$B$1005,"SAÍDA",'LANÇAMENTOS'!$D$6:$D$1005,$A30)) | G30: =IF($A30="","",SUMIFS('LANÇAMENTOS'!$G$6:$G$1005,'LANÇAMENTOS'!$I$6:$I$1005,($A$4*12+6),'LANÇAMENTOS'!$B$6:$B$1005,"SAÍDA",'LANÇAMENTOS'!$D$6:$D$1005,$A30)) | H30: =IF($A30="","",SUMIFS('LANÇAMENTOS'!$G$6:$G$1005,'LANÇAMENTOS'!$I$6:$I$1005,($A$4*12+7),'LANÇAMENTOS'!$B$6:$B$1005,"SAÍDA",'LANÇAMENTOS'!$D$6:$D$1005,$A30)) | I30: =IF($A30="","",SUMIFS('LANÇAMENTOS'!$G$6:$G$1005,'LANÇAMENTOS'!$I$6:$I$1005,($A$4*12+8),'LANÇAMENTOS'!$B$6:$B$1005,"SAÍDA",'LANÇAMENTOS'!$D$6:$D$1005,$A30)) | J30: =IF($A30="","",SUMIFS('LANÇAMENTOS'!$G$6:$G$1005,'LANÇAMENTOS'!$I$6:$I$1005,($A$4*12+9),'LANÇAMENTOS'!$B$6:$B$1005,"SAÍDA",'LANÇAMENTOS'!$D$6:$D$1005,$A30)) | K30: =IF($A30="","",SUMIFS('LANÇAMENTOS'!$G$6:$G$1005,'LANÇAMENTOS'!$I$6:$I$1005,($A$4*12+10),'LANÇAMENTOS'!$B$6:$B$1005,"SAÍDA",'LANÇAMENTOS'!$D$6:$D$1005,$A30)) | L30: =IF($A30="","",SUMIFS('LANÇAMENTOS'!$G$6:$G$1005,'LANÇAMENTOS'!$I$6:$I$1005,($A$4*12+11),'LANÇAMENTOS'!$B$6:$B$1005,"SAÍDA",'LANÇAMENTOS'!$D$6:$D$1005,$A30)) | M30: =IF($A30="","",SUMIFS('LANÇAMENTOS'!$G$6:$G$1005,'LANÇAMENTOS'!$I$6:$I$1005,($A$4*12+12),'LANÇAMENTOS'!$B$6:$B$1005,"SAÍDA",'LANÇAMENTOS'!$D$6:$D$1005,$A30)) | N30: =IF($A30="","",SUM(B30:M30))
A31: =IF(LISTAS!$B14="SAÍDA",LISTAS!$A14,"") | B31: =IF($A31="","",SUMIFS('LANÇAMENTOS'!$G$6:$G$1005,'LANÇAMENTOS'!$I$6:$I$1005,($A$4*12+1),'LANÇAMENTOS'!$B$6:$B$1005,"SAÍDA",'LANÇAMENTOS'!$D$6:$D$1005,$A31)) | C31: =IF($A31="","",SUMIFS('LANÇAMENTOS'!$G$6:$G$1005,'LANÇAMENTOS'!$I$6:$I$1005,($A$4*12+2),'LANÇAMENTOS'!$B$6:$B$1005,"SAÍDA",'LANÇAMENTOS'!$D$6:$D$1005,$A31)) | D31: =IF($A31="","",SUMIFS('LANÇAMENTOS'!$G$6:$G$1005,'LANÇAMENTOS'!$I$6:$I$1005,($A$4*12+3),'LANÇAMENTOS'!$B$6:$B$1005,"SAÍDA",'LANÇAMENTOS'!$D$6:$D$1005,$A31)) | E31: =IF($A31="","",SUMIFS('LANÇAMENTOS'!$G$6:$G$1005,'LANÇAMENTOS'!$I$6:$I$1005,($A$4*12+4),'LANÇAMENTOS'!$B$6:$B$1005,"SAÍDA",'LANÇAMENTOS'!$D$6:$D$1005,$A31)) | F31: =IF($A31="","",SUMIFS('LANÇAMENTOS'!$G$6:$G$1005,'LANÇAMENTOS'!$I$6:$I$1005,($A$4*12+5),'LANÇAMENTOS'!$B$6:$B$1005,"SAÍDA",'LANÇAMENTOS'!$D$6:$D$1005,$A31)) | G31: =IF($A31="","",SUMIFS('LANÇAMENTOS'!$G$6:$G$1005,'LANÇAMENTOS'!$I$6:$I$1005,($A$4*12+6),'LANÇAMENTOS'!$B$6:$B$1005,"SAÍDA",'LANÇAMENTOS'!$D$6:$D$1005,$A31)) | H31: =IF($A31="","",SUMIFS('LANÇAMENTOS'!$G$6:$G$1005,'LANÇAMENTOS'!$I$6:$I$1005,($A$4*12+7),'LANÇAMENTOS'!$B$6:$B$1005,"SAÍDA",'LANÇAMENTOS'!$D$6:$D$1005,$A31)) | I31: =IF($A31="","",SUMIFS('LANÇAMENTOS'!$G$6:$G$1005,'LANÇAMENTOS'!$I$6:$I$1005,($A$4*12+8),'LANÇAMENTOS'!$B$6:$B$1005,"SAÍDA",'LANÇAMENTOS'!$D$6:$D$1005,$A31)) | J31: =IF($A31="","",SUMIFS('LANÇAMENTOS'!$G$6:$G$1005,'LANÇAMENTOS'!$I$6:$I$1005,($A$4*12+9),'LANÇAMENTOS'!$B$6:$B$1005,"SAÍDA",'LANÇAMENTOS'!$D$6:$D$1005,$A31)) | K31: =IF($A31="","",SUMIFS('LANÇAMENTOS'!$G$6:$G$1005,'LANÇAMENTOS'!$I$6:$I$1005,($A$4*12+10),'LANÇAMENTOS'!$B$6:$B$1005,"SAÍDA",'LANÇAMENTOS'!$D$6:$D$1005,$A31)) | L31: =IF($A31="","",SUMIFS('LANÇAMENTOS'!$G$6:$G$1005,'LANÇAMENTOS'!$I$6:$I$1005,($A$4*12+11),'LANÇAMENTOS'!$B$6:$B$1005,"SAÍDA",'LANÇAMENTOS'!$D$6:$D$1005,$A31)) | M31: =IF($A31="","",SUMIFS('LANÇAMENTOS'!$G$6:$G$1005,'LANÇAMENTOS'!$I$6:$I$1005,($A$4*12+12),'LANÇAMENTOS'!$B$6:$B$1005,"SAÍDA",'LANÇAMENTOS'!$D$6:$D$1005,$A31)) | N31: =IF($A31="","",SUM(B31:M31))
