Workbook

Sheet DASHBOARD
A1: PAINEL FINANCEIRO PESSOAL - GUARANI (Gs.)
A2: Data de referencia e parametros na aba CFG_Sistema. Valores REALIZADOS salvo quando o titulo do indicador disser projetado.
A4: DINHEIRO
A5: SALDO TOTAL DAS CONTAS | C5: RESERVADO PARA METAS | E5: SALDO DISPONIVEL (LIVRE) | G5: SALDO PROJETADO (FIM DO HORIZONTE)
A6: =SUM(C_SALDO) -> 0 | C6: =SUM(C_RESERV) -> 0 | E6: =SUM(C_DISP) -> 0 | G6: =INDEX(PJ_SALDO,COUNT(PJ_SALDO)) -> 0
A8: INVESTIMENTOS E PATRIMONIO
A9: TOTAL INVESTIDO | C9: RENDIMENTO REALIZADO | E9: RENDIMENTO PROJETADO | G9: PATRIMONIO LIQUIDO TOTAL
A10: =SUM(I_SALDO) -> 0 | C10: =SUM(I_REND) -> 0 | E10: =SUM(I_RENDPROJ) -> 0 | G10: =PAT_PL_TOTAL -> 0
A12: DIVIDAS
A13: DIVIDA DE CARTOES | C13: LIMITE DISPONIVEL EM CARTOES | E13: SALDO DEVEDOR DE COMPROMISSOS | G13: PARCELAS + FATURAS PROXIMOS 12 MESES
A14: =SUM(K_DIVIDA) -> 0 | C14: =SUM(K_DISP) -> 0 | E14: =SUM(CM_DEVEDOR) -> 0 | G14: =SUMIFS(L_Valor,L_Data,">"&CFG_HOJE,L_Data,"<="&EDATE(CFG_HOJE,12),L_Status,"PROJETADO",L_ParcID,"<>")+SUMIFS(L_Valor,L_Data,">"&CFG_HOJE,L_Data,"<="&EDATE(CFG_HOJE,12),L_Status,"PROJETADO",L_Tipo,"PAGAMENTO_CARTAO") -> 0
A16: FLUXO DO MES CORRENTE
A17: RECEITAS REALIZADAS NO MES | C17: DESPESAS REALIZADAS NO MES | E17: RESULTADO DO MES | G17: MENOR SALDO PROJETADO NO HORIZONTE
A18: =SUMIFS(L_VRec,L_Data,">="&DATE(YEAR(CFG_HOJE),MONTH(CFG_HOJE),1),L_Data,"<="&EOMONTH(CFG_HOJE,0),L_Status,"REALIZADO") -> 0 | C18: =SUMIFS(L_VDesp,L_Data,">="&DATE(YEAR(CFG_HOJE),MONTH(CFG_HOJE),1),L_Data,"<="&EOMONTH(CFG_HOJE,0),L_Status,"REALIZADO") -> 0 | E18: =SUMIFS(L_VRec,L_Data,">="&DATE(YEAR(CFG_HOJE),MONTH(CFG_HOJE),1),L_Data,"<="&EOMONTH(CFG_HOJE,0),L_Status,"REALIZADO")+SUMIFS(L_VRend,L_Data,">="&DATE(YEAR(CFG_HOJE),MONTH(CFG_HOJE),1),L_Data,"<="&EOMONTH(CFG_HOJE,0),L_Status,"REALIZADO")-(SUMIFS(L_VDesp,L_Data,">="&DATE(YEAR(CFG_HOJE),MONTH(CFG_HOJE),1),L_Data,"<="&EOMONTH(CFG_HOJE,0),L_Status,"REALIZADO")) -> 0 | G18: =MIN(PJ_SALDO) -> 0
A20: METAS
A21: METAS ATIVAS | C21: VALOR ACUMULADO NAS METAS | E21: VALOR RESTANTE NAS METAS | G21: CONCLUSAO MEDIA DAS METAS ATIVAS
A22: =COUNTIF(M_STATUS,"Ativa") -> 0 | C22: =SUMIFS(M_RESERV,M_STATUS,"Ativa") -> 0 | E22: =SUMIFS(M_FALTA,M_STATUS,"Ativa") -> 0 | G22: =IF(COUNTIF(M_STATUS,"Ativa")=0,0,SUMIFS(M_RESERV,M_STATUS,"Ativa")/SUMIFS(M_OBJ,M_STATUS,"Ativa")) -> 0
A24: CONTROLE
A25: ALERTAS ATIVOS | C25: LANCAMENTOS REGISTRADOS | E25: LANCAMENTOS COM ERRO | G25: TESTES COM FALHA
A26: =AL_TOTAL -> 0 | C26: =COUNTIF(L_Status,"REALIZADO")+COUNTIF(L_Status,"PROJETADO") -> 0 | E26: =SUMPRODUCT((LEFT(L_Valid,4)="ERRO")*1) -> 0 | G26: =TS_FALHAS -> 0
A28: SALDO DAS CONTAS
A29: Conta | B29: Saldo_Calculado | C29: Reservado | D29: Disponivel | E29: Saldo_Projetado
A30: =IF(CAD_Contas!$A5="","",CAD_Contas!$B5) | B30: =IF(CAD_Contas!$A5="","",CAD_Contas!$J5) | C30: =IF(CAD_Contas!$A5="","",CAD_Contas!$K5) | D30: =IF(CAD_Contas!$A5="","",CAD_Contas!$L5) | E30: =IF(CAD_Contas!$A5="","",CAD_Contas!$O5)
A31: =IF(CAD_Contas!$A6="","",CAD_Contas!$B6) | B31: =IF(CAD_Contas!$A6="","",CAD_Contas!$J6) | C31: =IF(CAD_Contas!$A6="","",CAD_Contas!$K6) | D31: =IF(CAD_Contas!$A6="","",CAD_Contas!$L6) | E31: =IF(CAD_Contas!$A6="","",CAD_Contas!$O6)
A32: =IF(CAD_Contas!$A7="","",CAD_Contas!$B7) | B32: =IF(CAD_Contas!$A7="","",CAD_Contas!$J7) | C32: =IF(CAD_Contas!$A7="","",CAD_Contas!$K7) | D32: =IF(CAD_Contas!$A7="","",CAD_Contas!$L7) | E32: =IF(CAD_Contas!$A7="","",CAD_Contas!$O7)
A33: =IF(CAD_Contas!$A8="","",CAD_Contas!$B8) | B33: =IF(CAD_Contas!$A8="","",CAD_Contas!$J8) | C33: =IF(CAD_Contas!$A8="","",CAD_Contas!$K8) | D33: =IF(CAD_Contas!$A8="","",CAD_Contas!$L8) | E33: =IF(CAD_Contas!$A8="","",CAD_Contas!$O8)
A34: =IF(CAD_Contas!$A9="","",CAD_Contas!$B9) | B34: =IF(CAD_Contas!$A9="","",CAD_Contas!$J9) | C34: =IF(CAD_Contas!$A9="","",CAD_Contas!$K9) | D34: =IF(CAD_Contas!$A9="","",CAD_Contas!$L9) | E34: =IF(CAD_Contas!$A9="","",CAD_Contas!$O9)
A35: =IF(CAD_Contas!$A10="","",CAD_Contas!$B10) | B35: =IF(CAD_Contas!$A10="","",CAD_Contas!$J10) | C35: =IF(CAD_Contas!$A10="","",CAD_Contas!$K10) | D35: =IF(CAD_Contas!$A10="","",CAD_Contas!$L10) | E35: =IF(CAD_Contas!$A10="","",CAD_Contas!$O10)
A36: =IF(CAD_Contas!$A11="","",CAD_Contas!$B11) | B36: =IF(CAD_Contas!$A11="","",CAD_Contas!$J11) | C36: =IF(CAD_Contas!$A11="","",CAD_Contas!$K11) | D36: =IF(CAD_Contas!$A11="","",CAD_Contas!$L11) | E36: =IF(CAD_Contas!$A11="","",CAD_Contas!$O11)
A37: =IF(CAD_Contas!$A12="","",CAD_Contas!$B12) | B37: =IF(CAD_Contas!$A12="","",CAD_Contas!$J12) | C37: =IF(CAD_Contas!$A12="","",CAD_Contas!$K12) | D37: =IF(CAD_Contas!$A12="","",CAD_Contas!$L12) | E37: =IF(CAD_Contas!$A12="","",CAD_Contas!$O12)
A38: =IF(CAD_Contas!$A13="","",CAD_Contas!$B13) | B38: =IF(CAD_Contas!$A13="","",CAD_Contas!$J13) | C38: =IF(CAD_Contas!$A13="","",CAD_Contas!$K13) | D38: =IF(CAD_Contas!$A13="","",CAD_Contas!$L13) | E38: =IF(CAD_Contas!$A13="","",CAD_Contas!$O13)
A39: =IF(CAD_Contas!$A14="","",CAD_Contas!$B14) | B39: =IF(CAD_Contas!$A14="","",CAD_Contas!$J14) | C39: =IF(CAD_Contas!$A14="","",CAD_Contas!$K14) | D39: =IF(CAD_Contas!$A14="","",CAD_Contas!$L14) | E39: =IF(CAD_Contas!$A14="","",CAD_Contas!$O14)
A40: =IF(CAD_Contas!$A15="","",CAD_Contas!$B15) | B40: =IF(CAD_Contas!$A15="","",CAD_Contas!$J15) | C40: =IF(CAD_Contas!$A15="","",CAD_Contas!$K15) | D40: =IF(CAD_Contas!$A15="","",CAD_Contas!$L15) | E40: =IF(CAD_Contas!$A15="","",CAD_Contas!$O15)
A41: =IF(CAD_Contas!$A16="","",CAD_Contas!$B16) | B41: =IF(CAD_Contas!$A16="","",CAD_Contas!$J16) | C41: =IF(CAD_Contas!$A16="","",CAD_Contas!$K16) | D41: =IF(CAD_Contas!$A16="","",CAD_Contas!$L16) | E41: =IF(CAD_Contas!$A16="","",CAD_Contas!$O16)
... A69: =IF(CAD_Contas!$A44="","",CAD_Contas!$B44) | B69: =IF(CAD_Contas!$A44="","",CAD_Contas!$J44) | C69: =IF(CAD_Contas!$A44="","",CAD_Contas!$K44) | D69: =IF(CAD_Contas!$A44="","",CAD_Contas!$L44) | E69: =IF(CAD_Contas!$A44="","",CAD_Contas!$O44)
A71: METAS FINANCEIRAS
A72: Meta | B72: Objetivo | C72: Acumulado | D72: Faltante | E72: Concluido | F72: Situacao
A73: =IF(CAD_Metas!$A5="","",CAD_Metas!$B5) | B73: =IF(CAD_Metas!$A5="","",CAD_Metas!$C5) | C73: =IF(CAD_Metas!$A5="","",CAD_Metas!$H5) | D73: =IF(CAD_Metas!$A5="","",CAD_Metas!$J5) | E73: =IF(CAD_Metas!$A5="","",CAD_Metas!$I5) | F73: =IF(CAD_Metas!$A5="","",CAD_Metas!$O5)
A74: =IF(CAD_Metas!$A6="","",CAD_Metas!$B6) | B74: =IF(CAD_Metas!$A6="","",CAD_Metas!$C6) | C74: =IF(CAD_Metas!$A6="","",CAD_Metas!$H6) | D74: =IF(CAD_Metas!$A6="","",CAD_Metas!$J6) | E74: =IF(CAD_Metas!$A6="","",CAD_Metas!$I6) | F74: =IF(CAD_Metas!$A6="","",CAD_Metas!$O6)
A75: =IF(CAD_Metas!$A7="","",CAD_Metas!$B7) | B75: =IF(CAD_Metas!$A7="","",CAD_Metas!$C7) | C75: =IF(CAD_Metas!$A7="","",CAD_Metas!$H7) | D75: =IF(CAD_Metas!$A7="","",CAD_Metas!$J7) | E75: =IF(CAD_Metas!$A7="","",CAD_Metas!$I7) | F75: =IF(CAD_Metas!$A7="","",CAD_Metas!$O7)
...

Sheet LANCAR
A1: LANCAR - TELA DE LANCAMENTO RAPIDO
A2: Preencha as celulas amarelas. O sistema resolve os IDs e monta a linha pronta. Copie a LINHA PRONTA e cole na primeira linha vazia de LANCAMENTOS (colunas B ate S). O ID do lancamento e gerado automaticamente pela planilha.
A4: Data | B4: 46270
A5: Descricao | B5: Exemplo: Supermercado da semana
A6: Tipo de operacao | B6: DESPESA
A7: Status | B7: REALIZADO
A8: Valor (Gs.) | B8: 250000
A9: Origem - tipo | B9: CONTA | C9: ID resolvido | D9: =IF($B$9="EXTERNO","",IFERROR(INDEX(ENT_ID,MATCH(1,INDEX((ENT_NOME=$B$10)*(ENT_TIPO=$B$9),0),0)),"NAO ENCONTRADO")) -> NAO ENCONTRADO
A10: Origem - nome
A11: Destino - tipo | B11: EXTERNO | C11: ID resolvido | D11: =IF($B$11="EXTERNO","",IFERROR(INDEX(ENT_ID,MATCH(1,INDEX((ENT_NOME=$B$12)*(ENT_TIPO=$B$11),0),0)),"NAO ENCONTRADO"))
A12: Destino - nome | B12: (Externo)
A13: Categoria | B13: Alimentacao | C13: ID resolvido | D13: =IF($B$13="","",IFERROR(INDEX(CAT_ID,MATCH($B$13,CAT_NOME,0)),"NAO ENCONTRADO")) -> CAT-000001
A14: Subcategoria | B14: Supermercado | C14: ID resolvido | D14: =IF($B$14="","",IFERROR(INDEX(SUB_ID,MATCH(1,INDEX((SUB_NOME=$B$14)*(SUB_CATID=$D$13),0),0)),"NAO ENCONTRADO")) -> SUB-000001
A15: Forma de pagamento | B15: Debito
A16: Compromisso (opcional) | C16: ID resolvido | D16: =IF($B$16="","",IFERROR(INDEX(CM_ID,MATCH($B$16,CM_NOME,0)),"NAO ENCONTRADO"))
A17: Numero da parcela (vazio = proxima em aberto) | C17: Parcela resolvida | D17: =IF($D$16="","",IF($B$17="",IFERROR(INDEX(P_ID,MATCH(1,INDEX((P_CMP=$D$16)*(P_STATUS<>"PAGA")*(P_STATUS<>"CANCELADA"),0),0)),""),IFERROR(INDEX(P_ID,MATCH(1,INDEX((P_CMP=$D$16)*(P_NUM=$B$17),0),0)),"NAO ENCONTRADA")))
A18: Meta (opcional) | C18: Rotulo / vencimento / valor da parcela | D18: =IF($D$17="","",IFERROR(INDEX(P_ROT,MATCH($D$17,P_ID,0))&" venc "&DAY(INDEX(P_VENC,MATCH($D$17,P_ID,0)))&"/"&MONTH(INDEX(P_VENC,MATCH($D$17,P_ID,0)))&"/"&YEAR(INDEX(P_VENC,MATCH($D$17,P_ID,0)))&" Gs. "&TEXT(INDEX(P_VALOR,MATCH($D$17,P_ID,0)),"#,##0"),"?"))
A19: Recorrencia (opcional)
A20: Lancamento relacionado (estorno, opcional)
A21: Observacao
A23: VERIFICACAO ANTES DE COLAR
A24: Classificacao economica do lancamento | B24: =IFERROR(INDEX(MAP_CLASS,MATCH($B$6,MAP_TIPO,0)),"TIPO INVALIDO") -> DESPESA
A25: Efeito no caixa | B25: =IF(AND($B$11="CONTA",$B$9<>"CONTA"),"ENTRADA de caixa",IF(AND($B$9="CONTA",$B$11<>"CONTA"),"SAIDA de caixa","NAO afeta o caixa")) -> SAIDA de caixa
A26: Situacao do preenchimento | B26: =IF($B$8<=0,"ERRO: valor deve ser maior que zero",IF(AND($B$9="EXTERNO",$B$11="EXTERNO"),"ERRO: origem e destino externos",IF(AND($B$9<>"EXTERNO",$D$9=""),"ERRO: origem nao resolvida",IF(AND($B$11<>"EXTERNO",$D$11=""),"ERRO: destino nao resolvido",IF($D$13="","ERRO: categoria nao resolvida",IF(AND($B$14<>"",$D$14="NAO ENCONTRADO"),"ERRO: subcategoria nao pertence a categoria",IF(AND($D$16<>"",$D$17=""),"ATENCAO: compromisso sem parcela em aberto","PRONTO PARA COLAR"))))))) -> PRONTO PARA COLAR
A27: Aviso de vinculo | B27: =IF(AND($D$16="",$D$18="",$B$19="",$B$20=""),"Sem vinculos","ATENCAO: este lancamento fica vinculado a "&TRIM(IF($D$16<>"","compromisso/parcela ","")&IF($D$18<>"","meta ","")&IF($B$19<>"","recorrencia ","")&IF($B$20<>"","estorno",""))) -> Sem vinculos
A29: LINHA PRONTA PARA COPIAR (COLE EM LANCAMENTOS, COLUNAS B ATE S)
A30: Data | B30: Descricao | C30: Tipo_Operacao | D30: Status | E30: Valor | F30: Origem_Tipo | G30: Origem_ID | H30: Destino_Tipo | I30: Destino_ID | J30: Categoria_ID | K30: Subcategoria_ID | L30: Forma_Pagamento | M30: ID_Compromisso | N30: ID_Parcela | O30: ID_Meta | P30: ID_Recorrencia | Q30: ID_Relacionado | R30: Observacao
A31: =$B$4 -> 46270 | B31: =$B$5 -> Exemplo: Supermercado da semana | C31: =$B$6 -> DESPESA | D31: =$B$7 -> REALIZADO | E31: =$B$8 -> 250000 | F31: =$B$9 -> CONTA | G31: =$D$9 -> NAO ENCONTRADO | H31: =$B$11 -> EXTERNO | I31: =$D$11 | J31: =$D$13 -> CAT-000001 | K31: =$D$14 -> SUB-000001 | L31: =$B$15 -> Debito | M31: =$D$16 | N31: =$D$17 | O31: =$D$18 | P31: =$B$19 -> 0 | Q31: =$B$20 -> 0 | R31: =$B$21 -> 0
A33: ASSISTENTE DE RESGATE DE INVESTIMENTO (GERA DOIS LANCAMENTOS)
A34: Regra: o rendimento e reconhecido como RECEITA FINANCEIRA (lancamento 1) e o resgate transfere o dinheiro do investimento para a conta sem virar receita (lancamento 2). Se o rendimento ja foi lancado mes a mes, informe 0 no campo Rendimento apurado e use apenas o lancamento 2.
A35: Investimento (nome) | C35: ID | D35: =IFERROR(INDEX(I_ID,MATCH($B$35,I_NOME,0)),"NAO ENCONTRADO") -> NAO ENCONTRADO
A36: Conta de destino (nome) | C36: ID | D36: =IFERROR(INDEX(C_ID,MATCH($B$36,C_NOME,0)),"NAO ENCONTRADO") -> NAO ENCONTRADO
A37: Data do resgate | B37: 46270
A38: Valor total resgatado | B38: 3000000
A39: Rendimento apurado ainda nao lancado | B39: 0 | C39: Principal do resgate | D39: =MAX(0,$B$38-$B$39) -> 3000000
A41: Data | B41: Descricao | C41: Tipo_Operacao | D41: Status | E41: Valor | F41: Origem_Tipo | G41: Origem_ID | H41: Destino_Tipo | I41: Destino_ID | J41: Categoria_ID | K41: Subcategoria_ID | L41: Forma_Pagamento | M41: ID_Compromisso | N41: ID_Parcela | O41: ID_Meta | P41: ID_Recorrencia | Q41: ID_Relacionado | R41: Observacao
A42: =$B$37 -> 46270 | B42: ="Rendimento de "&$B$35 -> Rendimento de | C42: ="RENDIMENTO" -> RENDIMENTO | D42: ="REALIZADO" -> REALIZADO | E42: =$B$39 -> 0 | F42: ="EXTERNO" -> EXTERNO | G42: ="" | H42: ="INVESTIMENTO" -> INVESTIMENTO | I42: =$D$35 -> NAO ENCONTRADO | J42: =IFERROR(INDEX(CAT_ID,MATCH("Receitas",CAT_NOME,0)),"") -> CAT-000010 | K42: =IFERROR(INDEX(SUB_ID,MATCH(1,INDEX((SUB_NOME="Rendimento financeiro"),0),0)),"") -> SUB-000044 | L42: ="Transferencia" -> Transferencia | M42: ="" | N42: ="" | O42: ="" | P42: ="" | Q42: ="" | R42: ="Rendimento reconhecido no momento do resgate" -> Rendimento reconhecido no momento do resgate
A43: =$B$37 -> 46270 | B43: ="Resgate de "&$B$35 -> Resgate de | C43: ="RESGATE" -> RESGATE | D43: ="REALIZADO" -> REALIZADO | E43: =$B$38 -> 3000000 | F43: ="INVESTIMENTO" -> INVESTIMENTO | G43: =$D$35 -> NAO ENCONTRADO | H43: ="CONTA" -> CONTA | I43: =$D$36 -> NAO ENCONTRADO | J43: =IFERROR(INDEX(CAT_ID,MATCH("Investimentos",CAT_NOME,0)),"") -> CAT-000009 | K43: =IFERROR(INDEX(SUB_ID,MATCH(1,INDEX((SUB_NOME="Resgate"),0),0)),"") -> SUB-000039 | L43: ="Transferencia" -> Transferencia | M43: ="" | N43: ="" | O43: ="" | P43: ="" | Q43: ="" | R43: ="Operacao neutra: principal nao e receita" -> Operacao neutra: principal nao e receita
A46: ASSISTENTE DE MOVIMENTO DE META (COLE EM MOV_METAS, COLUNAS B ATE H)
A47: Meta (nome)
...

Sheet LANCAMENTOS
A1: LANCAMENTOS - LIVRO UNICO DE OPERACOES
A2: PARA APAGAR UM REGISTRO: selecione as celulas AMARELAS da linha e pressione DELETE (limpar conteudo). NUNCA use 'Excluir linha' nem classifique (sort) esta aba: os IDs sao gerados pela posicao da linha e os vinculos seriam quebrados em silencio. Para anular um lancamento sem perder o historico use o campo Status (CANCELADO / Inativo). Para pesquisar use os filtros do cabecalho. As colunas cinzas sao calculadas - nao digite nelas. Para anular um lancamento troque o Status para CANCELADO (o historico permanece e o efeito financeiro desaparece).
A4: ID_Lancamento | B4: Data | C4: Descricao | D4: Tipo_Operacao | E4: Status | F4: Valor | G4: Origem_Tipo | H4: Origem_ID | I4: Destino_Tipo | J4: Destino_ID | K4: Categoria_ID | L4: Subcategoria_ID | M4: Forma_Pagamento | N4: ID_Compromisso | O4: ID_Parcela | P4: ID_Meta | Q4: ID_Recorrencia | R4: ID_Relacionado | S4: Observacao | T4: Ano | U4: Mes | V4: AnoMes | W4: Classificacao | X4: Categoria | Y4: Subcategoria | Z4: Origem_Nome | AA4: Destino_Nome | AB4: Entrada_Caixa | AC4: Saida_Caixa | AD4: Vlr_Receita | AE4: Vlr_Despesa | AF4: Vlr_Rend_Fin | AG4: Efeito_Conta | AH4: Efeito_Cartao | AI4: Efeito_Investim | AJ4: Validacao | AK4: Vinculos
A5: =IF($B5="","","LAN-"&TEXT(ROW()-4,"000000")) | T5: =IF($B5="","",YEAR($B5)) | U5: =IF($B5="","",MONTH($B5)) | V5: =IF($B5="","",YEAR($B5)*100+MONTH($B5)) | W5: =IF($D5="","",IFERROR(INDEX(MAP_CLASS,MATCH($D5,MAP_TIPO,0)),"TIPO INVALIDO")) | X5: =IF($K5="","",IFERROR(INDEX(CAT_NOME,MATCH($K5,CAT_ID,0)),"?")) | Y5: =IF($L5="","",IFERROR(INDEX(SUB_NOME,MATCH($L5,SUB_ID,0)),"?")) | Z5: =IF($G5="","",IF($G5="EXTERNO","(Externo)",IFERROR(INDEX(ENT_NOME,MATCH($H5,ENT_ID,0)),"?"))) | AA5: =IF($I5="","",IF($I5="EXTERNO","(Externo)",IFERROR(INDEX(ENT_NOME,MATCH($J5,ENT_ID,0)),"?"))) | AB5: =IF($B5="",0,IF(AND($I5="CONTA",$G5<>"CONTA"),$F5,0)) -> 0 | AC5: =IF($B5="",0,IF(AND($G5="CONTA",$I5<>"CONTA"),$F5,0)) -> 0 | AD5: =IF($W5="RECEITA",$F5,0) -> 0 | AE5: =IF($W5="DESPESA",$F5,0) -> 0 | AF5: =IF($W5="RECEITA_FINANCEIRA",$F5,0) -> 0 | AG5: =IF($B5="",0,IF($I5="CONTA",$F5,0)-IF($G5="CONTA",$F5,0)) -> 0 | AH5: =IF($B5="",0,IF($G5="CARTAO",$F5,0)-IF($I5="CARTAO",$F5,0)) -> 0 | AI5: =IF($B5="",0,IF($I5="INVESTIMENTO",$F5,0)-IF($G5="INVESTIMENTO",$F5,0)) -> 0 | AJ5: =IF($B5="","",IF(NOT(ISNUMBER($F5)),"ERRO: valor nao numerico",IF($F5<=0,"ERRO: valor deve ser maior que zero",IF(COUNTIF(MAP_TIPO,$D5)=0,"ERRO: tipo de operacao nao cadastrado",IF(COUNTIF(LST_STATUS,$E5)=0,"ERRO: status invalido",IF(AND($G5="EXTERNO",$I5="EXTERNO"),"ERRO: origem e destino externos",IF(AND($G5<>"EXTERNO",COUNTIFS(ENT_ID,$H5,ENT_TIPO,$G5)=0),"ERRO: origem inexistente",IF(AND($I5<>"EXTERNO",COUNTIFS(ENT_ID,$J5,ENT_TIPO,$I5)=0),"ERRO: destino inexistente",IF(AND($K5<>"",COUNTIF(CAT_ID,$K5)=0),"ERRO: categoria inexistente",IF(AND($L5<>"",COUNTIF(SUB_ID,$L5)=0),"ERRO: subcategoria inexistente",IF(AND($L5<>"",$K5<>"",IFERROR(INDEX(SUB_CATID,MATCH($L5,SUB_ID,0)),"")<>$K5),"ERRO: subcategoria nao pertence a categoria",IF(AND($O5<>"",COUNTIF(P_ID,$O5)=0),"ERRO: parcela inexistente",IF(AND($N5<>"",COUNTIF(CM_ID,$N5)=0),"ERRO: compromisso inexistente","OK"))))))))))))) | AK5: =IF($B5="","",IF(AND($N5="",$O5="",$P5="",$Q5="",$R5=""),"","VINCULADO: "&TRIM(IF($N5<>"",$N5&" ","")&IF($O5<>"",$O5&" ","")&IF($P5<>"",$P5&" ","")&IF($Q5<>"",$Q5&" ","")&IF($R5<>"",$R5,""))))
A6: =IF($B6="","","LAN-"&TEXT(ROW()-4,"000000")) | T6: =IF($B6="","",YEAR($B6)) | U6: =IF($B6="","",MONTH($B6)) | V6: =IF($B6="","",YEAR($B6)*100+MONTH($B6)) | W6: =IF($D6="","",IFERROR(INDEX(MAP_CLASS,MATCH($D6,MAP_TIPO,0)),"TIPO INVALIDO")) | X6: =IF($K6="","",IFERROR(INDEX(CAT_NOME,MATCH($K6,CAT_ID,0)),"?")) | Y6: =IF($L6="","",IFERROR(INDEX(SUB_NOME,MATCH($L6,SUB_ID,0)),"?")) | Z6: =IF($G6="","",IF($G6="EXTERNO","(Externo)",IFERROR(INDEX(ENT_NOME,MATCH($H6,ENT_ID,0)),"?"))) | AA6: =IF($I6="","",IF($I6="EXTERNO","(Externo)",IFERROR(INDEX(ENT_NOME,MATCH($J6,ENT_ID,0)),"?"))) | AB6: =IF($B6="",0,IF(AND($I6="CONTA",$G6<>"CONTA"),$F6,0)) -> 0 | AC6: =IF($B6="",0,IF(AND($G6="CONTA",$I6<>"CONTA"),$F6,0)) -> 0 | AD6: =IF($W6="RECEITA",$F6,0) -> 0 | AE6: =IF($W6="DESPESA",$F6,0) -> 0 | AF6: =IF($W6="RECEITA_FINANCEIRA",$F6,0) -> 0 | AG6: =IF($B6="",0,IF($I6="CONTA",$F6,0)-IF($G6="CONTA",$F6,0)) -> 0 | AH6: =IF($B6="",0,IF($G6="CARTAO",$F6,0)-IF($I6="CARTAO",$F6,0)) -> 0 | AI6: =IF($B6="",0,IF($I6="INVESTIMENTO",$F6,0)-IF($G6="INVESTIMENTO",$F6,0)) -> 0 | AJ6: =IF($B6="","",IF(NOT(ISNUMBER($F6)),"ERRO: valor nao numerico",IF($F6<=0,"ERRO: valor deve ser maior que zero",IF(COUNTIF(MAP_TIPO,$D6)=0,"ERRO: tipo de operacao nao cadastrado",IF(COUNTIF(LST_STATUS,$E6)=0,"ERRO: status invalido",IF(AND($G6="EXTERNO",$I6="EXTERNO"),"ERRO: origem e destino externos",IF(AND($G6<>"EXTERNO",COUNTIFS(ENT_ID,$H6,ENT_TIPO,$G6)=0),"ERRO: origem inexistente",IF(AND($I6<>"EXTERNO",COUNTIFS(ENT_ID,$J6,ENT_TIPO,$I6)=0),"ERRO: destino inexistente",IF(AND($K6<>"",COUNTIF(CAT_ID,$K6)=0),"ERRO: categoria inexistente",IF(AND($L6<>"",COUNTIF(SUB_ID,$L6)=0),"ERRO: subcategoria inexistente",IF(AND($L6<>"",$K6<>"",IFERROR(INDEX(SUB_CATID,MATCH($L6,SUB_ID,0)),"")<>$K6),"ERRO: subcategoria nao pertence a categoria",IF(AND($O6<>"",COUNTIF(P_ID,$O6)=0),"ERRO: parcela inexistente",IF(AND($N6<>"",COUNTIF(CM_ID,$N6)=0),"ERRO: compromisso inexistente","OK"))))))))))))) | AK6: =IF($B6="","",IF(AND($N6="",$O6="",$P6="",$Q6="",$R6=""),"","VINCULADO: "&TRIM(IF($N6<>"",$N6&" ","")&IF($O6<>"",$O6&" ","")&IF($P6<>"",$P6&" ","")&IF($Q6<>"",$Q6&" ","")&IF($R6<>"",$R6,""))))
A7: =IF($B7="","","LAN-"&TEXT(ROW()-4,"000000")) | T7: =IF($B7="","",YEAR($B7)) | U7: =IF($B7="","",MONTH($B7)) | V7: =IF($B7="","",YEAR($B7)*100+MONTH($B7)) | W7: =IF($D7="","",IFERROR(INDEX(MAP_CLASS,MATCH($D7,MAP_TIPO,0)),"TIPO INVALIDO")) | X7: =IF($K7="","",IFERROR(INDEX(CAT_NOME,MATCH($K7,CAT_ID,0)),"?")) | Y7: =IF($L7="","",IFERROR(INDEX(SUB_NOME,MATCH($L7,SUB_ID,0)),"?")) | Z7: =IF($G7="","",IF($G7="EXTERNO","(Externo)",IFERROR(INDEX(ENT_NOME,MATCH($H7,ENT_ID,0)),"?"))) | AA7: =IF($I7="","",IF($I7="EXTERNO","(Externo)",IFERROR(INDEX(ENT_NOME,MATCH($J7,ENT_ID,0)),"?"))) | AB7: =IF($B7="",0,IF(AND($I7="CONTA",$G7<>"CONTA"),$F7,0)) -> 0 | AC7: =IF($B7="",0,IF(AND($G7="CONTA",$I7<>"CONTA"),$F7,0)) -> 0 | AD7: =IF($W7="RECEITA",$F7,0) -> 0 | AE7: =IF($W7="DESPESA",$F7,0) -> 0 | AF7: =IF($W7="RECEITA_FINANCEIRA",$F7,0) -> 0 | AG7: =IF($B7="",0,IF($I7="CONTA",$F7,0)-IF($G7="CONTA",$F7,0)) -> 0 | AH7: =IF($B7="",0,IF($G7="CARTAO",$F7,0)-IF($I7="CARTAO",$F7,0)) -> 0 | AI7: =IF($B7="",0,IF($I7="INVESTIMENTO",$F7,0)-IF($G7="INVESTIMENTO",$F7,0)) -> 0 | AJ7: =IF($B7="","",IF(NOT(ISNUMBER($F7)),"ERRO: valor nao numerico",IF($F7<=0,"ERRO: valor deve ser maior que zero",IF(COUNTIF(MAP_TIPO,$D7)=0,"ERRO: tipo de operacao nao cadastrado",IF(COUNTIF(LST_STATUS,$E7)=0,"ERRO: status invalido",IF(AND($G7="EXTERNO",$I7="EXTERNO"),"ERRO: origem e destino externos",IF(AND($G7<>"EXTERNO",COUNTIFS(ENT_ID,$H7,ENT_TIPO,$G7)=0),"ERRO: origem inexistente",IF(AND($I7<>"EXTERNO",COUNTIFS(ENT_ID,$J7,ENT_TIPO,$I7)=0),"ERRO: destino inexistente",IF(AND($K7<>"",COUNTIF(CAT_ID,$K7)=0),"ERRO: categoria inexistente",IF(AND($L7<>"",COUNTIF(SUB_ID,$L7)=0),"ERRO: subcategoria inexistente",IF(AND($L7<>"",$K7<>"",IFERROR(INDEX(SUB_CATID,MATCH($L7,SUB_ID,0)),"")<>$K7),"ERRO: subcategoria nao pertence a categoria",IF(AND($O7<>"",COUNTIF(P_ID,$O7)=0),"ERRO: parcela inexistente",IF(AND($N7<>"",COUNTIF(CM_ID,$N7)=0),"ERRO: compromisso inexistente","OK"))))))))))))) | AK7: =IF($B7="","",IF(AND($N7="",$O7="",$P7="",$Q7="",$R7=""),"","VINCULADO: "&TRIM(IF($N7<>"",$N7&" ","")&IF($O7<>"",$O7&" ","")&IF($P7<>"",$P7&" ","")&IF($Q7<>"",$Q7&" ","")&IF($R7<>"",$R7,""))))
A8: =IF($B8="","","LAN-"&TEXT(ROW()-4,"000000")) | T8: =IF($B8="","",YEAR($B8)) | U8: =IF($B8="","",MONTH($B8)) | V8: =IF($B8="","",YEAR($B8)*100+MONTH($B8)) | W8: =IF($D8="","",IFERROR(INDEX(MAP_CLASS,MATCH($D8,MAP_TIPO,0)),"TIPO INVALIDO")) | X8: =IF($K8="","",IFERROR(INDEX(CAT_NOME,MATCH($K8,CAT_ID,0)),"?")) | Y8: =IF($L8="","",IFERROR(INDEX(SUB_NOME,MATCH($L8,SUB_ID,0)),"?")) | Z8: =IF($G8="","",IF($G8="EXTERNO","(Externo)",IFERROR(INDEX(ENT_NOME,MATCH($H8,ENT_ID,0)),"?"))) | AA8: =IF($I8="","",IF($I8="EXTERNO","(Externo)",IFERROR(INDEX(ENT_NOME,MATCH($J8,ENT_ID,0)),"?"))) | AB8: =IF($B8="",0,IF(AND($I8="CONTA",$G8<>"CONTA"),$F8,0)) -> 0 | AC8: =IF($B8="",0,IF(AND($G8="CONTA",$I8<>"CONTA"),$F8,0)) -> 0 | AD8: =IF($W8="RECEITA",$F8,0) -> 0 | AE8: =IF($W8="DESPESA",$F8,0) -> 0 | AF8: =IF($W8="RECEITA_FINANCEIRA",$F8,0) -> 0 | AG8: =IF($B8="",0,IF($I8="CONTA",$F8,0)-IF($G8="CONTA",$F8,0)) -> 0 | AH8: =IF($B8="",0,IF($G8="CARTAO",$F8,0)-IF($I8="CARTAO",$F8,0)) -> 0 | AI8: =IF($B8="",0,IF($I8="INVESTIMENTO",$F8,0)-IF($G8="INVESTIMENTO",$F8,0)) -> 0 | AJ8: =IF($B8="","",IF(NOT(ISNUMBER($F8)),"ERRO: valor nao numerico",IF($F8<=0,"ERRO: valor deve ser maior que zero",IF(COUNTIF(MAP_TIPO,$D8)=0,"ERRO: tipo de operacao nao cadastrado",IF(COUNTIF(LST_STATUS,$E8)=0,"ERRO: status invalido",IF(AND($G8="EXTERNO",$I8="EXTERNO"),"ERRO: origem e destino externos",IF(AND($G8<>"EXTERNO",COUNTIFS(ENT_ID,$H8,ENT_TIPO,$G8)=0),"ERRO: origem inexistente",IF(AND($I8<>"EXTERNO",COUNTIFS(ENT_ID,$J8,ENT_TIPO,$I8)=0),"ERRO: destino inexistente",IF(AND($K8<>"",COUNTIF(CAT_ID,$K8)=0),"ERRO: categoria inexistente",IF(AND($L8<>"",COUNTIF(SUB_ID,$L8)=0),"ERRO: subcategoria inexistente",IF(AND($L8<>"",$K8<>"",IFERROR(INDEX(SUB_CATID,MATCH($L8,SUB_ID,0)),"")<>$K8),"ERRO: subcategoria nao pertence a categoria",IF(AND($O8<>"",COUNTIF(P_ID,$O8)=0),"ERRO: parcela inexistente",IF(AND($N8<>"",COUNTIF(CM_ID,$N8)=0),"ERRO: compromisso inexistente","OK"))))))))))))) | AK8: =IF($B8="","",IF(AND($N8="",$O8="",$P8="",$Q8="",$R8=""),"","VINCULADO: "&TRIM(IF($N8<>"",$N8&" ","")&IF($O8<>"",$O8&" ","")&IF($P8<>"",$P8&" ","")&IF($Q8<>"",$Q8&" ","")&IF($R8<>"",$R8,""))))
A9: =IF($B9="","","LAN-"&TEXT(ROW()-4,"000000")) | T9: =IF($B9="","",YEAR($B9)) | U9: =IF($B9="","",MONTH($B9)) | V9: =IF($B9="","",YEAR($B9)*100+MONTH($B9)) | W9: =IF($D9="","",IFERROR(INDEX(MAP_CLASS,MATCH($D9,MAP_TIPO,0)),"TIPO INVALIDO")) | X9: =IF($K9="","",IFERROR(INDEX(CAT_NOME,MATCH($K9,CAT_ID,0)),"?")) | Y9: =IF($L9="","",IFERROR(INDEX(SUB_NOME,MATCH($L9,SUB_ID,0)),"?")) | Z9: =IF($G9="","",IF($G9="EXTERNO","(Externo)",IFERROR(INDEX(ENT_NOME,MATCH($H9,ENT_ID,0)),"?"))) | AA9: =IF($I9="","",IF($I9="EXTERNO","(Externo)",IFERROR(INDEX(ENT_NOME,MATCH($J9,ENT_ID,0)),"?"))) | AB9: =IF($B9="",0,IF(AND($I9="CONTA",$G9<>"CONTA"),$F9,0)) -> 0 | AC9: =IF($B9="",0,IF(AND($G9="CONTA",$I9<>"CONTA"),$F9,0)) -> 0 | AD9: =IF($W9="RECEITA",$F9,0) -> 0 | AE9: =IF($W9="DESPESA",$F9,0) -> 0 | AF9: =IF($W9="RECEITA_FINANCEIRA",$F9,0) -> 0 | AG9: =IF($B9="",0,IF($I9="CONTA",$F9,0)-IF($G9="CONTA",$F9,0)) -> 0 | AH9: =IF($B9="",0,IF($G9="CARTAO",$F9,0)-IF($I9="CARTAO",$F9,0)) -> 0 | AI9: =IF($B9="",0,IF($I9="INVESTIMENTO",$F9,0)-IF($G9="INVESTIMENTO",$F9,0)) -> 0 | AJ9: =IF($B9="","",IF(NOT(ISNUMBER($F9)),"ERRO: valor nao numerico",IF($F9<=0,"ERRO: valor deve ser maior que zero",IF(COUNTIF(MAP_TIPO,$D9)=0,"ERRO: tipo de operacao nao cadastrado",IF(COUNTIF(LST_STATUS,$E9)=0,"ERRO: status invalido",IF(AND($G9="EXTERNO",$I9="EXTERNO"),"ERRO: origem e destino externos",IF(AND($G9<>"EXTERNO",COUNTIFS(ENT_ID,$H9,ENT_TIPO,$G9)=0),"ERRO: origem inexistente",IF(AND($I9<>"EXTERNO",COUNTIFS(ENT_ID,$J9,ENT_TIPO,$I9)=0),"ERRO: destino inexistente",IF(AND($K9<>"",COUNTIF(CAT_ID,$K9)=0),"ERRO: categoria inexistente",IF(AND($L9<>"",COUNTIF(SUB_ID,$L9)=0),"ERRO: subcategoria inexistente",IF(AND($L9<>"",$K9<>"",IFERROR(INDEX(SUB_CATID,MATCH($L9,SUB_ID,0)),"")<>$K9),"ERRO: subcategoria nao pertence a categoria",IF(AND($O9<>"",COUNTIF(P_ID,$O9)=0),"ERRO: parcela inexistente",IF(AND($N9<>"",COUNTIF(CM_ID,$N9)=0),"ERRO: compromisso inexistente","OK"))))))))))))) | AK9: =IF($B9="","",IF(AND($N9="",$O9="",$P9="",$Q9="",$R9=""),"","VINCULADO: "&TRIM(IF($N9<>"",$N9&" ","")&IF($O9<>"",$O9&" ","")&IF($P9<>"",$P9&" ","")&IF($Q9<>"",$Q9&" ","")&IF($R9<>"",$R9,""))))
A10: =IF($B10="","","LAN-"&TEXT(ROW()-4,"000000")) | T10: =IF($B10="","",YEAR($B10)) | U10: =IF($B10="","",MONTH($B10)) | V10: =IF($B10="","",YEAR($B10)*100+MONTH($B10)) | W10: =IF($D10="","",IFERROR(INDEX(MAP_CLASS,MATCH($D10,MAP_TIPO,0)),"TIPO INVALIDO")) | X10: =IF($K10="","",IFERROR(INDEX(CAT_NOME,MATCH($K10,CAT_ID,0)),"?")) | Y10: =IF($L10="","",IFERROR(INDEX(SUB_NOME,MATCH($L10,SUB_ID,0)),"?")) | Z10: =IF($G10="","",IF($G10="EXTERNO","(Externo)",IFERROR(INDEX(ENT_NOME,MATCH($H10,ENT_ID,0)),"?"))) | AA10: =IF($I10="","",IF($I10="EXTERNO","(Externo)",IFERROR(INDEX(ENT_NOME,MATCH($J10,ENT_ID,0)),"?"))) | AB10: =IF($B10="",0,IF(AND($I10="CONTA",$G10<>"CONTA"),$F10,0)) -> 0 | AC10: =IF($B10="",0,IF(AND($G10="CONTA",$I10<>"CONTA"),$F10,0)) -> 0 | AD10: =IF($W10="RECEITA",$F10,0) -> 0 | AE10: =IF($W10="DESPESA",$F10,0) -> 0 | AF10: =IF($W10="RECEITA_FINANCEIRA",$F10,0) -> 0 | AG10: =IF($B10="",0,IF($I10="CONTA",$F10,0)-IF($G10="CONTA",$F10,0)) -> 0 | AH10: =IF($B10="",0,IF($G10="CARTAO",$F10,0)-IF($I10="CARTAO",$F10,0)) -> 0 | AI10: =IF($B10="",0,IF($I10="INVESTIMENTO",$F10,0)-IF($G10="INVESTIMENTO",$F10,0)) -> 0 | AJ10: =IF($B10="","",IF(NOT(ISNUMBER($F10)),"ERRO: valor nao numerico",IF($F10<=0,"ERRO: valor deve ser maior que zero",IF(COUNTIF(MAP_TIPO,$D10)=0,"ERRO: tipo de operacao nao cadastrado",IF(COUNTIF(LST_STATUS,$E10)=0,"ERRO: status invalido",IF(AND($G10="EXTERNO",$I10="EXTERNO"),"ERRO: origem e destino externos",IF(AND($G10<>"EXTERNO",COUNTIFS(ENT_ID,$H10,ENT_TIPO,$G10)=0),"ERRO: origem inexistente",IF(AND($I10<>"EXTERNO",COUNTIFS(ENT_ID,$J10,ENT_TIPO,$I10)=0),"ERRO: destino inexistente",IF(AND($K10<>"",COUNTIF(CAT_ID,$K10)=0),"ERRO: categoria inexistente",IF(AND($L10<>"",COUNTIF(SUB_ID,$L10)=0),"ERRO: subcategoria inexistente",IF(AND($L10<>"",$K10<>"",IFERROR(INDEX(SUB_CATID,MATCH($L10,SUB_ID,0)),"")<>$K10),"ERRO: subcategoria nao pertence a categoria",IF(AND($O10<>"",COUNTIF(P_ID,$O10)=0),"ERRO: parcela inexistente",IF(AND($N10<>"",COUNTIF(CM_ID,$N10)=0),"ERRO: compromisso inexistente","OK"))))))))))))) | AK10: =IF($B10="","",IF(AND($N10="",$O10="",$P10="",$Q10="",$R10=""),"","VINCULADO: "&TRIM(IF($N10<>"",$N10&" ","")&IF($O10<>"",$O10&" ","")&IF($P10<>"",$P10&" ","")&IF($Q10<>"",$Q10&" ","")&IF($R10<>"",$R10,""))))
A11: =IF($B11="","","LAN-"&TEXT(ROW()-4,"000000")) | T11: =IF($B11="","",YEAR($B11)) | U11: =IF($B11="","",MONTH($B11)) | V11: =IF($B11="","",YEAR($B11)*100+MONTH($B11)) | W11: =IF($D11="","",IFERROR(INDEX(MAP_CLASS,MATCH($D11,MAP_TIPO,0)),"TIPO INVALIDO")) | X11: =IF($K11="","",IFERROR(INDEX(CAT_NOME,MATCH($K11,CAT_ID,0)),"?")) | Y11: =IF($L11="","",IFERROR(INDEX(SUB_NOME,MATCH($L11,SUB_ID,0)),"?")) | Z11: =IF($G11="","",IF($G11="EXTERNO","(Externo)",IFERROR(INDEX(ENT_NOME,MATCH($H11,ENT_ID,0)),"?"))) | AA11: =IF($I11="","",IF($I11="EXTERNO","(Externo)",IFERROR(INDEX(ENT_NOME,MATCH($J11,ENT_ID,0)),"?"))) | AB11: =IF($B11="",0,IF(AND($I11="CONTA",$G11<>"CONTA"),$F11,0)) -> 0 | AC11: =IF($B11="",0,IF(AND($G11="CONTA",$I11<>"CONTA"),$F11,0)) -> 0 | AD11: =IF($W11="RECEITA",$F11,0) -> 0 | AE11: =IF($W11="DESPESA",$F11,0) -> 0 | AF11: =IF($W11="RECEITA_FINANCEIRA",$F11,0) -> 0 | AG11: =IF($B11="",0,IF($I11="CONTA",$F11,0)-IF($G11="CONTA",$F11,0)) -> 0 | AH11: =IF($B11="",0,IF($G11="CARTAO",$F11,0)-IF($I11="CARTAO",$F11,0)) -> 0 | AI11: =IF($B11="",0,IF($I11="INVESTIMENTO",$F11,0)-IF($G11="INVESTIMENTO",$F11,0)) -> 0 | AJ11: =IF($B11="","",IF(NOT(ISNUMBER($F11)),"ERRO: valor nao numerico",IF($F11<=0,"ERRO: valor deve ser maior que zero",IF(COUNTIF(MAP_TIPO,$D11)=0,"ERRO: tipo de operacao nao cadastrado",IF(COUNTIF(LST_STATUS,$E11)=0,"ERRO: status invalido",IF(AND($G11="EXTERNO",$I11="EXTERNO"),"ERRO: origem e destino externos",IF(AND($G11<>"EXTERNO",COUNTIFS(ENT_ID,$H11,ENT_TIPO,$G11)=0),"ERRO: origem inexistente",IF(AND($I11<>"EXTERNO",COUNTIFS(ENT_ID,$J11,ENT_TIPO,$I11)=0),"ERRO: destino inexistente",IF(AND($K11<>"",COUNTIF(CAT_ID,$K11)=0),"ERRO: categoria inexistente",IF(AND($L11<>"",COUNTIF(SUB_ID,$L11)=0),"ERRO: subcategoria inexistente",IF(AND($L11<>"",$K11<>"",IFERROR(INDEX(SUB_CATID,MATCH($L11,SUB_ID,0)),"")<>$K11),"ERRO: subcategoria nao pertence a categoria",IF(AND($O11<>"",COUNTIF(P_ID,$O11)=0),"ERRO: parcela inexistente",IF(AND($N11<>"",COUNTIF(CM_ID,$N11)=0),"ERRO: compromisso inexistente","OK"))))))))))))) | AK11: =IF($B11="","",IF(AND($N11="",$O11="",$P11="",$Q11="",$R11=""),"","VINCULADO: "&TRIM(IF($N11<>"",$N11&" ","")&IF($O11<>"",$O11&" ","")&IF($P11<>"",$P11&" ","")&IF($Q11<>"",$Q11&" ","")&IF($R11<>"",$R11,""))))
A12: =IF($B12="","","LAN-"&TEXT(ROW()-4,"000000")) | T12: =IF($B12="","",YEAR($B12)) | U12: =IF($B12="","",MONTH($B12)) | V12: =IF($B12="","",YEAR($B12)*100+MONTH($B12)) | W12: =IF($D12="","",IFERROR(INDEX(MAP_CLASS,MATCH($D12,MAP_TIPO,0)),"TIPO INVALIDO")) | X12: =IF($K12="","",IFERROR(INDEX(CAT_NOME,MATCH($K12,CAT_ID,0)),"?")) | Y12: =IF($L12="","",IFERROR(INDEX(SUB_NOME,MATCH($L12,SUB_ID,0)),"?")) | Z12: =IF($G12="","",IF($G12="EXTERNO","(Externo)",IFERROR(INDEX(ENT_NOME,MATCH($H12,ENT_ID,0)),"?"))) | AA12: =IF($I12="","",IF($I12="EXTERNO","(Externo)",IFERROR(INDEX(ENT_NOME,MATCH($J12,ENT_ID,0)),"?"))) | AB12: =IF($B12="",0,IF(AND($I12="CONTA",$G12<>"CONTA"),$F12,0)) -> 0 | AC12: =IF($B12="",0,IF(AND($G12="CONTA",$I12<>"CONTA"),$F12,0)) -> 0 | AD12: =IF($W12="RECEITA",$F12,0) -> 0 | AE12: =IF($W12="DESPESA",$F12,0) -> 0 | AF12: =IF($W12="RECEITA_FINANCEIRA",$F12,0) -> 0 | AG12: =IF($B12="",0,IF($I12="CONTA",$F12,0)-IF($G12="CONTA",$F12,0)) -> 0 | AH12: =IF($B12="",0,IF($G12="CARTAO",$F12,0)-IF($I12="CARTAO",$F12,0)) -> 0 | AI12: =IF($B12="",0,IF($I12="INVESTIMENTO",$F12,0)-IF($G12="INVESTIMENTO",$F12,0)) -> 0 | AJ12: =IF($B12="","",IF(NOT(ISNUMBER($F12)),"ERRO: valor nao numerico",IF($F12<=0,"ERRO: valor deve ser maior que zero",IF(COUNTIF(MAP_TIPO,$D12)=0,"ERRO: tipo de operacao nao cadastrado",IF(COUNTIF(LST_STATUS,$E12)=0,"ERRO: status invalido",IF(AND($G12="EXTERNO",$I12="EXTERNO"),"ERRO: origem e destino externos",IF(AND($G12<>"EXTERNO",COUNTIFS(ENT_ID,$H12,ENT_TIPO,$G12)=0),"ERRO: origem inexistente",IF(AND($I12<>"EXTERNO",COUNTIFS(ENT_ID,$J12,ENT_TIPO,$I12)=0),"ERRO: destino inexistente",IF(AND($K12<>"",COUNTIF(CAT_ID,$K12)=0),"ERRO: categoria inexistente",IF(AND($L12<>"",COUNTIF(SUB_ID,$L12)=0),"ERRO: subcategoria inexistente",IF(AND($L12<>"",$K12<>"",IFERROR(INDEX(SUB_CATID,MATCH($L12,SUB_ID,0)),"")<>$K12),"ERRO: subcategoria nao pertence a categoria",IF(AND($O12<>"",COUNTIF(P_ID,$O12)=0),"ERRO: parcela inexistente",IF(AND($N12<>"",COUNTIF(CM_ID,$N12)=0),"ERRO: compromisso inexistente","OK"))))))))))))) | AK12: =IF($B12="","",IF(AND($N12="",$O12="",$P12="",$Q12="",$R12=""),"","VINCULADO: "&TRIM(IF($N12<>"",$N12&" ","")&IF($O12<>"",$O12&" ","")&IF($P12<>"",$P12&" ","")&IF($Q12<>"",$Q12&" ","")&IF($R12<>"",$R12,""))))
A13: =IF($B13="","","LAN-"&TEXT(ROW()-4,"000000")) | T13: =IF($B13="","",YEAR($B13)) | U13: =IF($B13="","",MONTH($B13)) | V13: =IF($B13="","",YEAR($B13)*100+MONTH($B13)) | W13: =IF($D13="","",IFERROR(INDEX(MAP_CLASS,MATCH($D13,MAP_TIPO,0)),"TIPO INVALIDO")) | X13: =IF($K13="","",IFERROR(INDEX(CAT_NOME,MATCH($K13,CAT_ID,0)),"?")) | Y13: =IF($L13="","",IFERROR(INDEX(SUB_NOME,MATCH($L13,SUB_ID,0)),"?")) | Z13: =IF($G13="","",IF($G13="EXTERNO","(Externo)",IFERROR(INDEX(ENT_NOME,MATCH($H13,ENT_ID,0)),"?"))) | AA13: =IF($I13="","",IF($I13="EXTERNO","(Externo)",IFERROR(INDEX(ENT_NOME,MATCH($J13,ENT_ID,0)),"?"))) | AB13: =IF($B13="",0,IF(AND($I13="CONTA",$G13<>"CONTA"),$F13,0)) -> 0 | AC13: =IF($B13="",0,IF(AND($G13="CONTA",$I13<>"CONTA"),$F13,0)) -> 0 | AD13: =IF($W13="RECEITA",$F13,0) -> 0 | AE13: =IF($W13="DESPESA",$F13,0) -> 0 | AF13: =IF($W13="RECEITA_FINANCEIRA",$F13,0) -> 0 | AG13: =IF($B13="",0,IF($I13="CONTA",$F13,0)-IF($G13="CONTA",$F13,0)) -> 0 | AH13: =IF($B13="",0,IF($G13="CARTAO",$F13,0)-IF($I13="CARTAO",$F13,0)) -> 0 | AI13: =IF($B13="",0,IF($I13="INVESTIMENTO",$F13,0)-IF($G13="INVESTIMENTO",$F13,0)) -> 0 | AJ13: =IF($B13="","",IF(NOT(ISNUMBER($F13)),"ERRO: valor nao numerico",IF($F13<=0,"ERRO: valor deve ser maior que zero",IF(COUNTIF(MAP_TIPO,$D13)=0,"ERRO: tipo de operacao nao cadastrado",IF(COUNTIF(LST_STATUS,$E13)=0,"ERRO: status invalido",IF(AND($G13="EXTERNO",$I13="EXTERNO"),"ERRO: origem e destino externos",IF(AND($G13<>"EXTERNO",COUNTIFS(ENT_ID,$H13,ENT_TIPO,$G13)=0),"ERRO: origem inexistente",IF(AND($I13<>"EXTERNO",COUNTIFS(ENT_ID,$J13,ENT_TIPO,$I13)=0),"ERRO: destino inexistente",IF(AND($K13<>"",COUNTIF(CAT_ID,$K13)=0),"ERRO: categoria inexistente",IF(AND($L13<>"",COUNTIF(SUB_ID,$L13)=0),"ERRO: subcategoria inexistente",IF(AND($L13<>"",$K13<>"",IFERROR(INDEX(SUB_CATID,MATCH($L13,SUB_ID,0)),"")<>$K13),"ERRO: subcategoria nao pertence a categoria",IF(AND($O13<>"",COUNTIF(P_ID,$O13)=0),"ERRO: parcela inexistente",IF(AND($N13<>"",COUNTIF(CM_ID,$N13)=0),"ERRO: compromisso inexistente","OK"))))))))))))) | AK13: =IF($B13="","",IF(AND($N13="",$O13="",$P13="",$Q13="",$R13=""),"","VINCULADO: "&TRIM(IF($N13<>"",$N13&" ","")&IF($O13<>"",$O13&" ","")&IF($P13<>"",$P13&" ","")&IF($Q13<>"",$Q13&" ","")&IF($R13<>"",$R13,""))))
A14: =IF($B14="","","LAN-"&TEXT(ROW()-4,"000000")) | T14: =IF($B14="","",YEAR($B14)) | U14: =IF($B14="","",MONTH($B14)) | V14: =IF($B14="","",YEAR($B14)*100+MONTH($B14)) | W14: =IF($D14="","",IFERROR(INDEX(MAP_CLASS,MATCH($D14,MAP_TIPO,0)),"TIPO INVALIDO")) | X14: =IF($K14="","",IFERROR(INDEX(CAT_NOME,MATCH($K14,CAT_ID,0)),"?")) | Y14: =IF($L14="","",IFERROR(INDEX(SUB_NOME,MATCH($L14,SUB_ID,0)),"?")) | Z14: =IF($G14="","",IF($G14="EXTERNO","(Externo)",IFERROR(INDEX(ENT_NOME,MATCH($H14,ENT_ID,0)),"?"))) | AA14: =IF($I14="","",IF($I14="EXTERNO","(Externo)",IFERROR(INDEX(ENT_NOME,MATCH($J14,ENT_ID,0)),"?"))) | AB14: =IF($B14="",0,IF(AND($I14="CONTA",$G14<>"CONTA"),$F14,0)) -> 0 | AC14: =IF($B14="",0,IF(AND($G14="CONTA",$I14<>"CONTA"),$F14,0)) -> 0 | AD14: =IF($W14="RECEITA",$F14,0) -> 0 | AE14: =IF($W14="DESPESA",$F14,0) -> 0 | AF14: =IF($W14="RECEITA_FINANCEIRA",$F14,0) -> 0 | AG14: =IF($B14="",0,IF($I14="CONTA",$F14,0)-IF($G14="CONTA",$F14,0)) -> 0 | AH14: =IF($B14="",0,IF($G14="CARTAO",$F14,0)-IF($I14="CARTAO",$F14,0)) -> 0 | AI14: =IF($B14="",0,IF($I14="INVESTIMENTO",$F14,0)-IF($G14="INVESTIMENTO",$F14,0)) -> 0 | AJ14: =IF($B14="","",IF(NOT(ISNUMBER($F14)),"ERRO: valor nao numerico",IF($F14<=0,"ERRO: valor deve ser maior que zero",IF(COUNTIF(MAP_TIPO,$D14)=0,"ERRO: tipo de operacao nao cadastrado",IF(COUNTIF(LST_STATUS,$E14)=0,"ERRO: status invalido",IF(AND($G14="EXTERNO",$I14="EXTERNO"),"ERRO: origem e destino externos",IF(AND($G14<>"EXTERNO",COUNTIFS(ENT_ID,$H14,ENT_TIPO,$G14)=0),"ERRO: origem inexistente",IF(AND($I14<>"EXTERNO",COUNTIFS(ENT_ID,$J14,ENT_TIPO,$I14)=0),"ERRO: destino inexistente",IF(AND($K14<>"",COUNTIF(CAT_ID,$K14)=0),"ERRO: categoria inexistente",IF(AND($L14<>"",COUNTIF(SUB_ID,$L14)=0),"ERRO: subcategoria inexistente",IF(AND($L14<>"",$K14<>"",IFERROR(INDEX(SUB_CATID,MATCH($L14,SUB_ID,0)),"")<>$K14),"ERRO: subcategoria nao pertence a categoria",IF(AND($O14<>"",COUNTIF(P_ID,$O14)=0),"ERRO: parcela inexistente",IF(AND($N14<>"",COUNTIF(CM_ID,$N14)=0),"ERRO: compromisso inexistente","OK"))))))))))))) | AK14: =IF($B14="","",IF(AND($N14="",$O14="",$P14="",$Q14="",$R14=""),"","VINCULADO: "&TRIM(IF($N14<>"",$N14&" ","")&IF($O14<>"",$O14&" ","")&IF($P14<>"",$P14&" ","")&IF($Q14<>"",$Q14&" ","")&IF($R14<>"",$R14,""))))
A15: =IF($B15="","","LAN-"&TEXT(ROW()-4,"000000")) | T15: =IF($B15="","",YEAR($B15)) | U15: =IF($B15="","",MONTH($B15)) | V15: =IF($B15="","",YEAR($B15)*100+MONTH($B15)) | W15: =IF($D15="","",IFERROR(INDEX(MAP_CLASS,MATCH($D15,MAP_TIPO,0)),"TIPO INVALIDO")) | X15: =IF($K15="","",IFERROR(INDEX(CAT_NOME,MATCH($K15,CAT_ID,0)),"?")) | Y15: =IF($L15="","",IFERROR(INDEX(SUB_NOME,MATCH($L15,SUB_ID,0)),"?")) | Z15: =IF($G15="","",IF($G15="EXTERNO","(Externo)",IFERROR(INDEX(ENT_NOME,MATCH($H15,ENT_ID,0)),"?"))) | AA15: =IF($I15="","",IF($I15="EXTERNO","(Externo)",IFERROR(INDEX(ENT_NOME,MATCH($J15,ENT_ID,0)),"?"))) | AB15: =IF($B15="",0,IF(AND($I15="CONTA",$G15<>"CONTA"),$F15,0)) -> 0 | AC15: =IF($B15="",0,IF(AND($G15="CONTA",$I15<>"CONTA"),$F15,0)) -> 0 | AD15: =IF($W15="RECEITA",$F15,0) -> 0 | AE15: =IF($W15="DESPESA",$F15,0) -> 0 | AF15: =IF($W15="RECEITA_FINANCEIRA",$F15,0) -> 0 | AG15: =IF($B15="",0,IF($I15="CONTA",$F15,0)-IF($G15="CONTA",$F15,0)) -> 0 | AH15: =IF($B15="",0,IF($G15="CARTAO",$F15,0)-IF($I15="CARTAO",$F15,0)) -> 0 | AI15: =IF($B15="",0,IF($I15="INVESTIMENTO",$F15,0)-IF($G15="INVESTIMENTO",$F15,0)) -> 0 | AJ15: =IF($B15="","",IF(NOT(ISNUMBER($F15)),"ERRO: valor nao numerico",IF($F15<=0,"ERRO: valor deve ser maior que zero",IF(COUNTIF(MAP_TIPO,$D15)=0,"ERRO: tipo de operacao nao cadastrado",IF(COUNTIF(LST_STATUS,$E15)=0,"ERRO: status invalido",IF(AND($G15="EXTERNO",$I15="EXTERNO"),"ERRO: origem e destino externos",IF(AND($G15<>"EXTERNO",COUNTIFS(ENT_ID,$H15,ENT_TIPO,$G15)=0),"ERRO: origem inexistente",IF(AND($I15<>"EXTERNO",COUNTIFS(ENT_ID,$J15,ENT_TIPO,$I15)=0),"ERRO: destino inexistente",IF(AND($K15<>"",COUNTIF(CAT_ID,$K15)=0),"ERRO: categoria inexistente",IF(AND($L15<>"",COUNTIF(SUB_ID,$L15)=0),"ERRO: subcategoria inexistente",IF(AND($L15<>"",$K15<>"",IFERROR(INDEX(SUB_CATID,MATCH($L15,SUB_ID,0)),"")<>$K15),"ERRO: subcategoria nao pertence a categoria",IF(AND($O15<>"",COUNTIF(P_ID,$O15)=0),"ERRO: parcela inexistente",IF(AND($N15<>"",COUNTIF(CM_ID,$N15)=0),"ERRO: compromisso inexistente","OK"))))))))))))) | AK15: =IF($B15="","",IF(AND($N15="",$O15="",$P15="",$Q15="",$R15=""),"","VINCULADO: "&TRIM(IF($N15<>"",$N15&" ","")&IF($O15<>"",$O15&" ","")&IF($P15<>"",$P15&" ","")&IF($Q15<>"",$Q15&" ","")&IF($R15<>"",$R15,""))))
A16: =IF($B16="","","LAN-"&TEXT(ROW()-4,"000000")) | T16: =IF($B16="","",YEAR($B16)) | U16: =IF($B16="","",MONTH($B16)) | V16: =IF($B16="","",YEAR($B16)*100+MONTH($B16)) | W16: =IF($D16="","",IFERROR(INDEX(MAP_CLASS,MATCH($D16,MAP_TIPO,0)),"TIPO INVALIDO")) | X16: =IF($K16="","",IFERROR(INDEX(CAT_NOME,MATCH($K16,CAT_ID,0)),"?")) | Y16: =IF($L16="","",IFERROR(INDEX(SUB_NOME,MATCH($L16,SUB_ID,0)),"?")) | Z16: =IF($G16="","",IF($G16="EXTERNO","(Externo)",IFERROR(INDEX(ENT_NOME,MATCH($H16,ENT_ID,0)),"?"))) | AA16: =IF($I16="","",IF($I16="EXTERNO","(Externo)",IFERROR(INDEX(ENT_NOME,MATCH($J16,ENT_ID,0)),"?"))) | AB16: =IF($B16="",0,IF(AND($I16="CONTA",$G16<>"CONTA"),$F16,0)) -> 0 | AC16: =IF($B16="",0,IF(AND($G16="CONTA",$I16<>"CONTA"),$F16,0)) -> 0 | AD16: =IF($W16="RECEITA",$F16,0) -> 0 | AE16: =IF($W16="DESPESA",$F16,0) -> 0 | AF16: =IF($W16="RECEITA_FINANCEIRA",$F16,0) -> 0 | AG16: =IF($B16="",0,IF($I16="CONTA",$F16,0)-IF($G16="CONTA",$F16,0)) -> 0 | AH16: =IF($B16="",0,IF($G16="CARTAO",$F16,0)-IF($I16="CARTAO",$F16,0)) -> 0 | AI16: =IF($B16="",0,IF($I16="INVESTIMENTO",$F16,0)-IF($G16="INVESTIMENTO",$F16,0)) -> 0 | AJ16: =IF($B16="","",IF(NOT(ISNUMBER($F16)),"ERRO: valor nao numerico",IF($F16<=0,"ERRO: valor deve ser maior que zero",IF(COUNTIF(MAP_TIPO,$D16)=0,"ERRO: tipo de operacao nao cadastrado",IF(COUNTIF(LST_STATUS,$E16)=0,"ERRO: status invalido",IF(AND($G16="EXTERNO",$I16="EXTERNO"),"ERRO: origem e destino externos",IF(AND($G16<>"EXTERNO",COUNTIFS(ENT_ID,$H16,ENT_TIPO,$G16)=0),"ERRO: origem inexistente",IF(AND($I16<>"EXTERNO",COUNTIFS(ENT_ID,$J16,ENT_TIPO,$I16)=0),"ERRO: destino inexistente",IF(AND($K16<>"",COUNTIF(CAT_ID,$K16)=0),"ERRO: categoria inexistente",IF(AND($L16<>"",COUNTIF(SUB_ID,$L16)=0),"ERRO: subcategoria inexistente",IF(AND($L16<>"",$K16<>"",IFERROR(INDEX(SUB_CATID,MATCH($L16,SUB_ID,0)),"")<>$K16),"ERRO: subcategoria nao pertence a categoria",IF(AND($O16<>"",COUNTIF(P_ID,$O16)=0),"ERRO: parcela inexistente",IF(AND($N16<>"",COUNTIF(CM_ID,$N16)=0),"ERRO: compromisso inexistente","OK"))))))))))))) | AK16: =IF($B16="","",IF(AND($N16="",$O16="",$P16="",$Q16="",$R16=""),"","VINCULADO: "&TRIM(IF($N16<>"",$N16&" ","")&IF($O16<>"",$O16&" ","")&IF($P16<>"",$P16&" ","")&IF($Q16<>"",$Q16&" ","")&IF($R16<>"",$R16,""))))
... A904: =IF($B904="","","LAN-"&TEXT(ROW()-4,"000000")) | T904: =IF($B904="","",YEAR($B904)) | U904: =IF($B904="","",MONTH($B904)) | V904: =IF($B904="","",YEAR($B904)*100+MONTH($B904)) | W904: =IF($D904="","",IFERROR(INDEX(MAP_CLASS,MATCH($D904,MAP_TIPO,0)),"TIPO INVALIDO")) | X904: =IF($K904="","",IFERROR(INDEX(CAT_NOME,MATCH($K904,CAT_ID,0)),"?")) | Y904: =IF($L904="","",IFERROR(INDEX(SUB_NOME,MATCH($L904,SUB_ID,0)),"?")) | Z904: =IF($G904="","",IF($G904="EXTERNO","(Externo)",IFERROR(INDEX(ENT_NOME,MATCH($H904,ENT_ID,0)),"?"))) | AA904: =IF($I904="","",IF($I904="EXTERNO","(Externo)",IFERROR(INDEX(ENT_NOME,MATCH($J904,ENT_ID,0)),"?"))) | AB904: =IF($B904="",0,IF(AND($I904="CONTA",$G904<>"CONTA"),$F904,0)) -> 0 | AC904: =IF($B904="",0,IF(AND($G904="CONTA",$I904<>"CONTA"),$F904,0)) -> 0 | AD904: =IF($W904="RECEITA",$F904,0) -> 0 | AE904: =IF($W904="DESPESA",$F904,0) -> 0 | AF904: =IF($W904="RECEITA_FINANCEIRA",$F904,0) -> 0 | AG904: =IF($B904="",0,IF($I904="CONTA",$F904,0)-IF($G904="CONTA",$F904,0)) -> 0 | AH904: =IF($B904="",0,IF($G904="CARTAO",$F904,0)-IF($I904="CARTAO",$F904,0)) -> 0 | AI904: =IF($B904="",0,IF($I904="INVESTIMENTO",$F904,0)-IF($G904="INVESTIMENTO",$F904,0)) -> 0 | AJ904: =IF($B904="","",IF(NOT(ISNUMBER($F904)),"ERRO: valor nao numerico",IF($F904<=0,"ERRO: valor deve ser maior que zero",IF(COUNTIF(MAP_TIPO,$D904)=0,"ERRO: tipo de operacao nao cadastrado",IF(COUNTIF(LST_STATUS,$E904)=0,"ERRO: status invalido",IF(AND($G904="EXTERNO",$I904="EXTERNO"),"ERRO: origem e destino externos",IF(AND($G904<>"EXTERNO",COUNTIFS(ENT_ID,$H904,ENT_TIPO,$G904)=0),"ERRO: origem inexistente",IF(AND($I904<>"EXTERNO",COUNTIFS(ENT_ID,$J904,ENT_TIPO,$I904)=0),"ERRO: destino inexistente",IF(AND($K904<>"",COUNTIF(CAT_ID,$K904)=0),"ERRO: categoria inexistente",IF(AND($L904<>"",COUNTIF(SUB_ID,$L904)=0),"ERRO: subcategoria inexistente",IF(AND($L904<>"",$K904<>"",IFERROR(INDEX(SUB_CATID,MATCH($L904,SUB_ID,0)),"")<>$K904),"ERRO: subcategoria nao pertence a categoria",IF(AND($O904<>"",COUNTIF(P_ID,$O904)=0),"ERRO: parcela inexistente",IF(AND($N904<>"",COUNTIF(CM_ID,$N904)=0),"ERRO: compromisso inexistente","OK"))))))))))))) | AK904: =IF($B904="","",IF(AND($N904="",$O904="",$P904="",$Q904="",$R904=""),"","VINCULADO: "&TRIM(IF($N904<>"",$N904&" ","")&IF($O904<>"",$O904&" ","")&IF($P904<>"",$P904&" ","")&IF($Q904<>"",$Q904&" ","")&IF($R904<>"",$R904,""))))

Sheet PARCELAS
A1: PARCELAS - CRONOGRAMA DE TODOS OS COMPROMISSOS
A2: PARA APAGAR UM REGISTRO: selecione as celulas AMARELAS da linha e pressione DELETE (limpar conteudo). NUNCA use 'Excluir linha' nem classifique (sort) esta aba: os IDs sao gerados pela posicao da linha e os vinculos seriam quebrados em silencio. Para anular um lancamento sem perder o historico use o campo Status (CANCELADO / Inativo). Para pesquisar use os filtros do cabecalho. O cronograma e gerado uma unica vez por compromisso. Use a aba GERADOR para produzir o cronograma de um novo compromisso e cole o resultado (colunas B ate E) no fim desta lista.
A4: ID_Parcela | B4: ID_Compromisso | C4: Num_Parcela | D4: Data_Vencimento | E4: Valor_Parcela | F4: Observacao | G4: Compromisso | H4: Total_Parcelas | I4: Rotulo | J4: Pago_Antes_Sistema | K4: Pagto_Realizado | L4: Data_Pagamento | M4: Qtd_Lanc_Realizados | N4: Qtd_Lanc_Projetados | O4: Status_Parcela | P4: Dias_Atraso | Q4: Diferenca_Valor
A5: =IF($B5="","","PAR-"&TEXT(ROW()-4,"000000")) | G5: =IF($B5="","",IFERROR(INDEX(CM_NOME,MATCH($B5,CM_ID,0)),"?")) | H5: =IF($B5="","",IFERROR(INDEX(CM_QTD,MATCH($B5,CM_ID,0)),"")) | I5: =IF($A5="","",$C5&"/"&$H5) | J5: =IF($A5="","",IF($C5<=IFERROR(INDEX(CM_PAGASANTES,MATCH($B5,CM_ID,0)),0),"SIM","NAO")) | K5: =IF($A5="",0,SUMIFS(L_Valor,L_ParcID,$A5,L_Status,"REALIZADO")) -> 0 | L5: =IF($A5="","",IFERROR(INDEX(L_Data,MATCH(1,INDEX((L_ParcID=$A5)*(L_Status="REALIZADO"),0),0)),"")) | M5: =IF($A5="",0,COUNTIFS(L_ParcID,$A5,L_Status,"REALIZADO")) -> 0 | N5: =IF($A5="",0,COUNTIFS(L_ParcID,$A5,L_Status,"PROJETADO")) -> 0 | O5: =IF($A5="","",IF($J5="SIM","PAGA",IF($M5>0,"PAGA",IF($D5<CFG_HOJE,"ATRASADA",IF($D5<=EOMONTH(CFG_HOJE,0),"ABERTA","PROJETADA"))))) | P5: =IF($O5="ATRASADA",CFG_HOJE-$D5,0) -> 0 | Q5: =IF($A5="",0,IF(AND($O5="PAGA",$J5="NAO"),$K5-$E5,0)) -> 0
A6: =IF($B6="","","PAR-"&TEXT(ROW()-4,"000000")) | G6: =IF($B6="","",IFERROR(INDEX(CM_NOME,MATCH($B6,CM_ID,0)),"?")) | H6: =IF($B6="","",IFERROR(INDEX(CM_QTD,MATCH($B6,CM_ID,0)),"")) | I6: =IF($A6="","",$C6&"/"&$H6) | J6: =IF($A6="","",IF($C6<=IFERROR(INDEX(CM_PAGASANTES,MATCH($B6,CM_ID,0)),0),"SIM","NAO")) | K6: =IF($A6="",0,SUMIFS(L_Valor,L_ParcID,$A6,L_Status,"REALIZADO")) -> 0 | L6: =IF($A6="","",IFERROR(INDEX(L_Data,MATCH(1,INDEX((L_ParcID=$A6)*(L_Status="REALIZADO"),0),0)),"")) | M6: =IF($A6="",0,COUNTIFS(L_ParcID,$A6,L_Status,"REALIZADO")) -> 0 | N6: =IF($A6="",0,COUNTIFS(L_ParcID,$A6,L_Status,"PROJETADO")) -> 0 | O6: =IF($A6="","",IF($J6="SIM","PAGA",IF($M6>0,"PAGA",IF($D6<CFG_HOJE,"ATRASADA",IF($D6<=EOMONTH(CFG_HOJE,0),"ABERTA","PROJETADA"))))) | P6: =IF($O6="ATRASADA",CFG_HOJE-$D6,0) -> 0 | Q6: =IF($A6="",0,IF(AND($O6="PAGA",$J6="NAO"),$K6-$E6,0)) -> 0
A7: =IF($B7="","","PAR-"&TEXT(ROW()-4,"000000")) | G7: =IF($B7="","",IFERROR(INDEX(CM_NOME,MATCH($B7,CM_ID,0)),"?")) | H7: =IF($B7="","",IFERROR(INDEX(CM_QTD,MATCH($B7,CM_ID,0)),"")) | I7: =IF($A7="","",$C7&"/"&$H7) | J7: =IF($A7="","",IF($C7<=IFERROR(INDEX(CM_PAGASANTES,MATCH($B7,CM_ID,0)),0),"SIM","NAO")) | K7: =IF($A7="",0,SUMIFS(L_Valor,L_ParcID,$A7,L_Status,"REALIZADO")) -> 0 | L7: =IF($A7="","",IFERROR(INDEX(L_Data,MATCH(1,INDEX((L_ParcID=$A7)*(L_Status="REALIZADO"),0),0)),"")) | M7: =IF($A7="",0,COUNTIFS(L_ParcID,$A7,L_Status,"REALIZADO")) -> 0 | N7: =IF($A7="",0,COUNTIFS(L_ParcID,$A7,L_Status,"PROJETADO")) -> 0 | O7: =IF($A7="","",IF($J7="SIM","PAGA",IF($M7>0,"PAGA",IF($D7<CFG_HOJE,"ATRASADA",IF($D7<=EOMONTH(CFG_HOJE,0),"ABERTA","PROJETADA"))))) | P7: =IF($O7="ATRASADA",CFG_HOJE-$D7,0) -> 0 | Q7: =IF($A7="",0,IF(AND($O7="PAGA",$J7="NAO"),$K7-$E7,0)) -> 0
A8: =IF($B8="","","PAR-"&TEXT(ROW()-4,"000000")) | G8: =IF($B8="","",IFERROR(INDEX(CM_NOME,MATCH($B8,CM_ID,0)),"?")) | H8: =IF($B8="","",IFERROR(INDEX(CM_QTD,MATCH($B8,CM_ID,0)),"")) | I8: =IF($A8="","",$C8&"/"&$H8) | J8: =IF($A8="","",IF($C8<=IFERROR(INDEX(CM_PAGASANTES,MATCH($B8,CM_ID,0)),0),"SIM","NAO")) | K8: =IF($A8="",0,SUMIFS(L_Valor,L_ParcID,$A8,L_Status,"REALIZADO")) -> 0 | L8: =IF($A8="","",IFERROR(INDEX(L_Data,MATCH(1,INDEX((L_ParcID=$A8)*(L_Status="REALIZADO"),0),0)),"")) | M8: =IF($A8="",0,COUNTIFS(L_ParcID,$A8,L_Status,"REALIZADO")) -> 0 | N8: =IF($A8="",0,COUNTIFS(L_ParcID,$A8,L_Status,"PROJETADO")) -> 0 | O8: =IF($A8="","",IF($J8="SIM","PAGA",IF($M8>0,"PAGA",IF($D8<CFG_HOJE,"ATRASADA",IF($D8<=EOMONTH(CFG_HOJE,0),"ABERTA","PROJETADA"))))) | P8: =IF($O8="ATRASADA",CFG_HOJE-$D8,0) -> 0 | Q8: =IF($A8="",0,IF(AND($O8="PAGA",$J8="NAO"),$K8-$E8,0)) -> 0
A9: =IF($B9="","","PAR-"&TEXT(ROW()-4,"000000")) | G9: =IF($B9="","",IFERROR(INDEX(CM_NOME,MATCH($B9,CM_ID,0)),"?")) | H9: =IF($B9="","",IFERROR(INDEX(CM_QTD,MATCH($B9,CM_ID,0)),"")) | I9: =IF($A9="","",$C9&"/"&$H9) | J9: =IF($A9="","",IF($C9<=IFERROR(INDEX(CM_PAGASANTES,MATCH($B9,CM_ID,0)),0),"SIM","NAO")) | K9: =IF($A9="",0,SUMIFS(L_Valor,L_ParcID,$A9,L_Status,"REALIZADO")) -> 0 | L9: =IF($A9="","",IFERROR(INDEX(L_Data,MATCH(1,INDEX((L_ParcID=$A9)*(L_Status="REALIZADO"),0),0)),"")) | M9: =IF($A9="",0,COUNTIFS(L_ParcID,$A9,L_Status,"REALIZADO")) -> 0 | N9: =IF($A9="",0,COUNTIFS(L_ParcID,$A9,L_Status,"PROJETADO")) -> 0 | O9: =IF($A9="","",IF($J9="SIM","PAGA",IF($M9>0,"PAGA",IF($D9<CFG_HOJE,"ATRASADA",IF($D9<=EOMONTH(CFG_HOJE,0),"ABERTA","PROJETADA"))))) | P9: =IF($O9="ATRASADA",CFG_HOJE-$D9,0) -> 0 | Q9: =IF($A9="",0,IF(AND($O9="PAGA",$J9="NAO"),$K9-$E9,0)) -> 0
A10: =IF($B10="","","PAR-"&TEXT(ROW()-4,"000000")) | G10: =IF($B10="","",IFERROR(INDEX(CM_NOME,MATCH($B10,CM_ID,0)),"?")) | H10: =IF($B10="","",IFERROR(INDEX(CM_QTD,MATCH($B10,CM_ID,0)),"")) | I10: =IF($A10="","",$C10&"/"&$H10) | J10: =IF($A10="","",IF($C10<=IFERROR(INDEX(CM_PAGASANTES,MATCH($B10,CM_ID,0)),0),"SIM","NAO")) | K10: =IF($A10="",0,SUMIFS(L_Valor,L_ParcID,$A10,L_Status,"REALIZADO")) -> 0 | L10: =IF($A10="","",IFERROR(INDEX(L_Data,MATCH(1,INDEX((L_ParcID=$A10)*(L_Status="REALIZADO"),0),0)),"")) | M10: =IF($A10="",0,COUNTIFS(L_ParcID,$A10,L_Status,"REALIZADO")) -> 0 | N10: =IF($A10="",0,COUNTIFS(L_ParcID,$A10,L_Status,"PROJETADO")) -> 0 | O10: =IF($A10="","",IF($J10="SIM","PAGA",IF($M10>0,"PAGA",IF($D10<CFG_HOJE,"ATRASADA",IF($D10<=EOMONTH(CFG_HOJE,0),"ABERTA","PROJETADA"))))) | P10: =IF($O10="ATRASADA",CFG_HOJE-$D10,0) -> 0 | Q10: =IF($A10="",0,IF(AND($O10="PAGA",$J10="NAO"),$K10-$E10,0)) -> 0
A11: =IF($B11="","","PAR-"&TEXT(ROW()-4,"000000")) | G11: =IF($B11="","",IFERROR(INDEX(CM_NOME,MATCH($B11,CM_ID,0)),"?")) | H11: =IF($B11="","",IFERROR(INDEX(CM_QTD,MATCH($B11,CM_ID,0)),"")) | I11: =IF($A11="","",$C11&"/"&$H11) | J11: =IF($A11="","",IF($C11<=IFERROR(INDEX(CM_PAGASANTES,MATCH($B11,CM_ID,0)),0),"SIM","NAO")) | K11: =IF($A11="",0,SUMIFS(L_Valor,L_ParcID,$A11,L_Status,"REALIZADO")) -> 0 | L11: =IF($A11="","",IFERROR(INDEX(L_Data,MATCH(1,INDEX((L_ParcID=$A11)*(L_Status="REALIZADO"),0),0)),"")) | M11: =IF($A11="",0,COUNTIFS(L_ParcID,$A11,L_Status,"REALIZADO")) -> 0 | N11: =IF($A11="",0,COUNTIFS(L_ParcID,$A11,L_Status,"PROJETADO")) -> 0 | O11: =IF($A11="","",IF($J11="SIM","PAGA",IF($M11>0,"PAGA",IF($D11<CFG_HOJE,"ATRASADA",IF($D11<=EOMONTH(CFG_HOJE,0),"ABERTA","PROJETADA"))))) | P11: =IF($O11="ATRASADA",CFG_HOJE-$D11,0) -> 0 | Q11: =IF($A11="",0,IF(AND($O11="PAGA",$J11="NAO"),$K11-$E11,0)) -> 0
A12: =IF($B12="","","PAR-"&TEXT(ROW()-4,"000000")) | G12: =IF($B12="","",IFERROR(INDEX(CM_NOME,MATCH($B12,CM_ID,0)),"?")) | H12: =IF($B12="","",IFERROR(INDEX(CM_QTD,MATCH($B12,CM_ID,0)),"")) | I12: =IF($A12="","",$C12&"/"&$H12) | J12: =IF($A12="","",IF($C12<=IFERROR(INDEX(CM_PAGASANTES,MATCH($B12,CM_ID,0)),0),"SIM","NAO")) | K12: =IF($A12="",0,SUMIFS(L_Valor,L_ParcID,$A12,L_Status,"REALIZADO")) -> 0 | L12: =IF($A12="","",IFERROR(INDEX(L_Data,MATCH(1,INDEX((L_ParcID=$A12)*(L_Status="REALIZADO"),0),0)),"")) | M12: =IF($A12="",0,COUNTIFS(L_ParcID,$A12,L_Status,"REALIZADO")) -> 0 | N12: =IF($A12="",0,COUNTIFS(L_ParcID,$A12,L_Status,"PROJETADO")) -> 0 | O12: =IF($A12="","",IF($J12="SIM","PAGA",IF($M12>0,"PAGA",IF($D12<CFG_HOJE,"ATRASADA",IF($D12<=EOMONTH(CFG_HOJE,0),"ABERTA","PROJETADA"))))) | P12: =IF($O12="ATRASADA",CFG_HOJE-$D12,0) -> 0 | Q12: =IF($A12="",0,IF(AND($O12="PAGA",$J12="NAO"),$K12-$E12,0)) -> 0
A13: =IF($B13="","","PAR-"&TEXT(ROW()-4,"000000")) | G13: =IF($B13="","",IFERROR(INDEX(CM_NOME,MATCH($B13,CM_ID,0)),"?")) | H13: =IF($B13="","",IFERROR(INDEX(CM_QTD,MATCH($B13,CM_ID,0)),"")) | I13: =IF($A13="","",$C13&"/"&$H13) | J13: =IF($A13="","",IF($C13<=IFERROR(INDEX(CM_PAGASANTES,MATCH($B13,CM_ID,0)),0),"SIM","NAO")) | K13: =IF($A13="",0,SUMIFS(L_Valor,L_ParcID,$A13,L_Status,"REALIZADO")) -> 0 | L13: =IF($A13="","",IFERROR(INDEX(L_Data,MATCH(1,INDEX((L_ParcID=$A13)*(L_Status="REALIZADO"),0),0)),"")) | M13: =IF($A13="",0,COUNTIFS(L_ParcID,$A13,L_Status,"REALIZADO")) -> 0 | N13: =IF($A13="",0,COUNTIFS(L_ParcID,$A13,L_Status,"PROJETADO")) -> 0 | O13: =IF($A13="","",IF($J13="SIM","PAGA",IF($M13>0,"PAGA",IF($D13<CFG_HOJE,"ATRASADA",IF($D13<=EOMONTH(CFG_HOJE,0),"ABERTA","PROJETADA"))))) | P13: =IF($O13="ATRASADA",CFG_HOJE-$D13,0) -> 0 | Q13: =IF($A13="",0,IF(AND($O13="PAGA",$J13="NAO"),$K13-$E13,0)) -> 0
A14: =IF($B14="","","PAR-"&TEXT(ROW()-4,"000000")) | G14: =IF($B14="","",IFERROR(INDEX(CM_NOME,MATCH($B14,CM_ID,0)),"?")) | H14: =IF($B14="","",IFERROR(INDEX(CM_QTD,MATCH($B14,CM_ID,0)),"")) | I14: =IF($A14="","",$C14&"/"&$H14) | J14: =IF($A14="","",IF($C14<=IFERROR(INDEX(CM_PAGASANTES,MATCH($B14,CM_ID,0)),0),"SIM","NAO")) | K14: =IF($A14="",0,SUMIFS(L_Valor,L_ParcID,$A14,L_Status,"REALIZADO")) -> 0 | L14: =IF($A14="","",IFERROR(INDEX(L_Data,MATCH(1,INDEX((L_ParcID=$A14)*(L_Status="REALIZADO"),0),0)),"")) | M14: =IF($A14="",0,COUNTIFS(L_ParcID,$A14,L_Status,"REALIZADO")) -> 0 | N14: =IF($A14="",0,COUNTIFS(L_ParcID,$A14,L_Status,"PROJETADO")) -> 0 | O14: =IF($A14="","",IF($J14="SIM","PAGA",IF($M14>0,"PAGA",IF($D14<CFG_HOJE,"ATRASADA",IF($D14<=EOMONTH(CFG_HOJE,0),"ABERTA","PROJETADA"))))) | P14: =IF($O14="ATRASADA",CFG_HOJE-$D14,0) -> 0 | Q14: =IF($A14="",0,IF(AND($O14="PAGA",$J14="NAO"),$K14-$E14,0)) -> 0
A15: =IF($B15="","","PAR-"&TEXT(ROW()-4,"000000")) | G15: =IF($B15="","",IFERROR(INDEX(CM_NOME,MATCH($B15,CM_ID,0)),"?")) | H15: =IF($B15="","",IFERROR(INDEX(CM_QTD,MATCH($B15,CM_ID,0)),"")) | I15: =IF($A15="","",$C15&"/"&$H15) | J15: =IF($A15="","",IF($C15<=IFERROR(INDEX(CM_PAGASANTES,MATCH($B15,CM_ID,0)),0),"SIM","NAO")) | K15: =IF($A15="",0,SUMIFS(L_Valor,L_ParcID,$A15,L_Status,"REALIZADO")) -> 0 | L15: =IF($A15="","",IFERROR(INDEX(L_Data,MATCH(1,INDEX((L_ParcID=$A15)*(L_Status="REALIZADO"),0),0)),"")) | M15: =IF($A15="",0,COUNTIFS(L_ParcID,$A15,L_Status,"REALIZADO")) -> 0 | N15: =IF($A15="",0,COUNTIFS(L_ParcID,$A15,L_Status,"PROJETADO")) -> 0 | O15: =IF($A15="","",IF($J15="SIM","PAGA",IF($M15>0,"PAGA",IF($D15<CFG_HOJE,"ATRASADA",IF($D15<=EOMONTH(CFG_HOJE,0),"ABERTA","PROJETADA"))))) | P15: =IF($O15="ATRASADA",CFG_HOJE-$D15,0) -> 0 | Q15: =IF($A15="",0,IF(AND($O15="PAGA",$J15="NAO"),$K15-$E15,0)) -> 0
A16: =IF($B16="","","PAR-"&TEXT(ROW()-4,"000000")) | G16: =IF($B16="","",IFERROR(INDEX(CM_NOME,MATCH($B16,CM_ID,0)),"?")) | H16: =IF($B16="","",IFERROR(INDEX(CM_QTD,MATCH($B16,CM_ID,0)),"")) | I16: =IF($A16="","",$C16&"/"&$H16) | J16: =IF($A16="","",IF($C16<=IFERROR(INDEX(CM_PAGASANTES,MATCH($B16,CM_ID,0)),0),"SIM","NAO")) | K16: =IF($A16="",0,SUMIFS(L_Valor,L_ParcID,$A16,L_Status,"REALIZADO")) -> 0 | L16: =IF($A16="","",IFERROR(INDEX(L_Data,MATCH(1,INDEX((L_ParcID=$A16)*(L_Status="REALIZADO"),0),0)),"")) | M16: =IF($A16="",0,COUNTIFS(L_ParcID,$A16,L_Status,"REALIZADO")) -> 0 | N16: =IF($A16="",0,COUNTIFS(L_ParcID,$A16,L_Status,"PROJETADO")) -> 0 | O16: =IF($A16="","",IF($J16="SIM","PAGA",IF($M16>0,"PAGA",IF($D16<CFG_HOJE,"ATRASADA",IF($D16<=EOMONTH(CFG_HOJE,0),"ABERTA","PROJETADA"))))) | P16: =IF($O16="ATRASADA",CFG_HOJE-$D16,0) -> 0 | Q16: =IF($A16="",0,IF(AND($O16="PAGA",$J16="NAO"),$K16-$E16,0)) -> 0
... A704: =IF($B704="","","PAR-"&TEXT(ROW()-4,"000000")) | G704: =IF($B704="","",IFERROR(INDEX(CM_NOME,MATCH($B704,CM_ID,0)),"?")) | H704: =IF($B704="","",IFERROR(INDEX(CM_QTD,MATCH($B704,CM_ID,0)),"")) | I704: =IF($A704="","",$C704&"/"&$H704) | J704: =IF($A704="","",IF($C704<=IFERROR(INDEX(CM_PAGASANTES,MATCH($B704,CM_ID,0)),0),"SIM","NAO")) | K704: =IF($A704="",0,SUMIFS(L_Valor,L_ParcID,$A704,L_Status,"REALIZADO")) -> 0 | L704: =IF($A704="","",IFERROR(INDEX(L_Data,MATCH(1,INDEX((L_ParcID=$A704)*(L_Status="REALIZADO"),0),0)),"")) | M704: =IF($A704="",0,COUNTIFS(L_ParcID,$A704,L_Status,"REALIZADO")) -> 0 | N704: =IF($A704="",0,COUNTIFS(L_ParcID,$A704,L_Status,"PROJETADO")) -> 0 | O704: =IF($A704="","",IF($J704="SIM","PAGA",IF($M704>0,"PAGA",IF($D704<CFG_HOJE,"ATRASADA",IF($D704<=EOMONTH(CFG_HOJE,0),"ABERTA","PROJETADA"))))) | P704: =IF($O704="ATRASADA",CFG_HOJE-$D704,0) -> 0 | Q704: =IF($A704="",0,IF(AND($O704="PAGA",$J704="NAO"),$K704-$E704,0)) -> 0

Sheet MOV_METAS
A1: MOV_METAS - MOVIMENTACAO DAS RESERVAS DE METAS
A2: PARA APAGAR UM REGISTRO: selecione as celulas AMARELAS da linha e pressione DELETE (limpar conteudo). NUNCA use 'Excluir linha' nem classifique (sort) esta aba: os IDs sao gerados pela posicao da linha e os vinculos seriam quebrados em silencio. Para anular um lancamento sem perder o historico use o campo Status (CANCELADO / Inativo). Para pesquisar use os filtros do cabecalho. Esta aba registra apenas RESERVAS LOGICAS. O dinheiro continua na conta; nenhuma linha daqui altera o saldo bancario.
A4: ID_Movimento | B4: Data | C4: ID_Meta | D4: Tipo_Movimento | E4: Valor | F4: Destino_Retirada | G4: ID_Meta_Destino | H4: Observacao | I4: Meta_Nome | J4: Sinal | K4: Valor_Com_Sinal | L4: Conta_Vinculada | M4: Validacao
A5: =IF($B5="","","MOV-"&TEXT(ROW()-4,"000000")) | I5: =IF($C5="","",IFERROR(INDEX(M_NOME,MATCH($C5,M_ID,0)),"?")) | J5: =IF($D5="",0,IFERROR(INDEX(MAP_SINALMOV,MATCH($D5,LST_TIPOMOV,0)),0)) -> 0 | K5: =IF($A5="",0,$E5*$J5) -> 0 | L5: =IF($C5="","",IFERROR(INDEX(M_CONTA,MATCH($C5,M_ID,0)),"")) | M5: =IF($B5="","",IF($E5<=0,"ERRO: valor deve ser maior que zero",IF(COUNTIF(M_ID,$C5)=0,"ERRO: meta inexistente",IF(COUNTIF(LST_TIPOMOV,$D5)=0,"ERRO: tipo de movimento invalido",IF(AND($D5="TRANSF_SAIDA",COUNTIF(M_ID,$G5)=0),"ERRO: informe a meta de destino",IF(AND($J5=-1,$F5=""),"ATENCAO: informe o destino da retirada","OK"))))))
A6: =IF($B6="","","MOV-"&TEXT(ROW()-4,"000000")) | I6: =IF($C6="","",IFERROR(INDEX(M_NOME,MATCH($C6,M_ID,0)),"?")) | J6: =IF($D6="",0,IFERROR(INDEX(MAP_SINALMOV,MATCH($D6,LST_TIPOMOV,0)),0)) -> 0 | K6: =IF($A6="",0,$E6*$J6) -> 0 | L6: =IF($C6="","",IFERROR(INDEX(M_CONTA,MATCH($C6,M_ID,0)),"")) | M6: =IF($B6="","",IF($E6<=0,"ERRO: valor deve ser maior que zero",IF(COUNTIF(M_ID,$C6)=0,"ERRO: meta inexistente",IF(COUNTIF(LST_TIPOMOV,$D6)=0,"ERRO: tipo de movimento invalido",IF(AND($D6="TRANSF_SAIDA",COUNTIF(M_ID,$G6)=0),"ERRO: informe a meta de destino",IF(AND($J6=-1,$F6=""),"ATENCAO: informe o destino da retirada","OK"))))))
A7: =IF($B7="","","MOV-"&TEXT(ROW()-4,"000000")) | I7: =IF($C7="","",IFERROR(INDEX(M_NOME,MATCH($C7,M_ID,0)),"?")) | J7: =IF($D7="",0,IFERROR(INDEX(MAP_SINALMOV,MATCH($D7,LST_TIPOMOV,0)),0)) -> 0 | K7: =IF($A7="",0,$E7*$J7) -> 0 | L7: =IF($C7="","",IFERROR(INDEX(M_CONTA,MATCH($C7,M_ID,0)),"")) | M7: =IF($B7="","",IF($E7<=0,"ERRO: valor deve ser maior que zero",IF(COUNTIF(M_ID,$C7)=0,"ERRO: meta inexistente",IF(COUNTIF(LST_TIPOMOV,$D7)=0,"ERRO: tipo de movimento invalido",IF(AND($D7="TRANSF_SAIDA",COUNTIF(M_ID,$G7)=0),"ERRO: informe a meta de destino",IF(AND($J7=-1,$F7=""),"ATENCAO: informe o destino da retirada","OK"))))))
A8: =IF($B8="","","MOV-"&TEXT(ROW()-4,"000000")) | I8: =IF($C8="","",IFERROR(INDEX(M_NOME,MATCH($C8,M_ID,0)),"?")) | J8: =IF($D8="",0,IFERROR(INDEX(MAP_SINALMOV,MATCH($D8,LST_TIPOMOV,0)),0)) -> 0 | K8: =IF($A8="",0,$E8*$J8) -> 0 | L8: =IF($C8="","",IFERROR(INDEX(M_CONTA,MATCH($C8,M_ID,0)),"")) | M8: =IF($B8="","",IF($E8<=0,"ERRO: valor deve ser maior que zero",IF(COUNTIF(M_ID,$C8)=0,"ERRO: meta inexistente",IF(COUNTIF(LST_TIPOMOV,$D8)=0,"ERRO: tipo de movimento invalido",IF(AND($D8="TRANSF_SAIDA",COUNTIF(M_ID,$G8)=0),"ERRO: informe a meta de destino",IF(AND($J8=-1,$F8=""),"ATENCAO: informe o destino da retirada","OK"))))))
